Workbook

Sheet Assumptions
A2: Revenue | B2: Growth rate as per the guidance by the company for explicit forecast period | G2: ='IS-Reorg'!L75 -> 0.03
A3: Terminal year growth rate assumed to be 2.5% as the company is a mature company and is assumed to grow in-line with long-term GDP growth rate
A5: WACC | B5: =WACC!D28 -> 0.080560348 | C5: Calculated in the WACC Sheet
A6: Beta has been adjusted using smoothing techniques
A8: Litigation related assumptions
A9: 3M is going thorugh 2 major litigation settlements
A10: 1. PFAS/PWS
A11: 2. Combat Arms Earplugs
A13: 3M official settlement documents with PWS have been used for the payment liability assumptions
A14: The Company filed an 8K form in June 2023 that explains the litigations payments and their schedules

Sheet IS-Reorg
B1: Historical Period | L1: Explicit forecast period
A2: All figures in millions of U.S. Dollar | B2: 2016 | C2: 2017 | D2: =C2+1 -> 2018 | E2: =D2+1 -> 2019 | F2: =E2+1 -> 2020 | G2: =F2+1 -> 2021 | H2: =G2+1 -> 2022 | I2: =H2+1 -> 2023 | J2: =I2+1 -> 2024 | K2: =J2+1 -> 2025 | L2: 2026 | M2: =L2+1 -> 2027 | N2: =M2+1 -> 2028 | O2: =N2+1 -> 2029 | P2: =O2+1 -> 2030 | Q2: =P2+1 -> 2031 | R2: =Q2+1 -> 2032 | S2: =R2+1 -> 2033 | T2: =S2+1 -> 2034 | ... V2: =U2+1 -> 2036 | X2: Common size base 2025
A3: Operating Items
A4: ='3M-IS'!A8 -> Sales | B4: =VLOOKUP($A4,'3M-IS'!$A$8:$K$61,11,FALSE) -> 30109 | C4: =VLOOKUP($A4,'3M-IS'!$A$8:$K$61,10,FALSE) -> 31657 | D4: =VLOOKUP($A4,'3M-IS'!$A$8:$K$61,9,FALSE) -> 32765 | E4: =VLOOKUP($A4,'3M-IS'!$A$8:$K$61,8,FALSE) -> 32136 | F4: =VLOOKUP($A4,'3M-IS'!$A$8:$K$61,7,FALSE) -> 32184 | G4: =VLOOKUP($A4,'3M-IS'!$A$8:$K$61,6,FALSE) -> 35355 | H4: =VLOOKUP($A4,'3M-IS'!$A$8:$K$61,5,FALSE) -> 34229 | I4: =VLOOKUP($A4,'3M-IS'!$A$8:$K$61,4,FALSE) -> 24610 | J4: =VLOOKUP($A4,'3M-IS'!$A$8:$K$61,3,FALSE) -> 24575 | K4: =VLOOKUP($A4,'3M-IS'!$A$8:$K$61,2,FALSE) -> 24948 | L4: =L72 -> 25313.28 | M4: =M72 -> 26325.811 | N4: =N72 -> 27378.844 | O4: =O72 -> 28473.997 | P4: =P72 -> 29612.957 | Q4: =Q72 -> 30501.346 | R4: =R72 -> 31416.386 | S4: =S72 -> 32358.878 | ... V4: =V72 -> 35359.42 | X4: =K4/$K$4 -> 1 | Y4: Revenue
A5: ='3M-IS'!A9 -> Cost of Goods Sold (COGS) incl. D&A | B5: =VLOOKUP($A5,'3M-IS'!$A$8:$K$61,11,FALSE) -> 15133 | C5: =VLOOKUP($A5,'3M-IS'!$A$8:$K$61,10,FALSE) -> 15995 | D5: =VLOOKUP($A5,'3M-IS'!$A$8:$K$61,9,FALSE) -> 16575 | E5: =VLOOKUP($A5,'3M-IS'!$A$8:$K$61,8,FALSE) -> 16830 | F5: =VLOOKUP($A5,'3M-IS'!$A$8:$K$61,7,FALSE) -> 16581 | G5: =VLOOKUP($A5,'3M-IS'!$A$8:$K$61,6,FALSE) -> 18743 | H5: =VLOOKUP($A5,'3M-IS'!$A$8:$K$61,5,FALSE) -> 19263 | I5: =VLOOKUP($A5,'3M-IS'!$A$8:$K$61,4,FALSE) -> 15037 | J5: =VLOOKUP($A5,'3M-IS'!$A$8:$K$61,3,FALSE) -> 14495 | K5: =VLOOKUP($A5,'3M-IS'!$A$8:$K$61,2,FALSE) -> 15072 | L5: =L6+L7 -> 15276.658 | M5: =M6+M7 -> 15701.471 | N5: =N6+N7 -> 16140.76 | O5: =O6+O7 -> 16594.735 | P5: =P6+P7 -> 17063.615 | Q5: =Q6+Q7 -> 17391.657 | R5: =R6+R7 -> 17726.581 | S5: =S6+S7 -> 18068.36 | ... V5: =V6+V7 -> 19134.581 | X5: =K5/$K$4 -> 0.6041366 | Y5: COGS w/ D&A
A6: ='3M-IS'!A10 -> COGS excluding D&A | B6: =VLOOKUP($A6,'3M-IS'!$A$8:$K$61,11,FALSE) -> 13659 | C6: =VLOOKUP($A6,'3M-IS'!$A$8:$K$61,10,FALSE) -> 14451 | D6: =VLOOKUP($A6,'3M-IS'!$A$8:$K$61,9,FALSE) -> 15087 | E6: =VLOOKUP($A6,'3M-IS'!$A$8:$K$61,8,FALSE) -> 15237 | F6: =VLOOKUP($A6,'3M-IS'!$A$8:$K$61,7,FALSE) -> 14670 | G6: =VLOOKUP($A6,'3M-IS'!$A$8:$K$61,6,FALSE) -> 16828 | H6: =VLOOKUP($A6,'3M-IS'!$A$8:$K$61,5,FALSE) -> 17432 | I6: =VLOOKUP($A6,'3M-IS'!$A$8:$K$61,4,FALSE) -> 13604 | J6: =VLOOKUP($A6,'3M-IS'!$A$8:$K$61,3,FALSE) -> 13271 | K6: =VLOOKUP($A6,'3M-IS'!$A$8:$K$61,2,FALSE) -> 13764 | L6: =L83 -> 13965.528 | M6: =M83 -> 14392.52 | N6: =N83 -> 14831.326 | O6: =O83 -> 15282.209 | P6: =P83 -> 15745.433 | Q6: =Q83 -> 16065.289 | R6: =R83 -> 16390.166 | S6: =S83 -> 16720.077 | ... V6: =V83 -> 17740.088 | X6: =K6/$K$4 -> 0.55170755 | Y6: COGS w/o D&A
A7: ='3M-IS'!A11 -> Depreciation & Amortization Expense | B7: =VLOOKUP($A7,'3M-IS'!$A$8:$K$61,11,FALSE) -> 1474 | C7: =VLOOKUP($A7,'3M-IS'!$A$8:$K$61,10,FALSE) -> 1544 | D7: =VLOOKUP($A7,'3M-IS'!$A$8:$K$61,9,FALSE) -> 1488 | E7: =VLOOKUP($A7,'3M-IS'!$A$8:$K$61,8,FALSE) -> 1593 | F7: =VLOOKUP($A7,'3M-IS'!$A$8:$K$61,7,FALSE) -> 1911 | G7: =VLOOKUP($A7,'3M-IS'!$A$8:$K$61,6,FALSE) -> 1915 | H7: =VLOOKUP($A7,'3M-IS'!$A$8:$K$61,5,FALSE) -> 1831 | I7: =VLOOKUP($A7,'3M-IS'!$A$8:$K$61,4,FALSE) -> 1433 | J7: =VLOOKUP($A7,'3M-IS'!$A$8:$K$61,3,FALSE) -> 1224 | K7: =VLOOKUP($A7,'3M-IS'!$A$8:$K$61,2,FALSE) -> 1308 | L7: =L8+L9 -> 1311.1303 | M7: =M8+M9 -> 1308.9515 | N7: =N8+N9 -> 1309.434 | O7: =O8+O9 -> 1312.5255 | P7: =P8+P9 -> 1318.1821 | Q7: =Q8+Q9 -> 1326.3682 | R7: =R8+R9 -> 1336.4154 | S7: =S8+S9 -> 1348.2837 | ... V7: =V8+V9 -> 1394.4927 | X7: =K7/$K$4 -> 0.052429052 | Y7: D&A
A8: ='3M-IS'!A12 -> Depreciation | B8: =VLOOKUP($A8,'3M-IS'!$A$8:$K$61,11,FALSE) -> 1212 | C8: =VLOOKUP($A8,'3M-IS'!$A$8:$K$61,10,FALSE) -> 1306 | D8: =VLOOKUP($A8,'3M-IS'!$A$8:$K$61,9,FALSE) -> 1239 | E8: =VLOOKUP($A8,'3M-IS'!$A$8:$K$61,8,FALSE) -> 1252 | F8: =VLOOKUP($A8,'3M-IS'!$A$8:$K$61,7,FALSE) -> 1374 | G8: =VLOOKUP($A8,'3M-IS'!$A$8:$K$61,6,FALSE) -> 1386 | H8: =VLOOKUP($A8,'3M-IS'!$A$8:$K$61,5,FALSE) -> 1333 | I8: =VLOOKUP($A8,'3M-IS'!$A$8:$K$61,4,FALSE) -> 1306 | J8: =VLOOKUP($A8,'3M-IS'!$A$8:$K$61,3,FALSE) -> 1116 | K8: =VLOOKUP($A8,'3M-IS'!$A$8:$K$61,2,FALSE) -> 1204 | L8: =-L101 -> 1215.6149 | M8: =-M101 -> 1221.7074 | N8: =-N101 -> 1229.7449 | O8: =-O101 -> 1239.7371 | P8: =-P101 -> 1251.697 | Q8: =-Q101 -> 1265.6403 | R8: =-R101 -> 1280.9463 | S8: =-S101 -> 1297.618 | ... V8: =-V101 -> 1355.8824
A9: ='3M-IS'!A13 -> Amortization of Intangibles | B9: =VLOOKUP($A9,'3M-IS'!$A$8:$K$61,11,FALSE) -> 262 | C9: =VLOOKUP($A9,'3M-IS'!$A$8:$K$61,10,FALSE) -> 238 | D9: =VLOOKUP($A9,'3M-IS'!$A$8:$K$61,9,FALSE) -> 249 | E9: =VLOOKUP($A9,'3M-IS'!$A$8:$K$61,8,FALSE) -> 341 | F9: =VLOOKUP($A9,'3M-IS'!$A$8:$K$61,7,FALSE) -> 537 | G9: =VLOOKUP($A9,'3M-IS'!$A$8:$K$61,6,FALSE) -> 529 | H9: =VLOOKUP($A9,'3M-IS'!$A$8:$K$61,5,FALSE) -> 498 | I9: =VLOOKUP($A9,'3M-IS'!$A$8:$K$61,4,FALSE) -> 127 | J9: =VLOOKUP($A9,'3M-IS'!$A$8:$K$61,3,FALSE) -> 108 | K9: =VLOOKUP($A9,'3M-IS'!$A$8:$K$61,2,FALSE) -> 104 | L9: =-L131 -> 95.515336 | M9: =-M131 -> 87.244094 | N9: =-N131 -> 79.689109 | O9: =-O131 -> 72.788355 | P9: =-P131 -> 66.485178 | Q9: =-Q131 -> 60.72783 | R9: =-R131 -> 55.469046 | S9: =-S131 -> 50.665651 | ... V9: =-V131 -> 38.610233
A10: ='3M-IS'!A14 -> Gross Income | B10: =VLOOKUP($A10,'3M-IS'!$A$8:$K$61,11,FALSE) -> 14976 | C10: =VLOOKUP($A10,'3M-IS'!$A$8:$K$61,10,FALSE) -> 15662 | D10: =VLOOKUP($A10,'3M-IS'!$A$8:$K$61,9,FALSE) -> 16190 | E10: =VLOOKUP($A10,'3M-IS'!$A$8:$K$61,8,FALSE) -> 15306 | F10: =VLOOKUP($A10,'3M-IS'!$A$8:$K$61,7,FALSE) -> 15603 | G10: =VLOOKUP($A10,'3M-IS'!$A$8:$K$61,6,FALSE) -> 16612 | H10: =VLOOKUP($A10,'3M-IS'!$A$8:$K$61,5,FALSE) -> 14966 | I10: =VLOOKUP($A10,'3M-IS'!$A$8:$K$61,4,FALSE) -> 9573 | J10: =VLOOKUP($A10,'3M-IS'!$A$8:$K$61,3,FALSE) -> 10080 | K10: =VLOOKUP($A10,'3M-IS'!$A$8:$K$61,2,FALSE) -> 9876 | L10: =L4-L5 -> 10036.622 | M10: =M4-M5 -> 10624.34 | N10: =N4-N5 -> 11238.083 | O10: =O4-O5 -> 11879.262 | P10: =P4-P5 -> 12549.342 | Q10: =Q4-Q5 -> 13109.689 | R10: =R4-R5 -> 13689.805 | S10: =S4-S5 -> 14290.518 | ... V10: =V4-V5 -> 16224.839 | X10: =K10/$K$4 -> 0.3958634 | Y10: GIM
A11: ='3M-IS'!A15 -> SG&A Expense | B11: =VLOOKUP($A11,'3M-IS'!$A$8:$K$61,11,FALSE) -> 7957 | C11: =VLOOKUP($A11,'3M-IS'!$A$8:$K$61,10,FALSE) -> 8436 | D11: =VLOOKUP($A11,'3M-IS'!$A$8:$K$61,9,FALSE) -> 8416 | E11: =VLOOKUP($A11,'3M-IS'!$A$8:$K$61,8,FALSE) -> 8332 | F11: =VLOOKUP($A11,'3M-IS'!$A$8:$K$61,7,FALSE) -> 8646 | G11: =VLOOKUP($A11,'3M-IS'!$A$8:$K$61,6,FALSE) -> 9086 | H11: =VLOOKUP($A11,'3M-IS'!$A$8:$K$61,5,FALSE) -> 10893 | I11: =VLOOKUP($A11,'3M-IS'!$A$8:$K$61,4,FALSE) -> 5526 | J11: =VLOOKUP($A11,'3M-IS'!$A$8:$K$61,3,FALSE) -> 5149 | K11: =VLOOKUP($A11,'3M-IS'!$A$8:$K$61,2,FALSE) -> 5146 | L11: =L89 -> 5221.346 | M11: =M89 -> 5298.5707 | N11: =N89 -> 5373.6193 | O11: =O89 -> 5446.1941 | P11: =P89 -> 5515.9771 | Q11: =Q89 -> 5528.9497 | R11: =R89 -> 5537.7363 | S11: =S89 -> 5542.074 | ... V11: =V89 -> 5525.5826 | X11: =K11/$K$4 -> 0.20626904 | Y11: SG&A %
A12: ='3M-IS'!A16 -> Research & Development | B12: =VLOOKUP($A12,'3M-IS'!$A$8:$K$61,11,FALSE) -> 1735 | C12: =VLOOKUP($A12,'3M-IS'!$A$8:$K$61,10,FALSE) -> 1862 | D12: =VLOOKUP($A12,'3M-IS'!$A$8:$K$61,9,FALSE) -> 1816 | E12: =VLOOKUP($A12,'3M-IS'!$A$8:$K$61,8,FALSE) -> 1874 | F12: =VLOOKUP($A12,'3M-IS'!$A$8:$K$61,7,FALSE) -> 1862 | G12: =VLOOKUP($A12,'3M-IS'!$A$8:$K$61,6,FALSE) -> 1977 | H12: =VLOOKUP($A12,'3M-IS'!$A$8:$K$61,5,FALSE) -> 1856 | I12: =VLOOKUP($A12,'3M-IS'!$A$8:$K$61,4,FALSE) -> 1123 | J12: =VLOOKUP($A12,'3M-IS'!$A$8:$K$61,3,FALSE) -> 1070 | K12: =VLOOKUP($A12,'3M-IS'!$A$8:$K$61,2,FALSE) -> 1169 | L12: =L91 -> 1265.664 | M12: =M91 -> 1316.2906 | N12: =N91 -> 1368.9422 | O12: =O91 -> 1423.6999 | P12: =P91 -> 1480.6479 | Q12: =Q91 -> 1525.0673 | R12: =R91 -> 1570.8193 | S12: =S91 -> 1617.9439 | ... V12: =V91 -> 1767.971
A13: ='3M-IS'!A17 -> Other SG&A | B13: =VLOOKUP($A13,'3M-IS'!$A$8:$K$61,11,FALSE) -> 6222 | C13: =VLOOKUP($A13,'3M-IS'!$A$8:$K$61,10,FALSE) -> 6574 | D13: =VLOOKUP($A13,'3M-IS'!$A$8:$K$61,9,FALSE) -> 6600 | E13: =VLOOKUP($A13,'3M-IS'!$A$8:$K$61,8,FALSE) -> 6458 | F13: =VLOOKUP($A13,'3M-IS'!$A$8:$K$61,7,FALSE) -> 6784 | G13: =VLOOKUP($A13,'3M-IS'!$A$8:$K$61,6,FALSE) -> 7109 | H13: =VLOOKUP($A13,'3M-IS'!$A$8:$K$61,5,FALSE) -> 9037 | I13: =VLOOKUP($A13,'3M-IS'!$A$8:$K$61,4,FALSE) -> 4403 | J13: =VLOOKUP($A13,'3M-IS'!$A$8:$K$61,3,FALSE) -> 4079 | K13: =VLOOKUP($A13,'3M-IS'!$A$8:$K$61,2,FALSE) -> 3977 | L13: =L11-L12 -> 3955.682 | M13: =M11-M12 -> 3982.2802 | N13: =N11-N12 -> 4004.6772 | O13: =O11-O12 -> 4022.4943 | P13: =P11-P12 -> 4035.3292 | Q13: =Q11-Q12 -> 4003.8824 | R13: =R11-R12 -> 3966.9169 | S13: =S11-S12 -> 3924.1301 | ... V13: =V11-V12 -> 3757.6116
A14: ='3M-IS'!A18 -> EBIT (Operating Income) | B14: =VLOOKUP($A14,'3M-IS'!$A$8:$K$61,11,FALSE) -> 7019 | C14: =VLOOKUP($A14,'3M-IS'!$A$8:$K$61,10,FALSE) -> 7226 | D14: =VLOOKUP($A14,'3M-IS'!$A$8:$K$61,9,FALSE) -> 7774 | E14: =VLOOKUP($A14,'3M-IS'!$A$8:$K$61,8,FALSE) -> 6974 | F14: =VLOOKUP($A14,'3M-IS'!$A$8:$K$61,7,FALSE) -> 6957 | G14: =VLOOKUP($A14,'3M-IS'!$A$8:$K$61,6,FALSE) -> 7526 | H14: =VLOOKUP($A14,'3M-IS'!$A$8:$K$61,5,FALSE) -> 4073 | I14: =VLOOKUP($A14,'3M-IS'!$A$8:$K$61,4,FALSE) -> 4047 | J14: =VLOOKUP($A14,'3M-IS'!$A$8:$K$61,3,FALSE) -> 4931 | K14: =VLOOKUP($A14,'3M-IS'!$A$8:$K$61,2,FALSE) -> 4730 | L14: =L10-L11 -> 4815.276 | M14: =M10-M11 -> 5325.7691 | N14: =N10-N11 -> 5864.4639 | O14: =O10-O11 -> 6433.0683 | P14: =P10-P11 -> 7033.365 | Q14: =Q10-Q11 -> 7580.7389 | R14: =R10-R11 -> 8152.0687 | S14: =S10-S11 -> 8748.4437 | ... V14: =V10-V11 -> 10699.257 | X14: =K14/$K$4 -> 0.18959436 | Y14: EBIT Margin
A16: Tax rate | B16: =VLOOKUP($A16,'3M-IS'!$A$64:$K$64,11,FALSE) -> 0.28285836 | C16: =VLOOKUP($A16,'3M-IS'!$A$64:$K$64,10,FALSE) -> 0.35492846 | D16: =VLOOKUP($A16,'3M-IS'!$A$64:$K$64,9,FALSE) -> 0.23385714 | E16: =VLOOKUP($A16,'3M-IS'!$A$64:$K$64,8,FALSE) -> 0.19782913 | F16: =VLOOKUP($A16,'3M-IS'!$A$64:$K$64,7,FALSE) -> 0.19676233 | G16: =VLOOKUP($A16,'3M-IS'!$A$64:$K$64,6,FALSE) -> 0.17837313 | H16: =VLOOKUP($A16,'3M-IS'!$A$64:$K$64,5,FALSE) -> 0.095744681 | I16: =VLOOKUP($A16,'3M-IS'!$A$64:$K$64,4,FALSE) -> 0.25436962 | J16: =VLOOKUP($A16,'3M-IS'!$A$64:$K$64,3,FALSE) -> 0.16683959 | K16: =VLOOKUP($A16,'3M-IS'!$A$64:$K$64,2,FALSE) -> 0.23807263 | L16: 0.21 | M16: =L16 -> 0.21 | N16: =M16 -> 0.21 | O16: =N16 -> 0.21 | P16: =O16 -> 0.21 | Q16: =P16 -> 0.21 | R16: =Q16 -> 0.21 | S16: =R16 -> 0.21 | T16: =S16 -> 0.21 | ... V16: =U16 -> 0.21 | Y16: U.S. federal statutory rate; used as the normalized forward rate since 3M's effective rate (10–35%) is distorted by one-time litigation/tax items.
A17: Operating Taxes | B17: =B16*B14 -> 1985.3828 | C17: =C16*C14 -> 2564.713 | D17: =D16*D14 -> 1818.0054 | E17: =E16*E14 -> 1379.6604 | F17: =F16*F14 -> 1368.8755 | G17: =G16*G14 -> 1342.4361 | H17: =H16*H14 -> 389.96809 | I17: =I16*I14 -> 1029.4339 | ... V17: =V16*V14 -> 2246.8439
A19: NOPAT | B19: =B14-B17 -> 5033.6172 | C19: =C14-C17 -> 4661.287 | D19: =D14-D17 -> 5955.9946 | E19: =E14-E17 -> 5594.3396 | F19: =F14-F17 -> 5588.1245 | G19: =G14-G17 -> 6183.5639 | H19: =H14-H17 -> 3683.0319 | I19: =I14-I17 -> 3017.5661 | ... V19: =V14-V17 -> 8452.4127 | X19: =K19/$K$4 -> 0.14445713 | Y19: NOPAT Margin
A21: ='3M-IS'!A19 -> Nonoperating Income - Net | B21: =VLOOKUP($A21,'3M-IS'!$A$8:$K$61,11,FALSE) -> 249 | C21: =VLOOKUP($A21,'3M-IS'!$A$8:$K$61,10,FALSE) -> 771 | D21: =VLOOKUP($A21,'3M-IS'!$A$8:$K$61,9,FALSE) -> 594 | E21: =VLOOKUP($A21,'3M-IS'!$A$8:$K$61,8,FALSE) -> 368 | F21: =VLOOKUP($A21,'3M-IS'!$A$8:$K$61,7,FALSE) -> 623 | G21: =VLOOKUP($A21,'3M-IS'!$A$8:$K$61,6,FALSE) -> 276 | H21: =VLOOKUP($A21,'3M-IS'!$A$8:$K$61,5,FALSE) -> 3137 | I21: =VLOOKUP($A21,'3M-IS'!$A$8:$K$61,4,FALSE) -> 517 | J21: =VLOOKUP($A21,'3M-IS'!$A$8:$K$61,3,FALSE) -> -189 | K21: =VLOOKUP($A21,'3M-IS'!$A$8:$K$61,2,FALSE) -> -100 | L21: =L22+L23 -> 153.28782 | M21: =M22+M23 -> 122.95192 | N21: =N22+N23 -> 143.9562 | O21: =O22+O23 -> 168.7428 | P21: =P22+P23 -> 224.79501 | Q21: =Q22+Q23 -> 288.37078 | R21: =R22+R23 -> 371.39 | S21: =S22+S23 -> 460.63636 | ... V21: =V22+V23 -> 766.00806 | X21: =K21/$K$4 -> -0.0040083373
A22: ='3M-IS'!A20 -> Nonoperating Interest Income | B22: =VLOOKUP($A22,'3M-IS'!$A$8:$K$61,11,FALSE) -> 29 | C22: =VLOOKUP($A22,'3M-IS'!$A$8:$K$61,10,FALSE) -> 50 | D22: =VLOOKUP($A22,'3M-IS'!$A$8:$K$61,9,FALSE) -> 70 | E22: =VLOOKUP($A22,'3M-IS'!$A$8:$K$61,8,FALSE) -> 80 | F22: =VLOOKUP($A22,'3M-IS'!$A$8:$K$61,7,FALSE) -> 29 | G22: =VLOOKUP($A22,'3M-IS'!$A$8:$K$61,6,FALSE) -> 26 | H22: =VLOOKUP($A22,'3M-IS'!$A$8:$K$61,5,FALSE) -> 67 | I22: =VLOOKUP($A22,'3M-IS'!$A$8:$K$61,4,FALSE) -> 250 | J22: =VLOOKUP($A22,'3M-IS'!$A$8:$K$61,3,FALSE) -> 452 | K22: =VLOOKUP($A22,'3M-IS'!$A$8:$K$61,2,FALSE) -> 232 | L22: =L154 -> 153.28782 | M22: =M154 -> 122.95192 | N22: =N154 -> 143.9562 | O22: =O154 -> 168.7428 | P22: =P154 -> 224.79501 | Q22: =Q154 -> 288.37078 | R22: =R154 -> 371.39 | S22: =S154 -> 460.63636 | ... V22: =V154 -> 766.00806
A23: ='3M-IS'!A21 -> Other Income (Expense) | B23: =VLOOKUP($A23,'3M-IS'!$A$8:$K$61,11,FALSE) -> 220 | C23: =VLOOKUP($A23,'3M-IS'!$A$8:$K$61,10,FALSE) -> 721 | D23: =VLOOKUP($A23,'3M-IS'!$A$8:$K$61,9,FALSE) -> 524 | E23: =VLOOKUP($A23,'3M-IS'!$A$8:$K$61,8,FALSE) -> 288 | F23: =VLOOKUP($A23,'3M-IS'!$A$8:$K$61,7,FALSE) -> 594 | G23: =VLOOKUP($A23,'3M-IS'!$A$8:$K$61,6,FALSE) -> 250 | H23: =VLOOKUP($A23,'3M-IS'!$A$8:$K$61,5,FALSE) -> 3070 | I23: =VLOOKUP($A23,'3M-IS'!$A$8:$K$61,4,FALSE) -> 267 | J23: =VLOOKUP($A23,'3M-IS'!$A$8:$K$61,3,FALSE) -> -641 | K23: =VLOOKUP($A23,'3M-IS'!$A$8:$K$61,2,FALSE) -> -332 | L23: 0 | M23: =L23 -> 0 | N23: =M23 -> 0 | O23: =N23 -> 0 | P23: =O23 -> 0 | Q23: =P23 -> 0 | R23: =Q23 -> 0 | S23: =R23 -> 0 | T23: =S23 -> 0 | ... V23: =U23 -> 0
A24: ='3M-IS'!A22 -> Interest Expense | B24: =VLOOKUP($A24,'3M-IS'!$A$8:$K$61,11,FALSE) -> 207 | C24: =VLOOKUP($A24,'3M-IS'!$A$8:$K$61,10,FALSE) -> 84 | D24: =VLOOKUP($A24,'3M-IS'!$A$8:$K$61,9,FALSE) -> 240 | E24: =VLOOKUP($A24,'3M-IS'!$A$8:$K$61,8,FALSE) -> 431 | F24: =VLOOKUP($A24,'3M-IS'!$A$8:$K$61,7,FALSE) -> 553 | G24: =VLOOKUP($A24,'3M-IS'!$A$8:$K$61,6,FALSE) -> 457 | H24: =VLOOKUP($A24,'3M-IS'!$A$8:$K$61,5,FALSE) -> 498 | I24: =VLOOKUP($A24,'3M-IS'!$A$8:$K$61,4,FALSE) -> 932 | J24: =VLOOKUP($A24,'3M-IS'!$A$8:$K$61,3,FALSE) -> 1182 | K24: =VLOOKUP($A24,'3M-IS'!$A$8:$K$61,2,FALSE) -> 938 | L24: =C150 -> 262.7372 | M24: =D150 -> 232.169 | N24: =E150 -> 161.2202 | O24: =F150 -> 134.3414 | P24: =G150 -> 107.7512 | Q24: =H150 -> 97.4084 | R24: =I150 -> 87.9782 | S24: =J150 -> 79.0394 | ... V24: =M150 -> 56.4116
A25: ='3M-IS'!A23 -> Gross Interest Expense | B25: =VLOOKUP($A25,'3M-IS'!$A$8:$K$61,11,FALSE) -> 217 | C25: =VLOOKUP($A25,'3M-IS'!$A$8:$K$61,10,FALSE) -> 84 | D25: =VLOOKUP($A25,'3M-IS'!$A$8:$K$61,9,FALSE) -> 240 | E25: =VLOOKUP($A25,'3M-IS'!$A$8:$K$61,8,FALSE) -> 431 | F25: =VLOOKUP($A25,'3M-IS'!$A$8:$K$61,7,FALSE) -> 553 | G25: =VLOOKUP($A25,'3M-IS'!$A$8:$K$61,6,FALSE) -> 457 | H25: =VLOOKUP($A25,'3M-IS'!$A$8:$K$61,5,FALSE) -> 498 | I25: =VLOOKUP($A25,'3M-IS'!$A$8:$K$61,4,FALSE) -> 932 | J25: =VLOOKUP($A25,'3M-IS'!$A$8:$K$61,3,FALSE) -> 1182 | K25: =VLOOKUP($A25,'3M-IS'!$A$8:$K$61,2,FALSE) -> 938 | L25: =C150 -> 262.7372 | M25: =D150 -> 232.169 | N25: =E150 -> 161.2202 | O25: =F150 -> 134.3414 | P25: =G150 -> 107.7512 | Q25: =H150 -> 97.4084 | R25: =I150 -> 87.9782 | S25: =J150 -> 79.0394 | ... V25: =M150 -> 56.4116
A26: ='3M-IS'!A24 -> Interest Capitalized | B26: =VLOOKUP($A26,'3M-IS'!$A$8:$K$61,11,FALSE) -> 10 | C26: =VLOOKUP($A26,'3M-IS'!$A$8:$K$61,10,FALSE) -> 0 | D26: =VLOOKUP($A26,'3M-IS'!$A$8:$K$61,9,FALSE) -> 0 | E26: =VLOOKUP($A26,'3M-IS'!$A$8:$K$61,8,FALSE) -> 0 | F26: =VLOOKUP($A26,'3M-IS'!$A$8:$K$61,7,FALSE) -> 0 | G26: =VLOOKUP($A26,'3M-IS'!$A$8:$K$61,6,FALSE) -> 0 | H26: =VLOOKUP($A26,'3M-IS'!$A$8:$K$61,5,FALSE) -> 0 | I26: =VLOOKUP($A26,'3M-IS'!$A$8:$K$61,4,FALSE) -> 0 | J26: =VLOOKUP($A26,'3M-IS'!$A$8:$K$61,3,FALSE) -> 0 | K26: =VLOOKUP($A26,'3M-IS'!$A$8:$K$61,2,FALSE) -> 0 | L26: 0 | M26: 0 | N26: 0 | O26: 0 | P26: 0 | Q26: 0 | R26: 0 | S26: 0 | T26: 0 | U26: 0 | V26: 0
A27: ='3M-IS'!A25 -> Unusual Expense - Net | B27: =VLOOKUP($A27,'3M-IS'!$A$8:$K$61,11,FALSE) -> 8 | C27: =VLOOKUP($A27,'3M-IS'!$A$8:$K$61,10,FALSE) -> 365 | D27: =VLOOKUP($A27,'3M-IS'!$A$8:$K$61,9,FALSE) -> 1128 | E27: =VLOOKUP($A27,'3M-IS'!$A$8:$K$61,8,FALSE) -> 1199 | F27: =VLOOKUP($A27,'3M-IS'!$A$8:$K$61,7,FALSE) -> 232 | G27: =VLOOKUP($A27,'3M-IS'!$A$8:$K$61,6,FALSE) -> 141 | H27: =VLOOKUP($A27,'3M-IS'!$A$8:$K$61,5,FALSE) -> 320 | I27: =VLOOKUP($A27,'3M-IS'!$A$8:$K$61,4,FALSE) -> 14903 | J27: =VLOOKUP($A27,'3M-IS'!$A$8:$K$61,3,FALSE) -> -1259 | K27: =VLOOKUP($A27,'3M-IS'!$A$8:$K$61,2,FALSE) -> -521 | L27: =-SUM(L28:L32) -> 0 | M27: =-SUM(M28:M32) -> 0 | N27: =-SUM(N28:N32) -> 0 | O27: =-SUM(O28:O32) -> 0 | P27: =-SUM(P28:P32) -> 0 | Q27: =-SUM(Q28:Q32) -> 0 | R27: =-SUM(R28:R32) -> 0 | S27: =-SUM(S28:S32) -> 0 | ... V27: =-SUM(V28:V32) -> 0
A28: ='3M-IS'!A26 -> Impairments | B28: =VLOOKUP($A28,'3M-IS'!$A$8:$K$61,11,FALSE) -> 0 | C28: =VLOOKUP($A28,'3M-IS'!$A$8:$K$61,10,FALSE) -> 0 | D28: =VLOOKUP($A28,'3M-IS'!$A$8:$K$61,9,FALSE) -> 0 | E28: =VLOOKUP($A28,'3M-IS'!$A$8:$K$61,8,FALSE) -> 0 | F28: =VLOOKUP($A28,'3M-IS'!$A$8:$K$61,7,FALSE) -> 0 | G28: =VLOOKUP($A28,'3M-IS'!$A$8:$K$61,6,FALSE) -> 0 | H28: =VLOOKUP($A28,'3M-IS'!$A$8:$K$61,5,FALSE) -> 271 | I28: =VLOOKUP($A28,'3M-IS'!$A$8:$K$61,4,FALSE) -> 0 | J28: =VLOOKUP($A28,'3M-IS'!$A$8:$K$61,3,FALSE) -> 0 | K28: =VLOOKUP($A28,'3M-IS'!$A$8:$K$61,2,FALSE) -> 0 | L28: 0 | M28: 0 | N28: 0 | O28: 0 | P28: 0 | Q28: 0 | R28: 0 | S28: 0 | T28: 0 | U28: 0 | V28: 0
A29: ='3M-IS'!A27 -> Goodwill | B29: =VLOOKUP($A29,'3M-IS'!$A$8:$K$61,11,FALSE) -> 0 | C29: =VLOOKUP($A29,'3M-IS'!$A$8:$K$61,10,FALSE) -> 0 | D29: =VLOOKUP($A29,'3M-IS'!$A$8:$K$61,9,FALSE) -> 0 | E29: =VLOOKUP($A29,'3M-IS'!$A$8:$K$61,8,FALSE) -> 0 | F29: =VLOOKUP($A29,'3M-IS'!$A$8:$K$61,7,FALSE) -> 0 | G29: =VLOOKUP($A29,'3M-IS'!$A$8:$K$61,6,FALSE) -> 0 | H29: =VLOOKUP($A29,'3M-IS'!$A$8:$K$61,5,FALSE) -> 271 | I29: =VLOOKUP($A29,'3M-IS'!$A$8:$K$61,4,FALSE) -> 0 | J29: =VLOOKUP($A29,'3M-IS'!$A$8:$K$61,3,FALSE) -> 0 | K29: =VLOOKUP($A29,'3M-IS'!$A$8:$K$61,2,FALSE) -> 0 | L29: 0 | M29: 0 | N29: 0 | O29: 0 | P29: 0 | Q29: 0 | R29: 0 | S29: 0 | T29: 0 | U29: 0 | V29: 0
A30: ='3M-IS'!A28 -> Restructuring Expense | B30: =VLOOKUP($A30,'3M-IS'!$A$8:$K$61,11,FALSE) -> 0 | C30: =VLOOKUP($A30,'3M-IS'!$A$8:$K$61,10,FALSE) -> 146 | D30: =VLOOKUP($A30,'3M-IS'!$A$8:$K$61,9,FALSE) -> 137 | E30: =VLOOKUP($A30,'3M-IS'!$A$8:$K$61,8,FALSE) -> 444 | F30: =VLOOKUP($A30,'3M-IS'!$A$8:$K$61,7,FALSE) -> 250 | G30: =VLOOKUP($A30,'3M-IS'!$A$8:$K$61,6,FALSE) -> 124 | H30: =VLOOKUP($A30,'3M-IS'!$A$8:$K$61,5,FALSE) -> 18 | I30: =VLOOKUP($A30,'3M-IS'!$A$8:$K$61,4,FALSE) -> 415 | J30: =VLOOKUP($A30,'3M-IS'!$A$8:$K$61,3,FALSE) -> 187 | K30: =VLOOKUP($A30,'3M-IS'!$A$8:$K$61,2,FALSE) -> 21 | L30: 0 | M30: 0 | N30: 0 | O30: 0 | P30: 0 | Q30: 0 | R30: 0 | S30: 0 | T30: 0 | U30: 0 | V30: 0
A31: ='3M-IS'!A29 -> Legal Claim Expense | B31: =VLOOKUP($A31,'3M-IS'!$A$8:$K$61,11,FALSE) -> 0 | C31: =VLOOKUP($A31,'3M-IS'!$A$8:$K$61,10,FALSE) -> 0 | D31: =VLOOKUP($A31,'3M-IS'!$A$8:$K$61,9,FALSE) -> 897 | E31: =VLOOKUP($A31,'3M-IS'!$A$8:$K$61,8,FALSE) -> 762 | F31: =VLOOKUP($A31,'3M-IS'!$A$8:$K$61,7,FALSE) -> 17 | G31: =VLOOKUP($A31,'3M-IS'!$A$8:$K$61,6,FALSE) -> 0 | H31: =VLOOKUP($A31,'3M-IS'!$A$8:$K$61,5,FALSE) -> 0 | I31: =VLOOKUP($A31,'3M-IS'!$A$8:$K$61,4,FALSE) -> 14500 | J31: =VLOOKUP($A31,'3M-IS'!$A$8:$K$61,3,FALSE) -> 87 | K31: =VLOOKUP($A31,'3M-IS'!$A$8:$K$61,2,FALSE) -> 0 | L31: 0 | M31: 0 | N31: 0 | O31: 0 | P31: 0 | Q31: 0 | R31: 0 | S31: 0 | T31: 0 | U31: 0 | V31: 0
A32: ='3M-IS'!A30 -> Unrealized Valuation Gain/Loss | B32: =VLOOKUP($A32,'3M-IS'!$A$8:$K$61,11,FALSE) -> -8 | C32: =VLOOKUP($A32,'3M-IS'!$A$8:$K$61,10,FALSE) -> -123 | D32: =VLOOKUP($A32,'3M-IS'!$A$8:$K$61,9,FALSE) -> -94 | E32: =VLOOKUP($A32,'3M-IS'!$A$8:$K$61,8,FALSE) -> 7 | F32: =VLOOKUP($A32,'3M-IS'!$A$8:$K$61,7,FALSE) -> 45 | G32: =VLOOKUP($A32,'3M-IS'!$A$8:$K$61,6,FALSE) -> -6 | H32: =VLOOKUP($A32,'3M-IS'!$A$8:$K$61,5,FALSE) -> -31 | I32: =VLOOKUP($A32,'3M-IS'!$A$8:$K$61,4,FALSE) -> 12 | J32: =VLOOKUP($A32,'3M-IS'!$A$8:$K$61,3,FALSE) -> 1533 | K32: =VLOOKUP($A32,'3M-IS'!$A$8:$K$61,2,FALSE) -> 542 | L32: 0 | M32: 0 | N32: 0 | O32: 0 | P32: 0 | Q32: 0 | R32: 0 | S32: 0 | T32: 0 | U32: 0 | V32: 0
A33: ='3M-IS'!A31 -> Investments | B33: =VLOOKUP($A33,'3M-IS'!$A$8:$K$61,11,FALSE) -> 0 | C33: =VLOOKUP($A33,'3M-IS'!$A$8:$K$61,10,FALSE) -> 0 | D33: =VLOOKUP($A33,'3M-IS'!$A$8:$K$61,9,FALSE) -> 0 | E33: =VLOOKUP($A33,'3M-IS'!$A$8:$K$61,8,FALSE) -> 0 | F33: =VLOOKUP($A33,'3M-IS'!$A$8:$K$61,7,FALSE) -> 0 | G33: =VLOOKUP($A33,'3M-IS'!$A$8:$K$61,6,FALSE) -> 0 | H33: =VLOOKUP($A33,'3M-IS'!$A$8:$K$61,5,FALSE) -> 0 | I33: =VLOOKUP($A33,'3M-IS'!$A$8:$K$61,4,FALSE) -> 0 | J33: =VLOOKUP($A33,'3M-IS'!$A$8:$K$61,3,FALSE) -> 1564 | K33: =VLOOKUP($A33,'3M-IS'!$A$8:$K$61,2,FALSE) -> 402 | L33: =K33 -> 402 | M33: =L33 -> 402 | N33: =M33 -> 402 | O33: =N33 -> 402 | P33: =O33 -> 402 | Q33: =P33 -> 402 | R33: =Q33 -> 402 | S33: =R33 -> 402 | ... V33: =U33 -> 402
A34: ='3M-IS'!A32 -> Hedges/Derivatives | B34: =VLOOKUP($A34,'3M-IS'!$A$8:$K$61,11,FALSE) -> -8 | C34: =VLOOKUP($A34,'3M-IS'!$A$8:$K$61,10,FALSE) -> -123 | D34: =VLOOKUP($A34,'3M-IS'!$A$8:$K$61,9,FALSE) -> -94 | E34: =VLOOKUP($A34,'3M-IS'!$A$8:$K$61,8,FALSE) -> 7 | F34: =VLOOKUP($A34,'3M-IS'!$A$8:$K$61,7,FALSE) -> 45 | G34: =VLOOKUP($A34,'3M-IS'!$A$8:$K$61,6,FALSE) -> -6 | H34: =VLOOKUP($A34,'3M-IS'!$A$8:$K$61,5,FALSE) -> -31 | I34: =VLOOKUP($A34,'3M-IS'!$A$8:$K$61,4,FALSE) -> 12 | J34: =VLOOKUP($A34,'3M-IS'!$A$8:$K$61,3,FALSE) -> -31 | K34: =VLOOKUP($A34,'3M-IS'!$A$8:$K$61,2,FALSE) -> 140 | L34: =K34 -> 140 | M34: =L34 -> 140 | N34: =M34 -> 140 | O34: =N34 -> 140 | P34: =O34 -> 140 | Q34: =P34 -> 140 | R34: =Q34 -> 140 | S34: =R34 -> 140 | ... V34: =U34 -> 140
A35: ='3M-IS'!A33 -> Excpl Chrgs - Others | B35: =VLOOKUP($A35,'3M-IS'!$A$8:$K$61,11,FALSE) -> 0 | C35: =VLOOKUP($A35,'3M-IS'!$A$8:$K$61,10,FALSE) -> 96 | D35: =VLOOKUP($A35,'3M-IS'!$A$8:$K$61,9,FALSE) -> 0 | E35: =VLOOKUP($A35,'3M-IS'!$A$8:$K$61,8,FALSE) -> 0 | F35: =VLOOKUP($A35,'3M-IS'!$A$8:$K$61,7,FALSE) -> 10 | G35: =VLOOKUP($A35,'3M-IS'!$A$8:$K$61,6,FALSE) -> 11 | H35: =VLOOKUP($A35,'3M-IS'!$A$8:$K$61,5,FALSE) -> 0 | I35: =VLOOKUP($A35,'3M-IS'!$A$8:$K$61,4,FALSE) -> 0 | J35: =VLOOKUP($A35,'3M-IS'!$A$8:$K$61,3,FALSE) -> 0 | K35: =VLOOKUP($A35,'3M-IS'!$A$8:$K$61,2,FALSE) -> 0 | L35: =K35 -> 0 | M35: =L35 -> 0 | N35: =M35 -> 0 | O35: =N35 -> 0 | P35: =O35 -> 0 | Q35: =P35 -> 0 | R35: =Q35 -> 0 | S35: =R35 -> 0 | ... V35: =U35 -> 0
A36: ='3M-IS'!A34 -> Restructuring of Debt | B36: =VLOOKUP($A36,'3M-IS'!$A$8:$K$61,11,FALSE) -> 0 | C36: =VLOOKUP($A36,'3M-IS'!$A$8:$K$61,10,FALSE) -> 96 | D36: =VLOOKUP($A36,'3M-IS'!$A$8:$K$61,9,FALSE) -> 0 | E36: =VLOOKUP($A36,'3M-IS'!$A$8:$K$61,8,FALSE) -> 0 | F36: =VLOOKUP($A36,'3M-IS'!$A$8:$K$61,7,FALSE) -> 10 | G36: =VLOOKUP($A36,'3M-IS'!$A$8:$K$61,6,FALSE) -> 11 | H36: =VLOOKUP($A36,'3M-IS'!$A$8:$K$61,5,FALSE) -> 0 | I36: =VLOOKUP($A36,'3M-IS'!$A$8:$K$61,4,FALSE) -> 0 | J36: =VLOOKUP($A36,'3M-IS'!$A$8:$K$61,3,FALSE) -> 0 | K36: =VLOOKUP($A36,'3M-IS'!$A$8:$K$61,2,FALSE) -> 0 | L36: =K36 -> 0 | M36: =L36 -> 0 | N36: =M36 -> 0 | O36: =N36 -> 0 | P36: =O36 -> 0 | Q36: =P36 -> 0 | R36: =Q36 -> 0 | S36: =R36 -> 0 | ... V36: =U36 -> 0
A37: ='3M-IS'!A35 -> Pretax Income | B37: =VLOOKUP($A37,'3M-IS'!$A$8:$K$61,11,FALSE) -> 7053 | C37: =VLOOKUP($A37,'3M-IS'!$A$8:$K$61,10,FALSE) -> 7548 | D37: =VLOOKUP($A37,'3M-IS'!$A$8:$K$61,9,FALSE) -> 7000 | E37: =VLOOKUP($A37,'3M-IS'!$A$8:$K$61,8,FALSE) -> 5712 | F37: =VLOOKUP($A37,'3M-IS'!$A$8:$K$61,7,FALSE) -> 6795 | G37: =VLOOKUP($A37,'3M-IS'!$A$8:$K$61,6,FALSE) -> 7204 | H37: =VLOOKUP($A37,'3M-IS'!$A$8:$K$61,5,FALSE) -> 6392 | I37: =VLOOKUP($A37,'3M-IS'!$A$8:$K$61,4,FALSE) -> -11271 | J37: =VLOOKUP($A37,'3M-IS'!$A$8:$K$61,3,FALSE) -> 4819 | K37: =VLOOKUP($A37,'3M-IS'!$A$8:$K$61,2,FALSE) -> 4213 | L37: =L14+L21+L27-L24 -> 4705.8266 | M37: =M14+M21+M27-M24 -> 5216.552 | N37: =N14+N21+N27-N24 -> 5847.1999 | O37: =O14+O21+O27-O24 -> 6467.4697 | P37: =P14+P21+P27-P24 -> 7150.4088 | Q37: =Q14+Q21+Q27-Q24 -> 7771.7012 | R37: =R14+R21+R27-R24 -> 8435.4805 | S37: =S14+S21+S27-S24 -> 9130.0407 | ... V37: =V14+V21+V27-V24 -> 11408.853 | X37: =K37/$K$4 -> 0.16887125 | Y37: EBT Margin
A38: ='3M-IS'!A36 -> Income Taxes | B38: =VLOOKUP($A38,'3M-IS'!$A$8:$K$61,11,FALSE) -> 1995 | C38: =VLOOKUP($A38,'3M-IS'!$A$8:$K$61,10,FALSE) -> 2679 | D38: =VLOOKUP($A38,'3M-IS'!$A$8:$K$61,9,FALSE) -> 1637 | E38: =VLOOKUP($A38,'3M-IS'!$A$8:$K$61,8,FALSE) -> 1130 | F38: =VLOOKUP($A38,'3M-IS'!$A$8:$K$61,7,FALSE) -> 1337 | G38: =VLOOKUP($A38,'3M-IS'!$A$8:$K$61,6,FALSE) -> 1285 | H38: =VLOOKUP($A38,'3M-IS'!$A$8:$K$61,5,FALSE) -> 612 | I38: =VLOOKUP($A38,'3M-IS'!$A$8:$K$61,4,FALSE) -> -2867 | J38: =VLOOKUP($A38,'3M-IS'!$A$8:$K$61,3,FALSE) -> 804 | K38: =VLOOKUP($A38,'3M-IS'!$A$8:$K$61,2,FALSE) -> 1003 | L38: =L37*L16 -> 988.2236 | M38: =M37*M16 -> 1095.4759 | N38: =N37*N16 -> 1227.912 | O38: =O37*O16 -> 1358.1686 | P38: =P37*P16 -> 1501.5859 | Q38: =Q37*Q16 -> 1632.0573 | R38: =R37*R16 -> 1771.4509 | S38: =S37*S16 -> 1917.3085 | ... V38: =V37*V16 -> 2395.8591 | X38: =K38/$K$4 -> 0.040203624
A39: ='3M-IS'!A37 -> Income Taxes - Current Domestic | B39: =VLOOKUP($A39,'3M-IS'!$A$8:$K$61,11,FALSE) -> 1267 | C39: =VLOOKUP($A39,'3M-IS'!$A$8:$K$61,10,FALSE) -> 1704 | D39: =VLOOKUP($A39,'3M-IS'!$A$8:$K$61,9,FALSE) -> 983 | E39: =VLOOKUP($A39,'3M-IS'!$A$8:$K$61,8,FALSE) -> 593 | F39: =VLOOKUP($A39,'3M-IS'!$A$8:$K$61,7,FALSE) -> 843 | G39: =VLOOKUP($A39,'3M-IS'!$A$8:$K$61,6,FALSE) -> 860 | H39: =VLOOKUP($A39,'3M-IS'!$A$8:$K$61,5,FALSE) -> 681 | I39: =VLOOKUP($A39,'3M-IS'!$A$8:$K$61,4,FALSE) -> 340 | J39: =VLOOKUP($A39,'3M-IS'!$A$8:$K$61,3,FALSE) -> -81 | K39: =VLOOKUP($A39,'3M-IS'!$A$8:$K$61,2,FALSE) -> -12 | X39: =K39/$K$4 -> -0.00048100048
A40: ='3M-IS'!A38 -> Income Taxes - Current Foreign | B40: =VLOOKUP($A40,'3M-IS'!$A$8:$K$61,11,FALSE) -> 733 | C40: =VLOOKUP($A40,'3M-IS'!$A$8:$K$61,10,FALSE) -> 722 | D40: =VLOOKUP($A40,'3M-IS'!$A$8:$K$61,9,FALSE) -> 763 | E40: =VLOOKUP($A40,'3M-IS'!$A$8:$K$61,8,FALSE) -> 673 | F40: =VLOOKUP($A40,'3M-IS'!$A$8:$K$61,7,FALSE) -> 632 | G40: =VLOOKUP($A40,'3M-IS'!$A$8:$K$61,6,FALSE) -> 597 | H40: =VLOOKUP($A40,'3M-IS'!$A$8:$K$61,5,FALSE) -> 621 | I40: =VLOOKUP($A40,'3M-IS'!$A$8:$K$61,4,FALSE) -> 494 | J40: =VLOOKUP($A40,'3M-IS'!$A$8:$K$61,3,FALSE) -> 583 | K40: =VLOOKUP($A40,'3M-IS'!$A$8:$K$61,2,FALSE) -> 597 | X40: =K40/$K$4 -> 0.023929774
A41: ='3M-IS'!A39 -> Income Taxes - Deferred Domestic | B41: =VLOOKUP($A41,'3M-IS'!$A$8:$K$61,11,FALSE) -> 6 | C41: =VLOOKUP($A41,'3M-IS'!$A$8:$K$61,10,FALSE) -> 177 | D41: =VLOOKUP($A41,'3M-IS'!$A$8:$K$61,9,FALSE) -> -55 | E41: =VLOOKUP($A41,'3M-IS'!$A$8:$K$61,8,FALSE) -> -58 | F41: =VLOOKUP($A41,'3M-IS'!$A$8:$K$61,7,FALSE) -> -61 | G41: =VLOOKUP($A41,'3M-IS'!$A$8:$K$61,6,FALSE) -> -244 | H41: =VLOOKUP($A41,'3M-IS'!$A$8:$K$61,5,FALSE) -> -688 | I41: =VLOOKUP($A41,'3M-IS'!$A$8:$K$61,4,FALSE) -> -3579 | J41: =VLOOKUP($A41,'3M-IS'!$A$8:$K$61,3,FALSE) -> 329 | K41: =VLOOKUP($A41,'3M-IS'!$A$8:$K$61,2,FALSE) -> 328 | X41: =K41/$K$4 -> 0.013147346
A42: ='3M-IS'!A40 -> Income Taxes - Deferred Foreign | B42: =VLOOKUP($A42,'3M-IS'!$A$8:$K$61,11,FALSE) -> -11 | C42: =VLOOKUP($A42,'3M-IS'!$A$8:$K$61,10,FALSE) -> 76 | D42: =VLOOKUP($A42,'3M-IS'!$A$8:$K$61,9,FALSE) -> -54 | E42: =VLOOKUP($A42,'3M-IS'!$A$8:$K$61,8,FALSE) -> -78 | F42: =VLOOKUP($A42,'3M-IS'!$A$8:$K$61,7,FALSE) -> -77 | G42: =VLOOKUP($A42,'3M-IS'!$A$8:$K$61,6,FALSE) -> 72 | H42: =VLOOKUP($A42,'3M-IS'!$A$8:$K$61,5,FALSE) -> -2 | I42: =VLOOKUP($A42,'3M-IS'!$A$8:$K$61,4,FALSE) -> -122 | J42: =VLOOKUP($A42,'3M-IS'!$A$8:$K$61,3,FALSE) -> -27 | K42: =VLOOKUP($A42,'3M-IS'!$A$8:$K$61,2,FALSE) -> 90 | X42: =K42/$K$4 -> 0.0036075036
A43: ='3M-IS'!A41 -> Equity in Earnings of Affiliates | B43: =VLOOKUP($A43,'3M-IS'!$A$8:$K$61,11,FALSE) -> 0 | C43: =VLOOKUP($A43,'3M-IS'!$A$8:$K$61,10,FALSE) -> 0 | D43: =VLOOKUP($A43,'3M-IS'!$A$8:$K$61,9,FALSE) -> 0 | E43: =VLOOKUP($A43,'3M-IS'!$A$8:$K$61,8,FALSE) -> 0 | F43: =VLOOKUP($A43,'3M-IS'!$A$8:$K$61,7,FALSE) -> -5 | G43: =VLOOKUP($A43,'3M-IS'!$A$8:$K$61,6,FALSE) -> 10 | H43: =VLOOKUP($A43,'3M-IS'!$A$8:$K$61,5,FALSE) -> 11 | I43: =VLOOKUP($A43,'3M-IS'!$A$8:$K$61,4,FALSE) -> 18 | J43: =VLOOKUP($A43,'3M-IS'!$A$8:$K$61,3,FALSE) -> 9 | K43: =VLOOKUP($A43,'3M-IS'!$A$8:$K$61,2,FALSE) -> 52 | L43: 0 | M43: =L43 -> 0 | N43: =M43 -> 0 | O43: =N43 -> 0 | P43: =O43 -> 0 | Q43: =P43 -> 0 | R43: =Q43 -> 0 | S43: =R43 -> 0 | T43: =S43 -> 0 | ... V43: =U43 -> 0
...

Sheet Litigation related payments
A1: Two settlements currently in progress
A3: 1. PWS settlement with annual payments expected to be completed by 2036 | D3: The source of this information is the 8K filed by 3M on its offical website which has schedules of payment.
A4: Risk free rate in 2023 | B4: 0.0234
A5: Amount | B5: 12.5 | C5: billion | D5: Announced maximum payment | E5: 3M 8-K 22-Jun-2023
A6: PV of amount | B6: 10.3 | C6: billion
A8: Imputed interest payments
A9: PV Accrual: $10,300M ,Total scheduled payments: $11,380M , Effective imputation rate: 2.34% , Payments: 2024 - 2036
A10: Year | B10: Opening Liability | C10: Imputed Interest (Rate × Opening) | D10: Cash Paid (Operating CF) | E10: Closing Liability
A11: 2024 | B11: 10300 | C11: =B11*$B$4 -> 241.02 | D11: 2900 | E11: =ROUND(B11+C11-D11,0) -> 7641
A12: 2025 | B12: 7641 | C12: =B12*$B$4 -> 178.7994 | D12: 1100 | E12: =ROUND(B12+C12-D12,0) -> 6720
A13: 2026 | B13: 6720 | C13: =B13*$B$4 -> 157.248 | D13: 900 | E13: =ROUND(B13+C13-D13,0) -> 5977
A14: 2027 | B14: 5977 | C14: =B14*$B$4 -> 139.8618 | D14: 2600 | E14: =ROUND(B14+C14-D14,0) -> 3517
A15: 2028 | B15: 3517 | C15: =B15*$B$4 -> 82.2978 | D15: 650 | E15: =ROUND(B15+C15-D15,0) -> 2949
A16: 2029 | B16: 2949 | C16: =B16*$B$4 -> 69.0066 | D16: 550 | E16: =ROUND(B16+C16-D16,0) -> 2468
A17: 2030 | B17: 2468 | C17: =B17*$B$4 -> 57.7512 | D17: 500 | E17: =ROUND(B17+C17-D17,0) -> 2026
A18: 2031 | B18: 2026 | C18: =B18*$B$4 -> 47.4084 | D18: 450 | E18: =ROUND(B18+C18-D18,0) -> 1623
A19: 2032 | B19: 1623 | C19: =B19*$B$4 -> 37.9782 | D19: 420 | E19: =ROUND(B19+C19-D19,0) -> 1241
A20: 2033 | B20: 1241 | C20: =B20*$B$4 -> 29.0394 | D20: 380 | E20: =ROUND(B20+C20-D20,0) -> 890
A21: 2034 | B21: 890 | C21: =B21*$B$4 -> 20.826 | D21: 350 | E21: =ROUND(B21+C21-D21,0) -> 561
A22: 2035 | B22: 561 | C22: =B22*$B$4 -> 13.1274 | D22: 300 | E22: =ROUND(B22+C22-D22,0) -> 274
A23: 2036 | B23: 274 | C23: =B23*$B$4 -> 6.4116 | D23: 280 | E23: =ROUND(B23+C23-D23,0) -> 0
A24: TOTALS | C24: =SUM(C11:C23) -> 1080.7758 | D24: =SUM(D11:D23) -> 11380
A25: Rate that amortizes the disclosed $10.3B present-value liability to zero over 3M's scheduled 2024–2036 payments (per 8-K dated
A26: 22-Jun-2023 and Q2-2023 10-Q). Held at the 2023 recognition-date rate per ASC 835-30 (long-term obligations are not remeasured for later rate changes).
A28: 2. Combat Arms Earplugs settlement | C28: 0.0156
A30: Opening PV: ~$5,700M , Nominal: $6,000M , Effective imputation rate: 1.56% , Payments: 2024 - 2029
A31: Year | B31: Opening Liability | C31: Imputed Interest (Rate × Opening) | D31: Cash Paid (Operating CF) | E31: Closing Liability
A32: 2024 | B32: 5700 | C32: =$C$28*B32 -> 88.92 | D32: 1400 | E32: =MAX(0,ROUND(B32+C32-D32,0)) -> 4389
A33: 2025 | B33: 4389 | C33: =$C$28*B33 -> 68.4684 | D33: 900 | E33: =MAX(0,ROUND(B33+C33-D33,0)) -> 3557
A34: 2026 | B34: 3557 | C34: =$C$28*B34 -> 55.4892 | D34: 900 | E34: =MAX(0,ROUND(B34+C34-D34,0)) -> 2712
A35: 2027 | B35: 2712 | C35: =$C$28*B35 -> 42.3072 | D35: 900 | E35: =MAX(0,ROUND(B35+C35-D35,0)) -> 1854
A36: 2028 | B36: 1854 | C36: =$C$28*B36 -> 28.9224 | D36: 900 | E36: =MAX(0,ROUND(B36+C36-D36,0)) -> 983
A37: 2029 | B37: 983 | C37: =$C$28*B37 -> 15.3348 | D37: 1000 | E37: =MAX(0,ROUND(B37+C37-D37,0)) -> 0
A38: TOTALS | C38: =SUM(C32:C37) -> 299.442 | D38: =SUM(D32:D37) -> 6000
B40: 2026 | C40: 2027 | D40: 2028 | E40: 2029 | F40: =E40+1 -> 2030 | G40: =F40+1 -> 2031 | H40: =G40+1 -> 2032 | I40: =H40+1 -> 2033 | J40: =I40+1 -> 2034 | K40: =J40+1 -> 2035 | L40: =K40+1 -> 2036
A41: Total imputed interest expense | B41: =C34+C13 -> 212.7372 | C41: =C35+C14 -> 182.169 | D41: =C36+C15 -> 111.2202 | E41: =C16+C37 -> 84.3414 | F41: =C17 -> 57.7512 | G41: =C18 -> 47.4084 | H41: =C19 -> 37.9782 | I41: =C20 -> 29.0394 | J41: =C21 -> 20.826 | K41: =C22 -> 13.1274 | L41: =C23 -> 6.4116
A43: Amortizes the disclosed ~$5.7B PV liability to zero over the 2024–2029 schedule (FY2023 10-K). Lower than the PWS rate because of the
A44: smaller PV-to-nominal gap over a shorter term.

Sheet BS-Reorg
L1: Explicit forecast period
A2: All figures in millions of U.S. Dollar | B2: 2016 | C2: 2017 | D2: =C2+1 -> 2018 | E2: =D2+1 -> 2019 | F2: =E2+1 -> 2020 | G2: =F2+1 -> 2021 | H2: =G2+1 -> 2022 | I2: =H2+1 -> 2023 | J2: =I2+1 -> 2024 | K2: =J2+1 -> 2025 | L2: 2026 | M2: =L2+1 -> 2027 | N2: =M2+1 -> 2028 | O2: =N2+1 -> 2029 | P2: =O2+1 -> 2030 | Q2: =P2+1 -> 2031 | R2: =Q2+1 -> 2032 | S2: =R2+1 -> 2033 | T2: =S2+1 -> 2034 | ... V2: =U2+1 -> 2036
A4: Cash & Short-Term Investments | B4: =B5+B6 -> 2678 | C4: =C5+C6 -> 4129 | D4: =D5+D6 -> 3233 | E4: =E5+E6 -> 2921 | F4: =F5+F6 -> 5038 | G4: =G5+G6 -> 4765 | H4: =H5+H6 -> 3893 | I4: =I5+I6 -> 5785 | ... K4: =K5+K6 -> 5933 | L4: =L71-(L7+L11+L15+L19+L28+L31+L34+L35) -> 6354.9985 | M4: =M71-(M7+M11+M15+M19+M28+M31+M34+M35) -> 5097.3341 | N4: =N71-(N7+N11+N15+N19+N28+N31+N34+N35) -> 5968.1288 | O4: =O71-(O7+O11+O15+O19+O28+O31+O34+O35) -> 6995.7301 | P4: =P71-(P7+P11+P15+P19+P28+P31+P34+P35) -> 9319.5397 | Q4: =Q71-(Q7+Q11+Q15+Q19+Q28+Q31+Q34+Q35) -> 11955.261 | R4: =R71-(R7+R11+R15+R19+R28+R31+R34+R35) -> 15397.067 | S4: =S71-(S7+S11+S15+S19+S28+S31+S34+S35) -> 19097.038 | ... V4: =V71-(V7+V11+V15+V19+V28+V31+V34+V35) -> 31757.122 | X4: Cash is a plug, excluded from invested capital; valuation uses 2025 cash only (Valuation!K25).
A5: Cash Only | B5: =VLOOKUP($A5,'3M-BS'!$A$12:$K$79,11, FALSE) -> 2398 | C5: =VLOOKUP($A5,'3M-BS'!$A$12:$K$79,10, FALSE) -> 3053 | D5: =VLOOKUP($A5,'3M-BS'!$A$12:$K$79,9, FALSE) -> 2853 | E5: =VLOOKUP($A5,'3M-BS'!$A$12:$K$79,8, FALSE) -> 2353 | F5: =VLOOKUP($A5,'3M-BS'!$A$12:$K$79,7, FALSE) -> 4634 | G5: =VLOOKUP($A5,'3M-BS'!$A$12:$K$79,6, FALSE) -> 4564 | H5: =VLOOKUP($A5,'3M-BS'!$A$12:$K$79,5, FALSE) -> 3655 | I5: =VLOOKUP($A5,'3M-BS'!$A$12:$K$79,4, FALSE) -> 5735 | J5: =VLOOKUP($A5,'3M-BS'!$A$12:$K$79,3, FALSE) -> 5600 | K5: =VLOOKUP($A5,'3M-BS'!$A$12:$K$79,2, FALSE) -> 5235 | L5: =$K$5/$K$4*L4 -> 5607.3516 | M5: =$K$5/$K$4*M4 -> 4497.6477 | N5: =$K$5/$K$4*N4 -> 5265.996 | O5: =$K$5/$K$4*O4 -> 6172.7031 | P5: =$K$5/$K$4*P4 -> 8223.1233 | Q5: =$K$5/$K$4*Q4 -> 10548.76 | R5: =$K$5/$K$4*R4 -> 13585.648 | S5: =$K$5/$K$4*S4 -> 16850.328 | ... V5: =$K$5/$K$4*V4 -> 28020.99 | X5: Unmodeled capital return inflates the projected balance but does not affect intrinsic value.
A6: Total Short Term Investments | B6: =VLOOKUP($A6,'3M-BS'!$A$12:$K$79,11, FALSE) -> 280 | C6: =VLOOKUP($A6,'3M-BS'!$A$12:$K$79,10, FALSE) -> 1076 | D6: =VLOOKUP($A6,'3M-BS'!$A$12:$K$79,9, FALSE) -> 380 | E6: =VLOOKUP($A6,'3M-BS'!$A$12:$K$79,8, FALSE) -> 568 | F6: =VLOOKUP($A6,'3M-BS'!$A$12:$K$79,7, FALSE) -> 404 | G6: =VLOOKUP($A6,'3M-BS'!$A$12:$K$79,6, FALSE) -> 201 | H6: =VLOOKUP($A6,'3M-BS'!$A$12:$K$79,5, FALSE) -> 238 | I6: =VLOOKUP($A6,'3M-BS'!$A$12:$K$79,4, FALSE) -> 50 | J6: =VLOOKUP($A6,'3M-BS'!$A$12:$K$79,3, FALSE) -> 2128 | K6: =VLOOKUP($A6,'3M-BS'!$A$12:$K$79,2, FALSE) -> 698 | L6: =$K$6/$K$5*L4 -> 847.33313 | M6: =$K$6/$K$5*M4 -> 679.64455 | N6: =$K$6/$K$5*N4 -> 795.75051 | O6: =$K$6/$K$5*O4 -> 932.76402 | P6: =$K$6/$K$5*P4 -> 1242.6053 | Q6: =$K$6/$K$5*Q4 -> 1594.0348 | R6: =$K$6/$K$5*R4 -> 2052.9423 | S6: =$K$6/$K$5*S4 -> 2546.2718 | ... V6: =$K$6/$K$5*V4 -> 4234.283
A7: ='3M-BS'!A14 -> Short-Term Receivables | B7: =VLOOKUP($A7,'3M-BS'!$A$12:$K$79,11, FALSE) -> 4392 | C7: =VLOOKUP($A7,'3M-BS'!$A$12:$K$79,10, FALSE) -> 4911 | D7: =VLOOKUP($A7,'3M-BS'!$A$12:$K$79,9, FALSE) -> 5020 | E7: =VLOOKUP($A7,'3M-BS'!$A$12:$K$79,8, FALSE) -> 4791 | F7: =VLOOKUP($A7,'3M-BS'!$A$12:$K$79,7, FALSE) -> 4705 | G7: =VLOOKUP($A7,'3M-BS'!$A$12:$K$79,6, FALSE) -> 4660 | H7: =VLOOKUP($A7,'3M-BS'!$A$12:$K$79,5, FALSE) -> 4532 | I7: =VLOOKUP($A7,'3M-BS'!$A$12:$K$79,4, FALSE) -> 3601 | J7: =VLOOKUP($A7,'3M-BS'!$A$12:$K$79,3, FALSE) -> 3194 | K7: =VLOOKUP($A7,'3M-BS'!$A$12:$K$79,2, FALSE) -> 3533 | L7: =L8 -> 3584.729 | M7: =M8 -> 3728.1181 | N7: =N8 -> 3866.6493 | O7: =O8 -> 4032.3326 | P7: =P8 -> 4193.6259 | Q7: =Q8 -> 4319.4346 | R7: =R8 -> 4436.8619 | S7: =S8 -> 4582.4882 | ... V7: =V8 -> 4993.7272
A8: ='3M-BS'!A15 -> Accounts Receivables, Net | B8: =VLOOKUP($A8,'3M-BS'!$A$12:$K$79,11, FALSE) -> 4392 | C8: =VLOOKUP($A8,'3M-BS'!$A$12:$K$79,10, FALSE) -> 4911 | D8: =VLOOKUP($A8,'3M-BS'!$A$12:$K$79,9, FALSE) -> 5020 | E8: =VLOOKUP($A8,'3M-BS'!$A$12:$K$79,8, FALSE) -> 4791 | F8: =VLOOKUP($A8,'3M-BS'!$A$12:$K$79,7, FALSE) -> 4705 | G8: =VLOOKUP($A8,'3M-BS'!$A$12:$K$79,6, FALSE) -> 4660 | H8: =VLOOKUP($A8,'3M-BS'!$A$12:$K$79,5, FALSE) -> 4532 | I8: =VLOOKUP($A8,'3M-BS'!$A$12:$K$79,4, FALSE) -> 3601 | J8: =VLOOKUP($A8,'3M-BS'!$A$12:$K$79,3, FALSE) -> 3194 | K8: =VLOOKUP($A8,'3M-BS'!$A$12:$K$79,2, FALSE) -> 3533 | L8: =L95 -> 3584.729 | M8: =M95 -> 3728.1181 | N8: =N95 -> 3866.6493 | O8: =O95 -> 4032.3326 | P8: =P95 -> 4193.6259 | Q8: =Q95 -> 4319.4346 | R8: =R95 -> 4436.8619 | S8: =S95 -> 4582.4882 | ... V8: =V95 -> 4993.7272
A9: ='3M-BS'!A16 -> Accounts Receivables, Gross | B9: =VLOOKUP($A9,'3M-BS'!$A$12:$K$79,11, FALSE) -> 4480 | C9: =VLOOKUP($A9,'3M-BS'!$A$12:$K$79,10, FALSE) -> 5014 | D9: =VLOOKUP($A9,'3M-BS'!$A$12:$K$79,9, FALSE) -> 5115 | E9: =VLOOKUP($A9,'3M-BS'!$A$12:$K$79,8, FALSE) -> 4952 | F9: =VLOOKUP($A9,'3M-BS'!$A$12:$K$79,7, FALSE) -> 4938 | G9: =VLOOKUP($A9,'3M-BS'!$A$12:$K$79,6, FALSE) -> 4849 | H9: =VLOOKUP($A9,'3M-BS'!$A$12:$K$79,5, FALSE) -> 4706 | I9: =VLOOKUP($A9,'3M-BS'!$A$12:$K$79,4, FALSE) -> 3663 | J9: =VLOOKUP($A9,'3M-BS'!$A$12:$K$79,3, FALSE) -> 3254 | K9: =VLOOKUP($A9,'3M-BS'!$A$12:$K$79,2, FALSE) -> 3594 | L9: =L8-L10 -> 3645.729 | M9: =M8-M10 -> 3789.1181 | N9: =N8-N10 -> 3927.6493 | O9: =O8-O10 -> 4093.3326 | P9: =P8-P10 -> 4254.6259 | Q9: =Q8-Q10 -> 4380.4346 | R9: =R8-R10 -> 4497.8619 | S9: =S8-S10 -> 4643.4882 | ... V9: =V8-V10 -> 5054.7272
A10: ='3M-BS'!A17 -> Bad Debt/Doubtful Accounts | B10: =VLOOKUP($A10,'3M-BS'!$A$12:$K$79,11, FALSE) -> -88 | C10: =VLOOKUP($A10,'3M-BS'!$A$12:$K$79,10, FALSE) -> -103 | D10: =VLOOKUP($A10,'3M-BS'!$A$12:$K$79,9, FALSE) -> -95 | E10: =VLOOKUP($A10,'3M-BS'!$A$12:$K$79,8, FALSE) -> -161 | F10: =VLOOKUP($A10,'3M-BS'!$A$12:$K$79,7, FALSE) -> -233 | G10: =VLOOKUP($A10,'3M-BS'!$A$12:$K$79,6, FALSE) -> -189 | H10: =VLOOKUP($A10,'3M-BS'!$A$12:$K$79,5, FALSE) -> -174 | I10: =VLOOKUP($A10,'3M-BS'!$A$12:$K$79,4, FALSE) -> -62 | J10: =VLOOKUP($A10,'3M-BS'!$A$12:$K$79,3, FALSE) -> -60 | K10: =VLOOKUP($A10,'3M-BS'!$A$12:$K$79,2, FALSE) -> -61 | L10: =K10 -> -61 | M10: =L10 -> -61 | N10: =M10 -> -61 | O10: =N10 -> -61 | P10: =O10 -> -61 | Q10: =P10 -> -61 | R10: =Q10 -> -61 | S10: =R10 -> -61 | ... V10: =U10 -> -61
A11: ='3M-BS'!A18 -> Inventories | B11: =VLOOKUP($A11,'3M-BS'!$A$12:$K$79,11, FALSE) -> 3385 | C11: =VLOOKUP($A11,'3M-BS'!$A$12:$K$79,10, FALSE) -> 4034 | D11: =VLOOKUP($A11,'3M-BS'!$A$12:$K$79,9, FALSE) -> 4366 | E11: =VLOOKUP($A11,'3M-BS'!$A$12:$K$79,8, FALSE) -> 4134 | F11: =VLOOKUP($A11,'3M-BS'!$A$12:$K$79,7, FALSE) -> 4239 | G11: =VLOOKUP($A11,'3M-BS'!$A$12:$K$79,6, FALSE) -> 4985 | H11: =VLOOKUP($A11,'3M-BS'!$A$12:$K$79,5, FALSE) -> 5372 | I11: =VLOOKUP($A11,'3M-BS'!$A$12:$K$79,4, FALSE) -> 3944 | J11: =VLOOKUP($A11,'3M-BS'!$A$12:$K$79,3, FALSE) -> 3698 | K11: =VLOOKUP($A11,'3M-BS'!$A$12:$K$79,2, FALSE) -> 3661 | L11: =L96 -> 3714.6031 | M11: =M96 -> 3828.176 | N11: =N96 -> 3934.1131 | O11: =O96 -> 4064.819 | P11: =P96 -> 4188.0289 | Q11: =Q96 -> 4273.1055 | R11: =R96 -> 4347.6062 | S11: =S96 -> 4447.2683 | ... V11: =V96 -> 4705.6824
A12: ='3M-BS'!A19 -> Finished Goods | B12: =VLOOKUP($A12,'3M-BS'!$A$12:$K$79,11, FALSE) -> 1629 | C12: =VLOOKUP($A12,'3M-BS'!$A$12:$K$79,10, FALSE) -> 1915 | D12: =VLOOKUP($A12,'3M-BS'!$A$12:$K$79,9, FALSE) -> 2120 | E12: =VLOOKUP($A12,'3M-BS'!$A$12:$K$79,8, FALSE) -> 2003 | F12: =VLOOKUP($A12,'3M-BS'!$A$12:$K$79,7, FALSE) -> 2081 | G12: =VLOOKUP($A12,'3M-BS'!$A$12:$K$79,6, FALSE) -> 2196 | H12: =VLOOKUP($A12,'3M-BS'!$A$12:$K$79,5, FALSE) -> 2497 | I12: =VLOOKUP($A12,'3M-BS'!$A$12:$K$79,4, FALSE) -> 1842 | J12: =VLOOKUP($A12,'3M-BS'!$A$12:$K$79,3, FALSE) -> 1849 | K12: =VLOOKUP($A12,'3M-BS'!$A$12:$K$79,2, FALSE) -> 1744 | L12: =$K$12/$K$11*L$11 -> 1769.535 | M12: =$K$12/$K$11*M$11 -> 1823.6381 | N12: =$K$12/$K$11*N$11 -> 1874.1036 | O12: =$K$12/$K$11*O$11 -> 1936.3683 | P12: =$K$12/$K$11*P$11 -> 1995.0621 | Q12: =$K$12/$K$11*Q$11 -> 2035.5903 | R12: =$K$12/$K$11*R$11 -> 2071.0804 | S12: =$K$12/$K$11*S$11 -> 2118.5566 | ... V12: =$K$12/$K$11*V$11 -> 2241.658
A13: ='3M-BS'!A20 -> Work in Progress | B13: =VLOOKUP($A13,'3M-BS'!$A$12:$K$79,11, FALSE) -> 1039 | C13: =VLOOKUP($A13,'3M-BS'!$A$12:$K$79,10, FALSE) -> 1218 | D13: =VLOOKUP($A13,'3M-BS'!$A$12:$K$79,9, FALSE) -> 1292 | E13: =VLOOKUP($A13,'3M-BS'!$A$12:$K$79,8, FALSE) -> 1194 | F13: =VLOOKUP($A13,'3M-BS'!$A$12:$K$79,7, FALSE) -> 1226 | G13: =VLOOKUP($A13,'3M-BS'!$A$12:$K$79,6, FALSE) -> 1577 | H13: =VLOOKUP($A13,'3M-BS'!$A$12:$K$79,5, FALSE) -> 1606 | I13: =VLOOKUP($A13,'3M-BS'!$A$12:$K$79,4, FALSE) -> 1242 | J13: =VLOOKUP($A13,'3M-BS'!$A$12:$K$79,3, FALSE) -> 1051 | K13: =VLOOKUP($A13,'3M-BS'!$A$12:$K$79,2, FALSE) -> 1126 | L13: =$K13/$K$11*L$11 -> 1142.4865 | M13: =$K13/$K$11*M$11 -> 1177.4177 | N13: =$K13/$K$11*N$11 -> 1210.0004 | O13: =$K13/$K$11*O$11 -> 1250.2011 | P13: =$K13/$K$11*P$11 -> 1288.0963 | Q13: =$K13/$K$11*Q$11 -> 1314.263 | R13: =$K13/$K$11*R$11 -> 1337.1769 | S13: =$K13/$K$11*S$11 -> 1367.8296 | ... V13: =$K13/$K$11*V$11 -> 1447.309
A14: ='3M-BS'!A21 -> Raw Materials | B14: =VLOOKUP($A14,'3M-BS'!$A$12:$K$79,11, FALSE) -> 717 | C14: =VLOOKUP($A14,'3M-BS'!$A$12:$K$79,10, FALSE) -> 901 | D14: =VLOOKUP($A14,'3M-BS'!$A$12:$K$79,9, FALSE) -> 954 | E14: =VLOOKUP($A14,'3M-BS'!$A$12:$K$79,8, FALSE) -> 937 | F14: =VLOOKUP($A14,'3M-BS'!$A$12:$K$79,7, FALSE) -> 932 | G14: =VLOOKUP($A14,'3M-BS'!$A$12:$K$79,6, FALSE) -> 1212 | H14: =VLOOKUP($A14,'3M-BS'!$A$12:$K$79,5, FALSE) -> 1269 | I14: =VLOOKUP($A14,'3M-BS'!$A$12:$K$79,4, FALSE) -> 860 | J14: =VLOOKUP($A14,'3M-BS'!$A$12:$K$79,3, FALSE) -> 798 | K14: =VLOOKUP($A14,'3M-BS'!$A$12:$K$79,2, FALSE) -> 791 | L14: =$K14/$K$11*L$11 -> 802.58155 | M14: =$K14/$K$11*M$11 -> 827.12025 | N14: =$K14/$K$11*N$11 -> 850.00913 | O14: =$K14/$K$11*O$11 -> 878.24961 | P14: =$K14/$K$11*P$11 -> 904.8705 | Q14: =$K14/$K$11*Q$11 -> 923.25224 | R14: =$K14/$K$11*R$11 -> 939.34894 | S14: =$K14/$K$11*S$11 -> 960.88205 | ... V14: =$K14/$K$11*V$11 -> 1016.7153
A15: ='3M-BS'!A22 -> Other Current Assets | B15: =VLOOKUP($A15,'3M-BS'!$A$12:$K$79,11, FALSE) -> 1271 | C15: =VLOOKUP($A15,'3M-BS'!$A$12:$K$79,10, FALSE) -> 1203 | D15: =VLOOKUP($A15,'3M-BS'!$A$12:$K$79,9, FALSE) -> 1090 | E15: =VLOOKUP($A15,'3M-BS'!$A$12:$K$79,8, FALSE) -> 1125 | F15: =VLOOKUP($A15,'3M-BS'!$A$12:$K$79,7, FALSE) -> 1000 | G15: =VLOOKUP($A15,'3M-BS'!$A$12:$K$79,6, FALSE) -> 993 | H15: =VLOOKUP($A15,'3M-BS'!$A$12:$K$79,5, FALSE) -> 891 | I15: =VLOOKUP($A15,'3M-BS'!$A$12:$K$79,4, FALSE) -> 3049 | J15: =VLOOKUP($A15,'3M-BS'!$A$12:$K$79,3, FALSE) -> 1264 | K15: =VLOOKUP($A15,'3M-BS'!$A$12:$K$79,2, FALSE) -> 3260 | L15: =L16+L17 -> 3307.7318 | M15: =M16+M17 -> 3440.0411 | N15: =N16+N17 -> 3577.6427 | O15: =O16+O17 -> 3720.7484 | P15: =P16+P17 -> 3869.5784 | Q15: =Q16+Q17 -> 3985.6657 | R15: =R16+R17 -> 4105.2357 | S15: =S16+S17 -> 4228.3927 | ... V15: =V16+V17 -> 4620.4789
A16: ='3M-BS'!A23 -> Prepaid Expenses | B16: =VLOOKUP($A16,'3M-BS'!$A$12:$K$79,11, FALSE) -> 0 | C16: =VLOOKUP($A16,'3M-BS'!$A$12:$K$79,10, FALSE) -> 937 | D16: =VLOOKUP($A16,'3M-BS'!$A$12:$K$79,9, FALSE) -> 741 | E16: =VLOOKUP($A16,'3M-BS'!$A$12:$K$79,8, FALSE) -> 704 | F16: =VLOOKUP($A16,'3M-BS'!$A$12:$K$79,7, FALSE) -> 675 | G16: =VLOOKUP($A16,'3M-BS'!$A$12:$K$79,6, FALSE) -> 654 | H16: =VLOOKUP($A16,'3M-BS'!$A$12:$K$79,5, FALSE) -> 435 | I16: =VLOOKUP($A16,'3M-BS'!$A$12:$K$79,4, FALSE) -> 344 | J16: =VLOOKUP($A16,'3M-BS'!$A$12:$K$79,3, FALSE) -> 436 | K16: =VLOOKUP($A16,'3M-BS'!$A$12:$K$79,2, FALSE) -> 391 | L16: =$K$16/$K$85*L85 -> 396.72489 | M16: =$K$16/$K$85*M85 -> 412.59388 | N16: =$K$16/$K$85*N85 -> 429.09764 | O16: =$K$16/$K$85*O85 -> 446.26154 | P16: =$K$16/$K$85*P85 -> 464.112 | Q16: =$K$16/$K$85*Q85 -> 478.03537 | R16: =$K$16/$K$85*R85 -> 492.37643 | S16: =$K$16/$K$85*S85 -> 507.14772 | ... V16: =$K$16/$K$85*V85 -> 554.17401
A17: ='3M-BS'!A24 -> Miscellaneous Current Assets | B17: =VLOOKUP($A17,'3M-BS'!$A$12:$K$79,11, FALSE) -> 1271 | C17: =VLOOKUP($A17,'3M-BS'!$A$12:$K$79,10, FALSE) -> 266 | D17: =VLOOKUP($A17,'3M-BS'!$A$12:$K$79,9, FALSE) -> 349 | E17: =VLOOKUP($A17,'3M-BS'!$A$12:$K$79,8, FALSE) -> 421 | F17: =VLOOKUP($A17,'3M-BS'!$A$12:$K$79,7, FALSE) -> 325 | G17: =VLOOKUP($A17,'3M-BS'!$A$12:$K$79,6, FALSE) -> 339 | H17: =VLOOKUP($A17,'3M-BS'!$A$12:$K$79,5, FALSE) -> 456 | I17: =VLOOKUP($A17,'3M-BS'!$A$12:$K$79,4, FALSE) -> 2705 | J17: =VLOOKUP($A17,'3M-BS'!$A$12:$K$79,3, FALSE) -> 828 | K17: =VLOOKUP($A17,'3M-BS'!$A$12:$K$79,2, FALSE) -> 2869 | L17: =$K$17/$K$85*L85 -> 2911.0069 | M17: =$K$17/$K$85*M85 -> 3027.4472 | N17: =$K$17/$K$85*N85 -> 3148.5451 | O17: =$K$17/$K$85*O85 -> 3274.4869 | P17: =$K$17/$K$85*P85 -> 3405.4663 | Q17: =$K$17/$K$85*Q85 -> 3507.6303 | R17: =$K$17/$K$85*R85 -> 3612.8592 | S17: =$K$17/$K$85*S85 -> 3721.245 | ... V17: =$K$17/$K$85*V85 -> 4066.3049
A19: ='3M-BS'!A26 -> Net Property, Plant & Equipment | B19: =VLOOKUP($A19,'3M-BS'!$A$12:$K$79,11, FALSE) -> 8516 | C19: =VLOOKUP($A19,'3M-BS'!$A$12:$K$79,10, FALSE) -> 8866 | D19: =VLOOKUP($A19,'3M-BS'!$A$12:$K$79,9, FALSE) -> 8738 | E19: =VLOOKUP($A19,'3M-BS'!$A$12:$K$79,8, FALSE) -> 10191 | F19: =VLOOKUP($A19,'3M-BS'!$A$12:$K$79,7, FALSE) -> 10285 | G19: =VLOOKUP($A19,'3M-BS'!$A$12:$K$79,6, FALSE) -> 10287 | H19: =VLOOKUP($A19,'3M-BS'!$A$12:$K$79,5, FALSE) -> 10007 | I19: =VLOOKUP($A19,'3M-BS'!$A$12:$K$79,4, FALSE) -> 8347 | J19: =VLOOKUP($A19,'3M-BS'!$A$12:$K$79,3, FALSE) -> 7953 | K19: =VLOOKUP($A19,'3M-BS'!$A$12:$K$79,2, FALSE) -> 7617 | L19: ='IS-Reorg'!L103 -> 7274.8178 | M19: ='IS-Reorg'!M103 -> 6969.4075 | N19: ='IS-Reorg'!N103 -> 6700.2218 | O19: ='IS-Reorg'!O103 -> 6466.7719 | P19: ='IS-Reorg'!P103 -> 6268.6271 | Q19: ='IS-Reorg'!Q103 -> 6092.5454 | R19: ='IS-Reorg'!R103 -> 5938.0686 | S19: ='IS-Reorg'!S103 -> 5804.7691 | ... V19: ='IS-Reorg'!V103 -> 5528.1099
A20: ='3M-BS'!A27 -> Property, Plant & Equipment - Gross | B20: =VLOOKUP($A20,'3M-BS'!$A$12:$K$79,11, FALSE) -> 23499 | C20: =VLOOKUP($A20,'3M-BS'!$A$12:$K$79,10, FALSE) -> 24914 | D20: =VLOOKUP($A20,'3M-BS'!$A$12:$K$79,9, FALSE) -> 24873 | E20: =VLOOKUP($A20,'3M-BS'!$A$12:$K$79,8, FALSE) -> 26982 | F20: =VLOOKUP($A20,'3M-BS'!$A$12:$K$79,7, FALSE) -> 27514 | G20: =VLOOKUP($A20,'3M-BS'!$A$12:$K$79,6, FALSE) -> 28071 | H20: =VLOOKUP($A20,'3M-BS'!$A$12:$K$79,5, FALSE) -> 26827 | I20: =VLOOKUP($A20,'3M-BS'!$A$12:$K$79,4, FALSE) -> 24151 | J20: =VLOOKUP($A20,'3M-BS'!$A$12:$K$79,3, FALSE) -> 23971 | K20: =VLOOKUP($A20,'3M-BS'!$A$12:$K$79,2, FALSE) -> 24438 | L20: ='IS-Reorg'!L112 -> 24560.48 | M20: ='IS-Reorg'!M112 -> 24722.061 | N20: ='IS-Reorg'!N112 -> 24922.938 | O20: ='IS-Reorg'!O112 -> 25163.371 | P20: ='IS-Reorg'!P112 -> 25443.681 | Q20: ='IS-Reorg'!Q112 -> 25751.383 | R20: ='IS-Reorg'!R112 -> 26086.541 | S20: ='IS-Reorg'!S112 -> 26449.249 | ... V20: ='IS-Reorg'!V112 -> 27704.099
A21: ='3M-BS'!A28 -> Buildings | B21: =VLOOKUP($A21,'3M-BS'!$A$12:$K$79,11, FALSE) -> 7252 | C21: =VLOOKUP($A21,'3M-BS'!$A$12:$K$79,10, FALSE) -> 7681 | D21: =VLOOKUP($A21,'3M-BS'!$A$12:$K$79,9, FALSE) -> 7517 | E21: =VLOOKUP($A21,'3M-BS'!$A$12:$K$79,8, FALSE) -> 7877 | F21: =VLOOKUP($A21,'3M-BS'!$A$12:$K$79,7, FALSE) -> 8021 | G21: =VLOOKUP($A21,'3M-BS'!$A$12:$K$79,6, FALSE) -> 8086 | H21: =VLOOKUP($A21,'3M-BS'!$A$12:$K$79,5, FALSE) -> 7560 | I21: =VLOOKUP($A21,'3M-BS'!$A$12:$K$79,4, FALSE) -> 7031 | J21: =VLOOKUP($A21,'3M-BS'!$A$12:$K$79,3, FALSE) -> 7432 | K21: =VLOOKUP($A21,'3M-BS'!$A$12:$K$79,2, FALSE) -> 7729 | L21: =$K21/$K$20*L20 -> 7767.7367 | M21: =$K21/$K$20*M20 -> 7818.8398 | N21: =$K21/$K$20*N20 -> 7882.3713 | O21: =$K21/$K$20*O20 -> 7958.413 | P21: =$K21/$K$20*P20 -> 8047.0664 | Q21: =$K21/$K$20*Q20 -> 8144.3834 | R21: =$K21/$K$20*R20 -> 8250.3837 | S21: =$K21/$K$20*S20 -> 8365.0973 | ... V21: =$K21/$K$20*V20 -> 8761.9684
A22: ='3M-BS'!A29 -> Land & Improvements | B22: =VLOOKUP($A22,'3M-BS'!$A$12:$K$79,11, FALSE) -> 341 | C22: =VLOOKUP($A22,'3M-BS'!$A$12:$K$79,10, FALSE) -> 348 | D22: =VLOOKUP($A22,'3M-BS'!$A$12:$K$79,9, FALSE) -> 340 | E22: =VLOOKUP($A22,'3M-BS'!$A$12:$K$79,8, FALSE) -> 351 | F22: =VLOOKUP($A22,'3M-BS'!$A$12:$K$79,7, FALSE) -> 338 | G22: =VLOOKUP($A22,'3M-BS'!$A$12:$K$79,6, FALSE) -> 312 | H22: =VLOOKUP($A22,'3M-BS'!$A$12:$K$79,5, FALSE) -> 255 | I22: =VLOOKUP($A22,'3M-BS'!$A$12:$K$79,4, FALSE) -> 215 | J22: =VLOOKUP($A22,'3M-BS'!$A$12:$K$79,3, FALSE) -> 200 | K22: =VLOOKUP($A22,'3M-BS'!$A$12:$K$79,2, FALSE) -> 202 | L22: =$K22/$K$20*L$20 -> 203.0124 | M22: =$K22/$K$20*M$20 -> 204.34799 | N22: =$K22/$K$20*N$20 -> 206.00841 | O22: =$K22/$K$20*O$20 -> 207.99578 | P22: =$K22/$K$20*P$20 -> 210.31277 | Q22: =$K22/$K$20*Q$20 -> 212.85618 | R22: =$K22/$K$20*R$20 -> 215.62654 | S22: =$K22/$K$20*S$20 -> 218.62461 | ... V22: =$K22/$K$20*V$20 -> 228.99697
A23: ='3M-BS'!A30 -> Machinery & Equipment | B23: =VLOOKUP($A23,'3M-BS'!$A$12:$K$79,11, FALSE) -> 14935 | C23: =VLOOKUP($A23,'3M-BS'!$A$12:$K$79,10, FALSE) -> 15907 | D23: =VLOOKUP($A23,'3M-BS'!$A$12:$K$79,9, FALSE) -> 15680 | E23: =VLOOKUP($A23,'3M-BS'!$A$12:$K$79,8, FALSE) -> 16586 | F23: =VLOOKUP($A23,'3M-BS'!$A$12:$K$79,7, FALSE) -> 16866 | G23: =VLOOKUP($A23,'3M-BS'!$A$12:$K$79,6, FALSE) -> 17305 | H23: =VLOOKUP($A23,'3M-BS'!$A$12:$K$79,5, FALSE) -> 16455 | I23: =VLOOKUP($A23,'3M-BS'!$A$12:$K$79,4, FALSE) -> 14716 | J23: =VLOOKUP($A23,'3M-BS'!$A$12:$K$79,3, FALSE) -> 14780 | K23: =VLOOKUP($A23,'3M-BS'!$A$12:$K$79,2, FALSE) -> 15328 | L23: =$K23/$K$20*L$20 -> 15404.822 | M23: =$K23/$K$20*M$20 -> 15506.169 | N23: =$K23/$K$20*N$20 -> 15632.163 | O23: =$K23/$K$20*O$20 -> 15782.967 | P23: =$K23/$K$20*P$20 -> 15958.783 | Q23: =$K23/$K$20*Q$20 -> 16151.78 | R23: =$K23/$K$20*R$20 -> 16361.998 | S23: =$K23/$K$20*S$20 -> 16589.496 | ... V23: =$K23/$K$20*V$20 -> 17376.563
A24: ='3M-BS'!A31 -> Construction in Progress | B24: =VLOOKUP($A24,'3M-BS'!$A$12:$K$79,11, FALSE) -> 809 | C24: =VLOOKUP($A24,'3M-BS'!$A$12:$K$79,10, FALSE) -> 843 | D24: =VLOOKUP($A24,'3M-BS'!$A$12:$K$79,9, FALSE) -> 1193 | E24: =VLOOKUP($A24,'3M-BS'!$A$12:$K$79,8, FALSE) -> 1310 | F24: =VLOOKUP($A24,'3M-BS'!$A$12:$K$79,7, FALSE) -> 1425 | G24: =VLOOKUP($A24,'3M-BS'!$A$12:$K$79,6, FALSE) -> 1510 | H24: =VLOOKUP($A24,'3M-BS'!$A$12:$K$79,5, FALSE) -> 1728 | I24: =VLOOKUP($A24,'3M-BS'!$A$12:$K$79,4, FALSE) -> 1532 | J24: =VLOOKUP($A24,'3M-BS'!$A$12:$K$79,3, FALSE) -> 994 | K24: =VLOOKUP($A24,'3M-BS'!$A$12:$K$79,2, FALSE) -> 663 | L24: =$K24/$K$20*L$20 -> 666.32287 | M24: =$K24/$K$20*M$20 -> 670.70654 | N24: =$K24/$K$20*N$20 -> 676.15632 | O24: =$K24/$K$20*O$20 -> 682.67923 | P24: =$K24/$K$20*P$20 -> 690.284 | Q24: =$K24/$K$20*Q$20 -> 698.63193 | R24: =$K24/$K$20*R$20 -> 707.72473 | S24: =$K24/$K$20*S$20 -> 717.56495 | ... V24: =$K24/$K$20*V$20 -> 751.60888
A25: ='3M-BS'!A32 -> Leases | B25: =VLOOKUP($A25,'3M-BS'!$A$12:$K$79,11, FALSE) -> 162 | C25: =VLOOKUP($A25,'3M-BS'!$A$12:$K$79,10, FALSE) -> 135 | D25: =VLOOKUP($A25,'3M-BS'!$A$12:$K$79,9, FALSE) -> 143 | E25: =VLOOKUP($A25,'3M-BS'!$A$12:$K$79,8, FALSE) -> 0 | F25: =VLOOKUP($A25,'3M-BS'!$A$12:$K$79,7, FALSE) -> 0 | G25: =VLOOKUP($A25,'3M-BS'!$A$12:$K$79,6, FALSE) -> 0 | H25: =VLOOKUP($A25,'3M-BS'!$A$12:$K$79,5, FALSE) -> 0 | I25: =VLOOKUP($A25,'3M-BS'!$A$12:$K$79,4, FALSE) -> 0 | J25: =VLOOKUP($A25,'3M-BS'!$A$12:$K$79,3, FALSE) -> 0 | K25: =VLOOKUP($A25,'3M-BS'!$A$12:$K$79,2, FALSE) -> 0 | L25: =K25 -> 0 | M25: =L25 -> 0 | N25: =M25 -> 0 | O25: =N25 -> 0 | P25: =O25 -> 0 | Q25: =P25 -> 0 | R25: =Q25 -> 0 | S25: =R25 -> 0 | ... V25: =U25 -> 0
A26: ='3M-BS'!A33 -> Operating Lease Right-of-Use Assets | B26: =VLOOKUP($A26,'3M-BS'!$A$12:$K$79,11, FALSE) -> 0 | C26: =VLOOKUP($A26,'3M-BS'!$A$12:$K$79,10, FALSE) -> 0 | D26: =VLOOKUP($A26,'3M-BS'!$A$12:$K$79,9, FALSE) -> 0 | E26: =VLOOKUP($A26,'3M-BS'!$A$12:$K$79,8, FALSE) -> 858 | F26: =VLOOKUP($A26,'3M-BS'!$A$12:$K$79,7, FALSE) -> 864 | G26: =VLOOKUP($A26,'3M-BS'!$A$12:$K$79,6, FALSE) -> 858 | H26: =VLOOKUP($A26,'3M-BS'!$A$12:$K$79,5, FALSE) -> 829 | I26: =VLOOKUP($A26,'3M-BS'!$A$12:$K$79,4, FALSE) -> 657 | J26: =VLOOKUP($A26,'3M-BS'!$A$12:$K$79,3, FALSE) -> 565 | K26: =VLOOKUP($A26,'3M-BS'!$A$12:$K$79,2, FALSE) -> 516 | L26: =$K26/$K$20*L$20 -> 518.58612 | M26: =$K26/$K$20*M$20 -> 521.99785 | N26: =$K26/$K$20*N$20 -> 526.23931 | O26: =$K26/$K$20*O$20 -> 531.31597 | P26: =$K26/$K$20*P$20 -> 537.23461 | Q26: =$K26/$K$20*Q$20 -> 543.73164 | R26: =$K26/$K$20*R$20 -> 550.80838 | S26: =$K26/$K$20*S$20 -> 558.46684 | ... V26: =$K26/$K$20*V$20 -> 584.96257
A27: ='3M-BS'!A34 -> Accumulated Depreciation | B27: =VLOOKUP($A27,'3M-BS'!$A$12:$K$79,11, FALSE) -> 14983 | C27: =VLOOKUP($A27,'3M-BS'!$A$12:$K$79,10, FALSE) -> 16048 | D27: =VLOOKUP($A27,'3M-BS'!$A$12:$K$79,9, FALSE) -> 16135 | E27: =VLOOKUP($A27,'3M-BS'!$A$12:$K$79,8, FALSE) -> 16791 | F27: =VLOOKUP($A27,'3M-BS'!$A$12:$K$79,7, FALSE) -> 17229 | G27: =VLOOKUP($A27,'3M-BS'!$A$12:$K$79,6, FALSE) -> 17784 | H27: =VLOOKUP($A27,'3M-BS'!$A$12:$K$79,5, FALSE) -> 16820 | I27: =VLOOKUP($A27,'3M-BS'!$A$12:$K$79,4, FALSE) -> 15804 | J27: =VLOOKUP($A27,'3M-BS'!$A$12:$K$79,3, FALSE) -> 16018 | K27: =VLOOKUP($A27,'3M-BS'!$A$12:$K$79,2, FALSE) -> 16821 | L27: ='IS-Reorg'!L119 -> 17285.662 | M27: ='IS-Reorg'!M119 -> 17752.653 | N27: ='IS-Reorg'!N119 -> 18222.717 | O27: ='IS-Reorg'!O119 -> 18696.599 | P27: ='IS-Reorg'!P119 -> 19175.054 | Q27: ='IS-Reorg'!Q119 -> 19658.838 | R27: ='IS-Reorg'!R119 -> 20148.473 | S27: ='IS-Reorg'!S119 -> 20644.48 | ... V27: ='IS-Reorg'!V119 -> 22175.989
A28: Total Long-Term Investments | B28: =VLOOKUP($A28,'3M-BS'!$A$12:$K$79,11, FALSE) -> 256 | C28: =VLOOKUP($A28,'3M-BS'!$A$12:$K$79,10, FALSE) -> 191 | D28: =VLOOKUP($A28,'3M-BS'!$A$12:$K$79,9, FALSE) -> 246 | E28: =VLOOKUP($A28,'3M-BS'!$A$12:$K$79,8, FALSE) -> 263 | F28: =VLOOKUP($A28,'3M-BS'!$A$12:$K$79,7, FALSE) -> 224 | G28: =VLOOKUP($A28,'3M-BS'!$A$12:$K$79,6, FALSE) -> 303 | H28: =VLOOKUP($A28,'3M-BS'!$A$12:$K$79,5, FALSE) -> 976 | I28: =VLOOKUP($A28,'3M-BS'!$A$12:$K$79,4, FALSE) -> 221 | J28: =VLOOKUP($A28,'3M-BS'!$A$12:$K$79,3, FALSE) -> 2583 | K28: =VLOOKUP($A28,'3M-BS'!$A$12:$K$79,2, FALSE) -> 161 | L28: =L29+L30 -> 163.35731 | M28: =M29+M30 -> 169.8916 | N28: =N29+N30 -> 176.68726 | O28: =O29+O30 -> 183.75475 | P28: =P29+P30 -> 191.10494 | Q28: =Q29+Q30 -> 196.83809 | R28: =R29+R30 -> 202.74323 | S28: =S29+S30 -> 208.82553 | ... V28: =V29+V30 -> 228.1893
A29: LT Investment - Affiliate Companies | B29: =VLOOKUP($A29,'3M-BS'!$A$12:$K$79,11, FALSE) -> 60 | C29: =VLOOKUP($A29,'3M-BS'!$A$12:$K$79,10, FALSE) -> 70 | D29: =VLOOKUP($A29,'3M-BS'!$A$12:$K$79,9, FALSE) -> 70 | E29: =VLOOKUP($A29,'3M-BS'!$A$12:$K$79,8, FALSE) -> 70 | F29: =VLOOKUP($A29,'3M-BS'!$A$12:$K$79,7, FALSE) -> 134 | G29: =VLOOKUP($A29,'3M-BS'!$A$12:$K$79,6, FALSE) -> 129 | H29: =VLOOKUP($A29,'3M-BS'!$A$12:$K$79,5, FALSE) -> 81 | I29: =VLOOKUP($A29,'3M-BS'!$A$12:$K$79,4, FALSE) -> 73 | J29: =VLOOKUP($A29,'3M-BS'!$A$12:$K$79,3, FALSE) -> 75 | K29: =VLOOKUP($A29,'3M-BS'!$A$12:$K$79,2, FALSE) -> 0 | L29: =K29 -> 0 | M29: =L29 -> 0 | N29: =M29 -> 0 | O29: =N29 -> 0 | P29: =O29 -> 0 | Q29: =P29 -> 0 | R29: =Q29 -> 0 | S29: =R29 -> 0 | ... V29: =U29 -> 0
A30: Other Long-Term Investments | B30: =VLOOKUP($A30,'3M-BS'!$A$12:$K$79,11, FALSE) -> 196 | C30: =VLOOKUP($A30,'3M-BS'!$A$12:$K$79,10, FALSE) -> 121 | D30: =VLOOKUP($A30,'3M-BS'!$A$12:$K$79,9, FALSE) -> 176 | E30: =VLOOKUP($A30,'3M-BS'!$A$12:$K$79,8, FALSE) -> 193 | F30: =VLOOKUP($A30,'3M-BS'!$A$12:$K$79,7, FALSE) -> 90 | G30: =VLOOKUP($A30,'3M-BS'!$A$12:$K$79,6, FALSE) -> 174 | H30: =VLOOKUP($A30,'3M-BS'!$A$12:$K$79,5, FALSE) -> 895 | I30: =VLOOKUP($A30,'3M-BS'!$A$12:$K$79,4, FALSE) -> 148 | J30: =VLOOKUP($A30,'3M-BS'!$A$12:$K$79,3, FALSE) -> 2508 | K30: =VLOOKUP($A30,'3M-BS'!$A$12:$K$79,2, FALSE) -> 161 | L30: =$K$30/$K$85*L85 -> 163.35731 | M30: =$K$30/$K$85*M85 -> 169.8916 | N30: =$K$30/$K$85*N85 -> 176.68726 | O30: =$K$30/$K$85*O85 -> 183.75475 | P30: =$K$30/$K$85*P85 -> 191.10494 | Q30: =$K$30/$K$85*Q85 -> 196.83809 | R30: =$K$30/$K$85*R85 -> 202.74323 | S30: =$K$30/$K$85*S85 -> 208.82553 | ... V30: =$K$30/$K$85*V85 -> 228.1893
A31: ='3M-BS'!A38 -> Intangible Assets | B31: =VLOOKUP($A31,'3M-BS'!$A$12:$K$79,11, FALSE) -> 11486 | C31: =VLOOKUP($A31,'3M-BS'!$A$12:$K$79,10, FALSE) -> 13449 | D31: =VLOOKUP($A31,'3M-BS'!$A$12:$K$79,9, FALSE) -> 12708 | E31: =VLOOKUP($A31,'3M-BS'!$A$12:$K$79,8, FALSE) -> 19823 | F31: =VLOOKUP($A31,'3M-BS'!$A$12:$K$79,7, FALSE) -> 19637 | G31: =VLOOKUP($A31,'3M-BS'!$A$12:$K$79,6, FALSE) -> 18774 | H31: =VLOOKUP($A31,'3M-BS'!$A$12:$K$79,5, FALSE) -> 17489 | I31: =VLOOKUP($A31,'3M-BS'!$A$12:$K$79,4, FALSE) -> 7705 | J31: =VLOOKUP($A31,'3M-BS'!$A$12:$K$79,3, FALSE) -> 7491 | K31: =VLOOKUP($A31,'3M-BS'!$A$12:$K$79,2, FALSE) -> 7522 | L31: =L32+L33 -> 7426.4847 | M31: =M32+M33 -> 7339.2406 | N31: =N32+N33 -> 7259.5515 | O31: =O32+O33 -> 7186.7631 | P31: =P32+P33 -> 7120.2779 | Q31: =Q32+Q33 -> 7059.5501 | R31: =R32+R33 -> 7004.0811 | S31: =S32+S33 -> 6953.4154 | ... V31: =V32+V33 -> 6826.2563
A32: ='3M-BS'!A39 -> Goodwill | B32: =VLOOKUP($A32,'3M-BS'!$A$12:$K$79,11, FALSE) -> 9166 | C32: =VLOOKUP($A32,'3M-BS'!$A$12:$K$79,10, FALSE) -> 10513 | D32: =VLOOKUP($A32,'3M-BS'!$A$12:$K$79,9, FALSE) -> 10051 | E32: =VLOOKUP($A32,'3M-BS'!$A$12:$K$79,8, FALSE) -> 13444 | F32: =VLOOKUP($A32,'3M-BS'!$A$12:$K$79,7, FALSE) -> 13802 | G32: =VLOOKUP($A32,'3M-BS'!$A$12:$K$79,6, FALSE) -> 13486 | H32: =VLOOKUP($A32,'3M-BS'!$A$12:$K$79,5, FALSE) -> 12790 | I32: =VLOOKUP($A32,'3M-BS'!$A$12:$K$79,4, FALSE) -> 6382 | J32: =VLOOKUP($A32,'3M-BS'!$A$12:$K$79,3, FALSE) -> 6281 | K32: =VLOOKUP($A32,'3M-BS'!$A$12:$K$79,2, FALSE) -> 6419 | L32: =K32 -> 6419 | M32: =L32 -> 6419 | N32: =M32 -> 6419 | O32: =N32 -> 6419 | P32: =O32 -> 6419 | Q32: =P32 -> 6419 | R32: =Q32 -> 6419 | S32: =R32 -> 6419 | ... V32: =U32 -> 6419
