Workbook

Sheet Dashboard
K3: Q4 FY'25 | L3: FY'26 Q1 | M3: Rest of FY'26 (Estimated) | N3: FY'26 End (Estimated)
J4: United States of America | K4: 629 | L4: 4 | M4: 16 | N4: 649
J5: Canada | K5: 110 | L5: 2 | M5: 3 | N5: 115
J6: Other International | K6: 175 | L6: 1 | M6: 2 | N6: 178
J7: Stores | K7: 914 | L7: 7 | M7: 21 | N7: 942
K10: Terminal Growth rate
J11: WACC | K11: WACC/Terminal growth rate | L11: 0.025 | M11: =L11+0.01 -> 0.035 | N11: =M11+0.01 -> 0.045 | O11: =N11+0.01 -> 0.055 | P11: =O11+0.01 -> 0.065
K12: =6.33% -> 0.0633 | L12: 470.73824 | M12: 617.60094 | N12: 924.96932 | O12: 1972.9844 | P12: -9308.5898
K13: =K12+0.01 -> 0.0733 | L13: 374.83029 | M13: 458.49742 | N13: 601.29326 | O13: 900.15013 | P13: 1919.144
K14: =K13+0.01 -> 0.0833 | L14: 311.87194 | M14: 365.32865 | N14: 446.7001 | O14: 585.57786 | P14: 876.23461
K15: =K14+0.01 -> 0.0933 | L15: 267.3887 | M15: 304.16406 | N15: 356.1673 | O15: 435.32629 | P15: 570.42801
K16: =K15+0.01 -> 0.1033 | L16: 234.30054 | M16: 260.94463 | N16: 296.72905 | O16: 347.33104 | P16: 424.35705
J18: Revenue Base case time series versus Historical Average
K19: 2026E | L19: 2027E | M19: 2028E | N19: 2029E
J20: Base Case | K20: 290232 | L20: 313495 | M20: 336757 | N20: 365768
J21: Historical growth | K21: 299318 | L21: 325508 | M21: 353990 | N21: 384965

Sheet Revenue Forecast ETS
B1: Reported revenue | E1: Lower bound | H1: Upper bound
A2: Date | B2: Net Sales | C2: Membership fee | D2: Revenue | E2: Net Sales | F2: Membership fee | G2: Revenue | H2: Net Sales | I2: Membership fee | J2: Revenue | L2: Growth rate | M2: Scenario | N2: 2
A3: 44885 | B3: 53437 | C3: 1000 | D3: =B3+C3 -> 54437
A4: =A3+84 -> 44969 | B4: 54239 | C4: 1027 | D4: =B4+C4 -> 55266 | M4: Year | N4: 2026 | O4: 2027 | P4: 2028 | Q4: 2029
A5: =A4+84 -> 45053 | B5: 52604 | C5: 1044 | D5: =B5+C5 -> 53648 | M5: Total Revenue | N5: =CHOOSE($N$2,N7,N8,N9) -> 290231.72 | O5: =CHOOSE($N$2,O7,O8,O9) -> 313494.72 | P5: =CHOOSE($N$2,P7,P8,P9) -> 336757.12 | Q5: =CHOOSE($N$2,Q7,Q8,Q9) -> 365767.83
A6: 45172 | B6: 77430 | C6: 1509 | D6: =B6+C6 -> 78939 | K6: =SUM(D3:D6) -> 242290 | M6: Growth | N6: =N5/K14-1 -> 0.054486974 | O6: =O5/N5-1 -> 0.080153179 | P6: =P5/O5-1 -> 0.074203504 | Q6: =Q5/P5-1 -> 0.086147269
A7: =A6+84 -> 45256 | B7: 56717 | C7: 1082 | D7: =B7+C7 -> 57799 | M7: Bull Case | N7: =SUM(J16:J18,D15) -> 342409.2 | O7: =SUM(J19:J22) -> 425778.7 | P7: =SUM(J23:J26) -> 484245.6 | Q7: =SUM(J27:J30) -> 542187.92
A8: =A7+84 -> 45340 | B8: 57331 | C8: 1111 | D8: =B8+C8 -> 58442 | M8: Base Case | N8: =SUM(D15:D18) -> 290231.72 | O8: =SUM(D19:D22) -> 313494.72 | P8: =SUM(D23:D26) -> 336757.12 | Q8: =SUM(D27:D30) -> 365767.83
A9: =A8+84 -> 45424 | B9: 57392 | C9: 1123 | D9: =B9+C9 -> 58515 | M9: Bear Case | N9: =SUM(D15,G16:G18) -> 238054.24 | O9: =SUM(G19:G22) -> 201210.73 | P9: =SUM(G23:G26) -> 189268.65 | Q9: =SUM(G27:G30) -> 189347.74
A10: 45536 | B10: 78185 | C10: 1512 | D10: =B10+C10 -> 79697 | K10: =SUM(D7:D10) -> 254453 | L10: =K10/K6-1 -> 0.050200173 | M10: CAGR | N10: 0.0793
A11: =A10+84 -> 45620 | B11: 60985 | C11: 1166 | D11: =B11+C11 -> 62151
A12: =A11+84 -> 45704 | B12: 62530 | C12: 1193 | D12: =B12+C12 -> 63723 | M12: Scenario | N12: 1
A13: =A12+84 -> 45788 | B13: 61965 | C13: 1240 | D13: =B13+C13 -> 63205
A14: 45900 | B14: 84432 | C14: 1724 | D14: =B14+C14 -> 86156 | K14: =SUM(D11:D14) -> 275235 | L14: =K14/K10-1 -> 0.081673236 | M14: Year | N14: 2026 | O14: 2027 | P14: 2028 | Q14: 2029
A15: =A14+84 -> 45984 | B15: 65978 | C15: 1329 | D15: =B15+C15 -> 67307 | M15: Membership fee | N15: =CHOOSE($N$12,N17,N18,N19) -> 7025.2045 | O15: =CHOOSE($N$12,O17,O18,O19) -> 8987.5015 | P15: =CHOOSE($N$12,P17,P18,P19) -> 10346.426 | Q15: =CHOOSE($N$12,Q17,Q18,Q19) -> 11670.4
A16: =A15+84 -> 46068 | B16: =_xlfn.FORECAST.ETS(A16,$B$3:$B$15,$A$3:$A$15,4) -> 65061.901 | C16: =_xlfn.FORECAST.ETS(A16,$C$3:$C$15,$A$3:$A$15,4) -> 1322.0642 | D16: =B16+C16 -> 66383.966 | E16: =B16-_xlfn.FORECAST.ETS.CONFINT(A16,$B$3:$B$15,$A$3:$A$15,0.95,4) -> 51541.772 | F16: =C16-_xlfn.FORECAST.ETS.CONFINT(A16,$C$3:$C$15,$A$3:$A$15,0.95,4) -> 1034.9094 | G16: =E16+F16 -> 52576.681 | H16: =B16+_xlfn.FORECAST.ETS.CONFINT(A16,$B$3:$B$15,$A$3:$A$15,0.95,4) -> 78582.031 | I16: =C16+_xlfn.FORECAST.ETS.CONFINT(A16,$C$3:$C$15,$A$3:$A$15,0.95,4) -> 1609.2191 | J16: =H16+I16 -> 80191.25 | M16: Growth | O16: =O15/N15-1 -> 0.27932241 | P16: =P15/O15-1 -> 0.15120157 | Q16: =Q15/P15-1 -> 0.12796441
A17: =A16+84 -> 46152 | B17: =_xlfn.FORECAST.ETS(A17,$B$3:$B$15,$A$3:$A$15,4) -> 70086.579 | C17: =_xlfn.FORECAST.ETS(A17,$C$3:$C$15,$A$3:$A$15,4) -> 1512.0549 | D17: =B17+C17 -> 71598.634 | E17: =B17-_xlfn.FORECAST.ETS.CONFINT(A17,$B$3:$B$15,$A$3:$A$15,0.95,4) -> 53178.302 | F17: =C17-_xlfn.FORECAST.ETS.CONFINT(A17,$C$3:$C$15,$A$3:$A$15,0.95,4) -> 1125.5354 | G17: =E17+F17 -> 54303.837 | H17: =B17+_xlfn.FORECAST.ETS.CONFINT(A17,$B$3:$B$15,$A$3:$A$15,0.95,4) -> 86994.857 | I17: =C17+_xlfn.FORECAST.ETS.CONFINT(A17,$C$3:$C$15,$A$3:$A$15,0.95,4) -> 1898.5744 | J17: =H17+I17 -> 88893.431 | M17: Bull Case | N17: =SUM(C15,I16:I18) -> 7025.2045 | O17: =SUM(I19:I22) -> 8987.5015 | P17: =SUM(I23:I26) -> 10346.426 | Q17: =SUM(I27:I30) -> 11670.4
A18: =A17+112 -> 46264 | B18: =_xlfn.FORECAST.ETS(A18,$B$3:$B$15,$A$3:$A$15,4) -> 83242.483 | C18: =_xlfn.FORECAST.ETS(A18,$C$3:$C$15,$A$3:$A$15,4) -> 1699.6393 | D18: =B18+C18 -> 84942.122 | E18: =B18-_xlfn.FORECAST.ETS.CONFINT(A18,$B$3:$B$15,$A$3:$A$15,0.95,4) -> 62655.858 | F18: =C18-_xlfn.FORECAST.ETS.CONFINT(A18,$C$3:$C$15,$A$3:$A$15,0.95,4) -> 1210.8677 | G18: =E18+F18 -> 63866.725 | H18: =B18+_xlfn.FORECAST.ETS.CONFINT(A18,$B$3:$B$15,$A$3:$A$15,0.95,4) -> 103829.11 | I18: =C18+_xlfn.FORECAST.ETS.CONFINT(A18,$C$3:$C$15,$A$3:$A$15,0.95,4) -> 2188.411 | J18: =H18+I18 -> 106017.52 | K18: =SUM(D15:D18) -> 290231.72 | L18: =K18/K14-1 -> 0.054486974 | M18: Base Case | N18: =SUM(C15:C18) -> 5862.7585 | O18: =SUM(C19:C22) -> 6390.1207 | P18: =SUM(C23:C26) -> 6917.4591 | Q18: =SUM(C27:C30) -> 7566.3587
A19: =A18+84 -> 46348 | B19: =_xlfn.FORECAST.ETS(A19,$B$3:$B$15,$A$3:$A$15,4) -> 70919.565 | C19: =_xlfn.FORECAST.ETS(A19,$C$3:$C$15,$A$3:$A$15,4) -> 1448.3974 | D19: =B19+C19 -> 72367.962 | E19: =B19-_xlfn.FORECAST.ETS.CONFINT(A19,$B$3:$B$15,$A$3:$A$15,0.95,4) -> 47378.032 | F19: =C19-_xlfn.FORECAST.ETS.CONFINT(A19,$C$3:$C$15,$A$3:$A$15,0.95,4) -> 890.38894 | G19: =E19+F19 -> 48268.421 | H19: =B19+_xlfn.FORECAST.ETS.CONFINT(A19,$B$3:$B$15,$A$3:$A$15,0.95,4) -> 94461.097 | I19: =C19+_xlfn.FORECAST.ETS.CONFINT(A19,$C$3:$C$15,$A$3:$A$15,0.95,4) -> 2006.4059 | J19: =H19+I19 -> 96467.503 | M19: Bear Case | N19: =SUM(C15,F16:F18) -> 4700.3124 | O19: =SUM(F19:F22) -> 3792.7398 | P19: =SUM(F23:F26) -> 3488.4923 | Q19: =SUM(F27:F30) -> 3462.3173
A20: =A19+84 -> 46432 | B20: =_xlfn.FORECAST.ETS(A20,$B$3:$B$15,$A$3:$A$15,4) -> 71983.348 | C20: =_xlfn.FORECAST.ETS(A20,$C$3:$C$15,$A$3:$A$15,4) -> 1507.0879 | D20: =B20+C20 -> 73490.436 | E20: =B20-_xlfn.FORECAST.ETS.CONFINT(A20,$B$3:$B$15,$A$3:$A$15,0.95,4) -> 45308.81 | F20: =C20-_xlfn.FORECAST.ETS.CONFINT(A20,$C$3:$C$15,$A$3:$A$15,0.95,4) -> 883.23904 | G20: =E20+F20 -> 46192.049 | H20: =B20+_xlfn.FORECAST.ETS.CONFINT(A20,$B$3:$B$15,$A$3:$A$15,0.95,4) -> 98657.887 | I20: =C20+_xlfn.FORECAST.ETS.CONFINT(A20,$C$3:$C$15,$A$3:$A$15,0.95,4) -> 2130.9368 | J20: =H20+I20 -> 100788.82 | M20: CAGR | N20: 0.0878
A21: =A20+84 -> 46516 | B21: =_xlfn.FORECAST.ETS(A21,$B$3:$B$15,$A$3:$A$15,4) -> 81721.329 | C21: =_xlfn.FORECAST.ETS(A21,$C$3:$C$15,$A$3:$A$15,4) -> 1737.7635 | D21: =B21+C21 -> 83459.092 | E21: =B21-_xlfn.FORECAST.ETS.CONFINT(A21,$B$3:$B$15,$A$3:$A$15,0.95,4) -> 53158.763 | F21: =C21-_xlfn.FORECAST.ETS.CONFINT(A21,$C$3:$C$15,$A$3:$A$15,0.95,4) -> 1061.9142 | G21: =E21+F21 -> 54220.677 | H21: =B21+_xlfn.FORECAST.ETS.CONFINT(A21,$B$3:$B$15,$A$3:$A$15,0.95,4) -> 110283.89 | I21: =C21+_xlfn.FORECAST.ETS.CONFINT(A21,$C$3:$C$15,$A$3:$A$15,0.95,4) -> 2413.6129 | J21: =H21+I21 -> 112697.51 | M21: Scenario | N21: 1
A22: =A21+112 -> 46628 | B22: =_xlfn.FORECAST.ETS(A22,$B$3:$B$15,$A$3:$A$15,4) -> 82480.355 | C22: =_xlfn.FORECAST.ETS(A22,$C$3:$C$15,$A$3:$A$15,4) -> 1696.8718 | D22: =B22+C22 -> 84177.227 | E22: =B22-_xlfn.FORECAST.ETS.CONFINT(A22,$B$3:$B$15,$A$3:$A$15,0.95,4) -> 51572.39 | F22: =C22-_xlfn.FORECAST.ETS.CONFINT(A22,$C$3:$C$15,$A$3:$A$15,0.95,4) -> 957.19763 | G22: =E22+F22 -> 52529.588 | H22: =B22+_xlfn.FORECAST.ETS.CONFINT(A22,$B$3:$B$15,$A$3:$A$15,0.95,4) -> 113388.32 | I22: =C22+_xlfn.FORECAST.ETS.CONFINT(A22,$C$3:$C$15,$A$3:$A$15,0.95,4) -> 2436.546 | J22: =H22+I22 -> 115824.87 | K22: =SUM(D19:D22) -> 313494.72 | L22: =K22/K18-1 -> 0.080153179
A23: =A22+84 -> 46712 | B23: =_xlfn.FORECAST.ETS(A23,$B$3:$B$15,$A$3:$A$15,4) -> 75860.564 | C23: =_xlfn.FORECAST.ETS(A23,$C$3:$C$15,$A$3:$A$15,4) -> 1567.771 | D23: =B23+C23 -> 77428.335 | E23: =B23-_xlfn.FORECAST.ETS.CONFINT(A23,$B$3:$B$15,$A$3:$A$15,0.95,4) -> 42487.019 | F23: =C23-_xlfn.FORECAST.ETS.CONFINT(A23,$C$3:$C$15,$A$3:$A$15,0.95,4) -> 776.90227 | G23: =E23+F23 -> 43263.921 | H23: =B23+_xlfn.FORECAST.ETS.CONFINT(A23,$B$3:$B$15,$A$3:$A$15,0.95,4) -> 109234.11 | I23: =C23+_xlfn.FORECAST.ETS.CONFINT(A23,$C$3:$C$15,$A$3:$A$15,0.95,4) -> 2358.6398 | J23: =H23+I23 -> 111592.75 | M23: Year | N23: 2026 | O23: 2027 | P23: 2028 | Q23: 2029
A24: =A23+84 -> 46796 | B24: =_xlfn.FORECAST.ETS(A24,$B$3:$B$15,$A$3:$A$15,4) -> 78904.795 | C24: =_xlfn.FORECAST.ETS(A24,$C$3:$C$15,$A$3:$A$15,4) -> 1692.1116 | D24: =B24+C24 -> 80596.907 | E24: =B24-_xlfn.FORECAST.ETS.CONFINT(A24,$B$3:$B$15,$A$3:$A$15,0.95,4) -> 43609.135 | F24: =C24-_xlfn.FORECAST.ETS.CONFINT(A24,$C$3:$C$15,$A$3:$A$15,0.95,4) -> 856.1883 | G24: =E24+F24 -> 44465.323 | H24: =B24+_xlfn.FORECAST.ETS.CONFINT(A24,$B$3:$B$15,$A$3:$A$15,0.95,4) -> 114200.46 | I24: =C24+_xlfn.FORECAST.ETS.CONFINT(A24,$C$3:$C$15,$A$3:$A$15,0.95,4) -> 2528.035 | J24: =H24+I24 -> 116728.49 | M24: Net Sales | N24: =CHOOSE($N$21,N26,N27,N28) -> 335384 | O24: =CHOOSE($N$21,O26,O27,O28) -> 416791.2 | P24: =CHOOSE($N$21,P26,P27,P28) -> 10346.426 | Q24: =CHOOSE($N$21,Q26,Q27,Q28) -> 530517.52
A25: =A24+84 -> 46880 | B25: =_xlfn.FORECAST.ETS(A25,$B$3:$B$15,$A$3:$A$15,4) -> 93356.078 | C25: =_xlfn.FORECAST.ETS(A25,$C$3:$C$15,$A$3:$A$15,4) -> 1963.4722 | D25: =B25+C25 -> 95319.55 | E25: =B25-_xlfn.FORECAST.ETS.CONFINT(A25,$B$3:$B$15,$A$3:$A$15,0.95,4) -> 56596.415 | F25: =C25-_xlfn.FORECAST.ETS.CONFINT(A25,$C$3:$C$15,$A$3:$A$15,0.95,4) -> 1087.6861 | G25: =E25+F25 -> 57684.101 | H25: =B25+_xlfn.FORECAST.ETS.CONFINT(A25,$B$3:$B$15,$A$3:$A$15,0.95,4) -> 130115.74 | I25: =C25+_xlfn.FORECAST.ETS.CONFINT(A25,$C$3:$C$15,$A$3:$A$15,0.95,4) -> 2839.2582 | J25: =H25+I25 -> 132955 | M25: Growth
A26: =A25+112 -> 46992 | B26: =_xlfn.FORECAST.ETS(A26,$B$3:$B$15,$A$3:$A$15,4) -> 81718.227 | C26: =_xlfn.FORECAST.ETS(A26,$C$3:$C$15,$A$3:$A$15,4) -> 1694.1042 | D26: =B26+C26 -> 83412.332 | E26: =B26-_xlfn.FORECAST.ETS.CONFINT(A26,$B$3:$B$15,$A$3:$A$15,0.95,4) -> 43087.585 | F26: =C26-_xlfn.FORECAST.ETS.CONFINT(A26,$C$3:$C$15,$A$3:$A$15,0.95,4) -> 767.71562 | G26: =E26+F26 -> 43855.301 | H26: =B26+_xlfn.FORECAST.ETS.CONFINT(A26,$B$3:$B$15,$A$3:$A$15,0.95,4) -> 120348.87 | I26: =C26+_xlfn.FORECAST.ETS.CONFINT(A26,$C$3:$C$15,$A$3:$A$15,0.95,4) -> 2620.4929 | J26: =H26+I26 -> 122969.36 | K26: =SUM(D23:D26) -> 336757.12 | L26: =K26/K22-1 -> 0.074203504 | M26: Bull Case | N26: =SUM(B15,H16:H18) -> 335384 | O26: =SUM(H19:H22) -> 416791.2 | P26: =SUM(I23:I26) -> 10346.426 | Q26: =SUM(H27:H30) -> 530517.52
A27: =A26+84 -> 47076 | B27: =_xlfn.FORECAST.ETS(A27,$B$3:$B$15,$A$3:$A$15,4) -> 80801.564 | C27: =_xlfn.FORECAST.ETS(A27,$C$3:$C$15,$A$3:$A$15,4) -> 1687.1447 | D27: =B27+C27 -> 82488.709 | E27: =B27-_xlfn.FORECAST.ETS.CONFINT(A27,$B$3:$B$15,$A$3:$A$15,0.95,4) -> 39823.96 | F27: =C27-_xlfn.FORECAST.ETS.CONFINT(A27,$C$3:$C$15,$A$3:$A$15,0.95,4) -> 716.33167 | G27: =E27+F27 -> 40540.292 | H27: =B27+_xlfn.FORECAST.ETS.CONFINT(A27,$B$3:$B$15,$A$3:$A$15,0.95,4) -> 121779.17 | I27: =C27+_xlfn.FORECAST.ETS.CONFINT(A27,$C$3:$C$15,$A$3:$A$15,0.95,4) -> 2657.9577 | J27: =H27+I27 -> 124437.13 | M27: Base Case | N27: =SUM(B15:B18) -> 284368.96 | O27: =SUM(B19:B22) -> 307104.6 | P27: =SUM(B23:B26) -> 329839.66 | Q27: =SUM(B27:B30) -> 358201.47
A28: =A27+84 -> 47160 | B28: =_xlfn.FORECAST.ETS(A28,$B$3:$B$15,$A$3:$A$15,4) -> 85826.242 | C28: =_xlfn.FORECAST.ETS(A28,$C$3:$C$15,$A$3:$A$15,4) -> 1877.1353 | D28: =B28+C28 -> 87703.377 | E28: =B28-_xlfn.FORECAST.ETS.CONFINT(A28,$B$3:$B$15,$A$3:$A$15,0.95,4) -> 43570.107 | F28: =C28-_xlfn.FORECAST.ETS.CONFINT(A28,$C$3:$C$15,$A$3:$A$15,0.95,4) -> 871.54485 | G28: =E28+F28 -> 44441.652 | H28: =B28+_xlfn.FORECAST.ETS.CONFINT(A28,$B$3:$B$15,$A$3:$A$15,0.95,4) -> 128082.38 | I28: =C28+_xlfn.FORECAST.ETS.CONFINT(A28,$C$3:$C$15,$A$3:$A$15,0.95,4) -> 2882.7258 | J28: =H28+I28 -> 130965.1 | M28: Bear Case | N28: =SUM(B15,E16:E18) -> 233353.93 | O28: =SUM(E19:E22) -> 197417.99 | P28: =SUM(E23:E26) -> 185780.15 | Q28: =SUM(E27:E30) -> 185885.42
A29: =A28+84 -> 47244 | B29: =_xlfn.FORECAST.ETS(A29,$B$3:$B$15,$A$3:$A$15,4) -> 104990.83 | C29: =_xlfn.FORECAST.ETS(A29,$C$3:$C$15,$A$3:$A$15,4) -> 2189.1808 | D29: =B29+C29 -> 107180.01 | E29: =B29-_xlfn.FORECAST.ETS.CONFINT(A29,$B$3:$B$15,$A$3:$A$15,0.95,4) -> 61490.517 | F29: =C29-_xlfn.FORECAST.ETS.CONFINT(A29,$C$3:$C$15,$A$3:$A$15,0.95,4) -> 1149.9035 | G29: =E29+F29 -> 62640.42 | H29: =B29+_xlfn.FORECAST.ETS.CONFINT(A29,$B$3:$B$15,$A$3:$A$15,0.95,4) -> 148491.14 | I29: =C29+_xlfn.FORECAST.ETS.CONFINT(A29,$C$3:$C$15,$A$3:$A$15,0.95,4) -> 3228.4581 | J29: =H29+I29 -> 151719.6 | M29: CAGR | N29: 0.0791
A30: =A29+119 -> 47363 | B30: =_xlfn.FORECAST.ETS(A30,$B$3:$B$15,$A$3:$A$15,4) -> 86582.838 | C30: =_xlfn.FORECAST.ETS(A30,$C$3:$C$15,$A$3:$A$15,4) -> 1812.8979 | D30: =B30+C30 -> 88395.736 | E30: =B30-_xlfn.FORECAST.ETS.CONFINT(A30,$B$3:$B$15,$A$3:$A$15,0.95,4) -> 41000.838 | F30: =C30-_xlfn.FORECAST.ETS.CONFINT(A30,$C$3:$C$15,$A$3:$A$15,0.95,4) -> 724.53722 | G30: =E30+F30 -> 41725.375 | H30: =B30+_xlfn.FORECAST.ETS.CONFINT(A30,$B$3:$B$15,$A$3:$A$15,0.95,4) -> 132164.84 | I30: =C30+_xlfn.FORECAST.ETS.CONFINT(A30,$C$3:$C$15,$A$3:$A$15,0.95,4) -> 2901.2586 | J30: =H30+I30 -> 135066.1 | K30: =SUM(D27:D30) -> 365767.83 | L30: =K30/K26-1 -> 0.086147269

Sheet Forecast
B1: Financial Statements
B3: Income Statement
B5: Units for figures (Millions of USD) | F5: 2021 | G5: 2022 | H5: 2023 | I5: 2024 | J5: 2025 | K5: =J5+1 -> 2026 | L5: =K5+1 -> 2027 | M5: =L5+1 -> 2028 | N5: Terminal Year | Q5: Rate | R5: Explanation/ Assumption
B7: Net sales | F7: =VLOOKUP($B7,INCOME_STATEMENT!$B$20:$L$39,11,0) -> 192052 | G7: =VLOOKUP($B7,INCOME_STATEMENT!$B$20:$L$39,9,0) -> 222730 | H7: =VLOOKUP($B7,INCOME_STATEMENT!$B$20:$L$39,7,0) -> 237710 | I7: =VLOOKUP($B7,INCOME_STATEMENT!$B$20:$L$39,5,0) -> 249625 | J7: =VLOOKUP($B7,INCOME_STATEMENT!$B$20:$L$39,3,0) -> 269912 | K7: =J7*(1+'Revenue Forecast ETS'!$N$29) -> 291262.04 | L7: =K7*(1+'Revenue Forecast ETS'!$N$29) -> 314300.87 | M7: =L7*(1+'Revenue Forecast ETS'!$N$29) -> 339162.07 | N7: =M7*(1+3.5%) -> 351032.74 | Q7: As per sheet-> CAGR used | R7: Sales growth projected using time series forecasting (Detail in Revenue forecast ETS sheet)
B8: Membership fees | F8: =VLOOKUP($B8,INCOME_STATEMENT!$B$20:$L$39,11,0) -> 3877 | G8: =VLOOKUP($B8,INCOME_STATEMENT!$B$20:$L$39,9,0) -> 4224 | H8: =VLOOKUP($B8,INCOME_STATEMENT!$B$20:$L$39,7,0) -> 4580 | I8: =VLOOKUP($B8,INCOME_STATEMENT!$B$20:$L$39,5,0) -> 4828 | J8: =VLOOKUP($B8,INCOME_STATEMENT!$B$20:$L$39,3,0) -> 5323 | K8: =J8*(1+'Revenue Forecast ETS'!$N$20) -> 5790.3594 | L8: =K8*(1+'Revenue Forecast ETS'!$N$20) -> 6298.753 | M8: =L8*(1+'Revenue Forecast ETS'!$N$20) -> 6851.7835 | N8: =M8*(1+3.5%) -> 7091.5959
B9: Total revenue | F9: =VLOOKUP($B9,INCOME_STATEMENT!$B$20:$L$39,11,0) -> 195929 | G9: =VLOOKUP($B9,INCOME_STATEMENT!$B$20:$L$39,9,0) -> 226954 | H9: =VLOOKUP($B9,INCOME_STATEMENT!$B$20:$L$39,7,0) -> 242290 | I9: =VLOOKUP($B9,INCOME_STATEMENT!$B$20:$L$39,5,0) -> 254453 | J9: =VLOOKUP($B9,INCOME_STATEMENT!$B$20:$L$39,3,0) -> 275235 | K9: =SUM(K7:K8) -> 297052.4 | L9: =SUM(L7:L8) -> 320599.62 | M9: =SUM(M7:M8) -> 346013.85 | N9: =SUM(N7:N8) -> 358124.33
B11: OPERATING EXPENSES
B12: Merchandise costs | F12: =VLOOKUP($B12,INCOME_STATEMENT!$B$20:$L$39,11,0) -> 170684 | G12: =VLOOKUP($B12,INCOME_STATEMENT!$B$20:$L$39,9,0) -> 199382 | H12: =VLOOKUP($B12,INCOME_STATEMENT!$B$20:$L$39,7,0) -> 212586 | I12: =VLOOKUP($B12,INCOME_STATEMENT!$B$20:$L$39,5,0) -> 222358 | J12: =VLOOKUP($B12,INCOME_STATEMENT!$B$20:$L$39,3,0) -> 239886 | K12: =K$9*$Q12 -> 259772.49 | L12: =L$9*$Q12 -> 280364.55 | M12: =M$9*$Q12 -> 302589.31 | N12: =M12*(1+3.5%) -> 313179.93 | Q12: =K104 -> 0.87450057 | R12: Using as percentage rate of sale (average 5 years - Operating Expense)
B13: Selling, general and administrative | F13: =VLOOKUP($B13,INCOME_STATEMENT!$B$20:$L$39,11,0) -> 18537 | G13: =VLOOKUP($B13,INCOME_STATEMENT!$B$20:$L$39,9,0) -> 19779 | H13: =VLOOKUP($B13,INCOME_STATEMENT!$B$20:$L$39,7,0) -> 21590 | I13: =VLOOKUP($B13,INCOME_STATEMENT!$B$20:$L$39,5,0) -> 22810 | J13: =VLOOKUP($B13,INCOME_STATEMENT!$B$20:$L$39,3,0) -> 24966 | K13: =K$9*$Q13 -> 26807.192 | L13: =L$9*$Q13 -> 28932.188 | M13: =M$9*$Q13 -> 31225.669 | N13: =M13*(1+3.5%) -> 32318.567 | Q13: =K105 -> 0.090243986 | R13: Using as percentage rate of sale (average 5 years - Operating Expense)
B14: Operating income | F14: =VLOOKUP($B14,INCOME_STATEMENT!$B$20:$L$39,11,0) -> 6708 | G14: =VLOOKUP($B14,INCOME_STATEMENT!$B$20:$L$39,9,0) -> 7793 | H14: =VLOOKUP($B14,INCOME_STATEMENT!$B$20:$L$39,7,0) -> 8114 | I14: =VLOOKUP($B14,INCOME_STATEMENT!$B$20:$L$39,5,0) -> 9285 | J14: =VLOOKUP($B14,INCOME_STATEMENT!$B$20:$L$39,3,0) -> 10383 | K14: =K9-SUM(K12:K13) -> 10472.713 | L14: =L9-SUM(L12:L13) -> 11302.881 | M14: =M9-SUM(M12:M13) -> 12198.871 | N14: =M14*(1+3.5%) -> 12625.831
B16: OTHER INCOME (EXPENSE)
B17: Interest expense | F17: =VLOOKUP($B17,INCOME_STATEMENT!$B$20:$L$39,11,0) -> -171 | G17: =VLOOKUP($B17,INCOME_STATEMENT!$B$20:$L$39,9,0) -> -158 | H17: =VLOOKUP($B17,INCOME_STATEMENT!$B$20:$L$39,7,0) -> -160 | I17: =VLOOKUP($B17,INCOME_STATEMENT!$B$20:$L$39,5,0) -> -169 | J17: =VLOOKUP($B17,INCOME_STATEMENT!$B$20:$L$39,3,0) -> -154 | K17: =K118 -> -151.91223 | L17: =L118 -> -120.79638 | M17: =M118 -> -90.684279 | N17: =M17*(1+3.5%) -> -93.858229 | Q17: =J117 -> 0.026766316 | R17: Interset expense is average total debt multiple interest rate FY2025 (detail in Debt Modeling)
B18: Interest income and other, net | F18: =VLOOKUP($B18,INCOME_STATEMENT!$B$20:$L$39,11,0) -> 143 | G18: =VLOOKUP($B18,INCOME_STATEMENT!$B$20:$L$39,9,0) -> 205 | H18: =VLOOKUP($B18,INCOME_STATEMENT!$B$20:$L$39,7,0) -> 533 | I18: =VLOOKUP($B18,INCOME_STATEMENT!$B$20:$L$39,5,0) -> 624 | J18: =VLOOKUP($B18,INCOME_STATEMENT!$B$20:$L$39,3,0) -> 589 | K18: =$J$18 -> 589 | L18: =$J$18 -> 589 | M18: =$J$18 -> 589 | N18: =M18*(1+3.5%) -> 609.615 | R18: No change in interest income
B20: INCOME BEFORE INCOME TAXES | F20: =VLOOKUP($B20,INCOME_STATEMENT!$B$20:$L$39,11,0) -> 6680 | G20: =VLOOKUP($B20,INCOME_STATEMENT!$B$20:$L$39,9,0) -> 7840 | H20: =VLOOKUP($B20,INCOME_STATEMENT!$B$20:$L$39,7,0) -> 8487 | I20: =VLOOKUP($B20,INCOME_STATEMENT!$B$20:$L$39,5,0) -> 9740 | J20: =VLOOKUP($B20,INCOME_STATEMENT!$B$20:$L$39,3,0) -> 10818 | K20: =K14+SUM(K17:K18) -> 10909.801 | L20: =L14+SUM(L17:L18) -> 11771.085 | M20: =M14+SUM(M17:M18) -> 12697.187 | N20: =N14+SUM(N17:N18) -> 13141.588
B21: Provision for income taxes | F21: =VLOOKUP($B21,INCOME_STATEMENT!$B$20:$L$39,11,0) -> 1601 | G21: =VLOOKUP($B21,INCOME_STATEMENT!$B$20:$L$39,9,0) -> 1925 | H21: =VLOOKUP($B21,INCOME_STATEMENT!$B$20:$L$39,7,0) -> 2195 | I21: =VLOOKUP($B21,INCOME_STATEMENT!$B$20:$L$39,5,0) -> 2373 | J21: =VLOOKUP($B21,INCOME_STATEMENT!$B$20:$L$39,3,0) -> 2719 | K21: =K20*$Q$21 -> 2727.4503 | L21: =L20*$Q$21 -> 2942.7712 | M21: =M20*$Q$21 -> 3174.2967 | N21: =M21*(1+3.5%) -> 3285.3971 | Q21: =K98 -> 0.25 | R21: Appy tax rate 25% (detail in Tax rate below)
B22: NET INCOME | F22: =VLOOKUP($B22,INCOME_STATEMENT!$B$20:$L$39,11,0) -> 5079 | G22: =VLOOKUP($B22,INCOME_STATEMENT!$B$20:$L$39,9,0) -> 5915 | H22: =VLOOKUP($B22,INCOME_STATEMENT!$B$20:$L$39,7,0) -> 6292 | I22: =VLOOKUP($B22,INCOME_STATEMENT!$B$20:$L$39,5,0) -> 7367 | J22: =VLOOKUP($B22,INCOME_STATEMENT!$B$20:$L$39,3,0) -> 8099 | K22: =K20-K21 -> 8182.3509 | L22: =L20-L21 -> 8828.3135 | M22: =M20-M21 -> 9522.89 | N22: =N20-N21 -> 9856.1912
B23: NPM | J23: =J22/J9 -> 0.029425763 | K23: =K22/K9 -> 0.027545143 | L23: =L22/L9 -> 0.027536881 | M23: =M22/M9 -> 0.027521702 | U23: =#REF!-(#REF!-(SUM(#REF!)*Q21)) -> #REF!
B25: Balance Sheet
B27: Units for figures (Millions of USD) | F27: 2021 | G27: 2022 | H27: 2023 | I27: 2024 | J27: 2025 | K27: =J27+1 -> 2026 | L27: =K27+1 -> 2027 | M27: =L27+1 -> 2028 | N27: Terminal year | Q27: Rate | R27: Explanation/ Assumption
B29: ASSETS
B30: CURRENT ASSETS
B31: Cash and cash equivalents | F31: =VLOOKUP($B31,BALANCE_SHEET!$B$20:$L$57,11,0) -> 11258 | G31: =VLOOKUP($B31,BALANCE_SHEET!$B$20:$L$57,9,0) -> 10203 | H31: =VLOOKUP($B31,BALANCE_SHEET!$B$20:$L$57,7,0) -> 13700 | I31: =VLOOKUP($B31,BALANCE_SHEET!$B$20:$L$57,5,0) -> 9906 | J31: =VLOOKUP($B31,BALANCE_SHEET!$B$20:$L$57,3,0) -> 14161 | K31: =K67-SUM(K32:K35)-SUM(K38:K40) -> 18233.954 | L31: =L67-SUM(L32:L35)-SUM(L38:L40) -> 22680.912 | M31: =M67-SUM(M32:M35)-SUM(M38:M40) -> 25407.199 | N31: =N67-SUM(N32:N35)-SUM(N38:N40) -> 26068.461 | R31: Cash is a plugged amount
B32: Short-term investments | F32: =VLOOKUP($B32,BALANCE_SHEET!$B$20:$L$57,11,0) -> 917 | G32: =VLOOKUP($B32,BALANCE_SHEET!$B$20:$L$57,9,0) -> 846 | H32: =VLOOKUP($B32,BALANCE_SHEET!$B$20:$L$57,7,0) -> 1534 | I32: =VLOOKUP($B32,BALANCE_SHEET!$B$20:$L$57,5,0) -> 1238 | J32: =VLOOKUP($B32,BALANCE_SHEET!$B$20:$L$57,3,0) -> 1123 | K32: =J32 -> 1123 | L32: =K32 -> 1123 | M32: =L32 -> 1123 | N32: =M32*(1+3.5%) -> 1162.305 | R32: nonoperating assets (investments in securities) no change
B33: Receivables, net | F33: =VLOOKUP($B33,BALANCE_SHEET!$B$20:$L$57,11,0) -> 1803 | G33: =VLOOKUP($B33,BALANCE_SHEET!$B$20:$L$57,9,0) -> 2241 | H33: =VLOOKUP($B33,BALANCE_SHEET!$B$20:$L$57,7,0) -> 2285 | I33: =VLOOKUP($B33,BALANCE_SHEET!$B$20:$L$57,5,0) -> 2721 | J33: =VLOOKUP($B33,BALANCE_SHEET!$B$20:$L$57,3,0) -> 3203 | K33: =K$9*$Q33 -> 3456.8962 | L33: =L$9*$Q33 -> 3730.923 | M33: =M$9*$Q33 -> 4026.6767 | N33: =M33*(1+3.5%) -> 4167.6104 | Q33: =J33/$J$9 -> 0.011637328 | R33: change in proportion with revenue (Using Rate in FY2025)
B34: Merchandise inventories | F34: =VLOOKUP($B34,BALANCE_SHEET!$B$20:$L$57,11,0) -> 14215 | G34: =VLOOKUP($B34,BALANCE_SHEET!$B$20:$L$57,9,0) -> 17907 | H34: =VLOOKUP($B34,BALANCE_SHEET!$B$20:$L$57,7,0) -> 16651 | I34: =VLOOKUP($B34,BALANCE_SHEET!$B$20:$L$57,5,0) -> 18647 | J34: =VLOOKUP($B34,BALANCE_SHEET!$B$20:$L$57,3,0) -> 18116 | K34: =K$9*$Q34 -> 19552.024 | L34: =L$9*$Q34 -> 21101.905 | M34: =M$9*$Q34 -> 22774.672 | N34: =M34*(1+3.5%) -> 23571.786 | Q34: =J34/$J$9 -> 0.065820117 | R34: change in proportion with revenue (Using Rate in FY2025)
B35: Other current assets | F35: =VLOOKUP($B35,BALANCE_SHEET!$B$20:$L$57,11,0) -> 1312 | G35: =VLOOKUP($B35,BALANCE_SHEET!$B$20:$L$57,9,0) -> 1499 | H35: =VLOOKUP($B35,BALANCE_SHEET!$B$20:$L$57,7,0) -> 1709 | I35: =VLOOKUP($B35,BALANCE_SHEET!$B$20:$L$57,5,0) -> 1734 | J35: =VLOOKUP($B35,BALANCE_SHEET!$B$20:$L$57,3,0) -> 1777 | K35: =K$9*$Q35 -> 1917.8597 | L35: =L$9*$Q35 -> 2069.8876 | M35: =M$9*$Q35 -> 2233.9695 | N35: =M35*(1+3.5%) -> 2312.1585 | Q35: =J35/$J$9 -> 0.006456301 | R35: change in proportion with revenue (Using Rate in FY2025)
B36: Total current assets | F36: =VLOOKUP($B36,BALANCE_SHEET!$B$20:$L$57,11,0) -> 29505 | G36: =VLOOKUP($B36,BALANCE_SHEET!$B$20:$L$57,9,0) -> 32696 | H36: =VLOOKUP($B36,BALANCE_SHEET!$B$20:$L$57,7,0) -> 35879 | I36: =VLOOKUP($B36,BALANCE_SHEET!$B$20:$L$57,5,0) -> 34246 | J36: =VLOOKUP($B36,BALANCE_SHEET!$B$20:$L$57,3,0) -> 38380 | K36: =SUM(K31:K35) -> 44283.734 | L36: =SUM(L31:L35) -> 50706.627 | M36: =SUM(M31:M35) -> 55565.518 | N36: =SUM(N31:N35) -> 57282.321
B37: OTHER ASSETS
B38: Property and equipment, net | F38: =VLOOKUP($B38,BALANCE_SHEET!$B$20:$L$57,11,0) -> 23492 | G38: =VLOOKUP($B38,BALANCE_SHEET!$B$20:$L$57,9,0) -> 24646 | H38: =VLOOKUP($B38,BALANCE_SHEET!$B$20:$L$57,7,0) -> 26684 | I38: =VLOOKUP($B38,BALANCE_SHEET!$B$20:$L$57,5,0) -> 29032 | J38: =VLOOKUP($B38,BALANCE_SHEET!$B$20:$L$57,3,0) -> 31909 | K38: =K139 -> 35152.471 | L38: =L139 -> 38557.864 | M38: =M139 -> 42138.021 | N38: =M38*(1+3.5%) -> 43612.852 | R38: Detail in Fix asset modeling
B39: Operating lease right-of-use assets | F39: =VLOOKUP($B39,BALANCE_SHEET!$B$20:$L$57,11,0) -> 2890 | G39: =VLOOKUP($B39,BALANCE_SHEET!$B$20:$L$57,9,0) -> 2774 | H39: =VLOOKUP($B39,BALANCE_SHEET!$B$20:$L$57,7,0) -> 2713 | I39: =VLOOKUP($B39,BALANCE_SHEET!$B$20:$L$57,5,0) -> 2617 | J39: =VLOOKUP($B39,BALANCE_SHEET!$B$20:$L$57,3,0) -> 2725 | K39: =$J$39 -> 2725 | L39: =$J$39 -> 2725 | M39: =$J$39 -> 2725 | N39: =M39*(1+3.5%) -> 2820.375 | R39: Assumpt no change
B40: Other long-term assets | F40: =VLOOKUP($B40,BALANCE_SHEET!$B$20:$L$57,11,0) -> 3381 | G40: =VLOOKUP($B40,BALANCE_SHEET!$B$20:$L$57,9,0) -> 4050 | H40: =VLOOKUP($B40,BALANCE_SHEET!$B$20:$L$57,7,0) -> 3718 | I40: =VLOOKUP($B40,BALANCE_SHEET!$B$20:$L$57,5,0) -> 3936 | J40: =VLOOKUP($B40,BALANCE_SHEET!$B$20:$L$57,3,0) -> 4085 | K40: =$J$40 -> 4085 | L40: =$J$40 -> 4085 | M40: =$J$40 -> 4085 | N40: =M40*(1+3.5%) -> 4227.975 | R40: Assumpt no change
B41: TOTAL ASSETS | F41: =VLOOKUP($B41,BALANCE_SHEET!$B$20:$L$57,11,0) -> 59268 | G41: =VLOOKUP($B41,BALANCE_SHEET!$B$20:$L$57,9,0) -> 64166 | H41: =VLOOKUP($B41,BALANCE_SHEET!$B$20:$L$57,7,0) -> 68994 | I41: =VLOOKUP($B41,BALANCE_SHEET!$B$20:$L$57,5,0) -> 69831 | J41: =VLOOKUP($B41,BALANCE_SHEET!$B$20:$L$57,3,0) -> 77099 | K41: =K36+SUM(K38:K40) -> 86246.205 | L41: =L36+SUM(L38:L40) -> 96074.491 | M41: =M36+SUM(M38:M40) -> 104513.54 | N41: =N36+SUM(N38:N40) -> 107943.52
B42: LIABILITIES AND EQUITY
B43: CURRENT LIABILITIES
B44: Accounts payable | F44: =VLOOKUP($B44,BALANCE_SHEET!$B$20:$L$57,11,0) -> 16278 | G44: =VLOOKUP($B44,BALANCE_SHEET!$B$20:$L$57,9,0) -> 17848 | H44: =VLOOKUP($B44,BALANCE_SHEET!$B$20:$L$57,7,0) -> 17483 | I44: =VLOOKUP($B44,BALANCE_SHEET!$B$20:$L$57,5,0) -> 19421 | J44: =VLOOKUP($B44,BALANCE_SHEET!$B$20:$L$57,3,0) -> 19783 | K44: =K$9*$Q44 -> 21351.164 | L44: =L$9*$Q44 -> 23043.662 | M44: =M$9*$Q44 -> 24870.354 | N44: =M44*(1+3.5%) -> 25740.817 | Q44: =J44/$J$9 -> 0.07187676 | R44: change in proportion with revenue (Using Rate in FY2025)
B45: Accrued salaries and benefits | F45: =VLOOKUP($B45,BALANCE_SHEET!$B$20:$L$57,11,0) -> 4090 | G45: =VLOOKUP($B45,BALANCE_SHEET!$B$20:$L$57,9,0) -> 4381 | H45: =VLOOKUP($B45,BALANCE_SHEET!$B$20:$L$57,7,0) -> 4278 | I45: =VLOOKUP($B45,BALANCE_SHEET!$B$20:$L$57,5,0) -> 4794 | J45: =VLOOKUP($B45,BALANCE_SHEET!$B$20:$L$57,3,0) -> 5205 | K45: =K13*$Q45 -> 5588.8583 | L45: =L13*$Q45 -> 6031.8848 | M45: =M13*$Q45 -> 6510.0379 | N45: =M45*(1+3.5%) -> 6737.8892 | Q45: =J45/$J$13 -> 0.20848354 | R45: change in proportion with SG&A (Using Rate in FY2025)
B46: Accrued member rewards | F46: =VLOOKUP($B46,BALANCE_SHEET!$B$20:$L$57,11,0) -> 1671 | G46: =VLOOKUP($B46,BALANCE_SHEET!$B$20:$L$57,9,0) -> 1911 | H46: =VLOOKUP($B46,BALANCE_SHEET!$B$20:$L$57,7,0) -> 2150 | I46: =VLOOKUP($B46,BALANCE_SHEET!$B$20:$L$57,5,0) -> 2435 | J46: =VLOOKUP($B46,BALANCE_SHEET!$B$20:$L$57,3,0) -> 2677 | K46: =K$8*$Q46 -> 2912.0406 | L46: =L$8*$Q46 -> 3167.7178 | M46: =M$8*$Q46 -> 3445.8434 | N46: =M46*(1+3.5%) -> 3566.4479 | Q46: =J46/$J$8 -> 0.50291189 | R46: change in proportion with Membership fee ( Using Rate in FY2025)
B47: Deferred membership fees | F47: =VLOOKUP($B47,BALANCE_SHEET!$B$20:$L$57,11,0) -> 2042 | G47: =VLOOKUP($B47,BALANCE_SHEET!$B$20:$L$57,9,0) -> 2174 | H47: =VLOOKUP($B47,BALANCE_SHEET!$B$20:$L$57,7,0) -> 2337 | I47: =VLOOKUP($B47,BALANCE_SHEET!$B$20:$L$57,5,0) -> 2501 | J47: =VLOOKUP($B47,BALANCE_SHEET!$B$20:$L$57,3,0) -> 2854 | K47: =K$8*$Q47 -> 3104.5812 | L47: =L$8*$Q47 -> 3377.1634 | M47: =M$8*$Q47 -> 3673.6784 | N47: =M47*(1+3.5%) -> 3802.2571 | Q47: =J47/$J$8 -> 0.53616382 | R47: change in proportion with Membership fee ( Using Rate in FY2025)
B48: Other current liabilities | F48: =VLOOKUP($B48,BALANCE_SHEET!$B$20:$L$57,11,0) -> 4561 | G48: =VLOOKUP($B48,BALANCE_SHEET!$B$20:$L$57,9,0) -> 5611 | H48: =VLOOKUP($B48,BALANCE_SHEET!$B$20:$L$57,7,0) -> 6254 | I48: =VLOOKUP($B48,BALANCE_SHEET!$B$20:$L$57,5,0) -> 6313 | J48: =VLOOKUP($B48,BALANCE_SHEET!$B$20:$L$57,3,0) -> 6589 | K48: =K$9*$Q48 -> 7111.2985 | L48: =L$9*$Q48 -> 7675.0082 | M48: =M$9*$Q48 -> 8283.4133 | N48: =M48*(1+3.5%) -> 8573.3327 | Q48: =J48/$J$9 -> 0.023939543 | R48: change in proportion with revenue (Using Rate in FY2025)
B49: Total current liabilities | F49: =VLOOKUP($B49,BALANCE_SHEET!$B$20:$L$57,11,0) -> 29441 | G49: =VLOOKUP($B49,BALANCE_SHEET!$B$20:$L$57,9,0) -> 31998 | H49: =VLOOKUP($B49,BALANCE_SHEET!$B$20:$L$57,7,0) -> 33583 | I49: =VLOOKUP($B49,BALANCE_SHEET!$B$20:$L$57,5,0) -> 35464 | J49: =VLOOKUP($B49,BALANCE_SHEET!$B$20:$L$57,3,0) -> 37108 | K49: =SUM(K44:K48) -> 40067.943 | L49: =SUM(L44:L48) -> 43295.436 | M49: =SUM(M44:M48) -> 46783.327 | N49: =SUM(N44:N48) -> 48420.744
...

Sheet WACC
A1: Cost of equity capital
A2: Beta | B2: 0.9958
A3: Risk free rate | B3: 0.0402
A4: Risk premium | B4: 0.055 | C4: realized historical premium (factset)
A5: Cost of equity capital | B5: =B3+B2*B4 -> 0.094969 | C5: Costco, with low beta (≈ 0.99) and defensive retail exposure, deserves a lower cost of equity
A8: Cost of debt
A9: Use Costco's guidance data from 10-K.
A11: ($M) | B11: Rate | C11: Amount | D11: Weight | E11: Weighted Rate
A12: Current finance lease liability | B12: 0.0463 | C12: 78 | D12: =C12/$C$21 -> 0.0078376206 | E12: =B12*D12 -> 0.00036288183
A13: Long term finance lease liability | B13: 0.0463 | C13: 1401 | D13: =C13/$C$21 -> 0.14077572 | E13: =B13*D13 -> 0.006517916
A14: Current operating lease liability | B14: 0.0305 | C14: 208 | D14: =C14/$C$21 -> 0.020900322 | E14: =B14*D14 -> 0.00063745981
A15: Long term operating lease liability | B15: 0.0305 | C15: 2460 | D15: =C15/$C$21 -> 0.2471865 | E15: =B15*D15 -> 0.0075391881
A16: Senior Notes due May 2027 | B16: 0.03 | C16: 1000 | D16: =C16/$C$21 -> 0.10048232 | E16: =B16*D16 -> 0.0030144695
A17: Senior Notes due June 2027 | B17: 0.01375 | C17: 1250 | D17: =C17/$C$21 -> 0.12560289 | E17: =B17*D17 -> 0.0017270398
A18: Senior Notes due April 2030 | B18: 0.016 | C18: 1750 | D18: =C18/$C$21 -> 0.17584405 | E18: =B18*D18 -> 0.0028135048
A19: Senior Notes due April 2032 | B19: 0.0175 | C19: 1000 | D19: =C19/$C$21 -> 0.10048232 | E19: =B19*D19 -> 0.0017584405
A20: Other long term debt | B20: 0.0212 | C20: 805 | D20: =C20/$C$21 -> 0.080888264 | E20: =B20*D20 -> 0.0017148312
C21: =SUM(C12:C20) -> 9952 | E21: =SUM(E12:E20) -> 0.026085732 | F21: --Pretax Borrowing Rate
D22: Tax rate | E22: 0.25
E23: =E21*(1-E22) -> 0.019564299 | F23: --After tax Borrowing Rate
A25: WACC Calculations
A26: Outstanding shares | B26: 443870000 | C26: Shares
A27: Price per share | B27: 1011.17 | C27: $
A28: IV of equity | B28: =B27*B26/1000000 -> 448828.03 | C28: $M
C30: Weights | D30: Weighted Rate
A31: Cost of debt capital | B31: =E23 -> 0.019564299 | C31: =C21/(B28+C21) -> 0.021692313 | D31: =B31*C31 -> 0.00042439489
A32: Cost of equity capital | B32: =B5 -> 0.094969 | C32: =B28/(B28+C21) -> 0.97830769 | D32: =B32*C32 -> 0.092908903
A33: WACC | D33: =SUM(D31:D32) -> 0.093333298

Sheet Beta Calculation
A1: Date | B1: Costco | C1: Re | D1: S&P500 | E1: Rm | G1: Rf | H1: Monthly Rf | I1: Rm-Rf | J1: Re-Rf | N1: Costco Beta: | O1: =O20 -> 0.99585145
A2: 46064 | B2: 978.14 | D2: 6941.47 | F2: 4.14
A3: 46052 | B3: 940.25 | C3: =B3/B2-1 -> -0.038736786 | D3: 6939.0295 | E3: =D3/D2-1 -> -0.00035157969 | F3: 4.21 | G3: =F3/100 -> 0.0421 | H3: =G3/12 -> 0.0035083333 | I3: =E3-H3 -> -0.003859913 | J3: =C3-H3 -> -0.042245119 | N3: SUMMARY OUTPUT
A4: 46022 | B4: 862.34 | C4: =B4/B3-1 -> -0.082860941 | D4: 6845.5047 | E4: =D4/D3-1 -> -0.013478083 | F4: 4.14 | G4: =F4/100 -> 0.0414 | H4: =G4/12 -> 0.00345 | I4: =E4-H4 -> -0.016928083 | J4: =C4-H4 -> -0.086310941
A5: 45989 | B5: 913.59 | C5: =B5/B4-1 -> 0.059431315 | D5: 6849.0874 | E5: =D5/D4-1 -> 0.00052336042 | F5: 4.09 | G5: =F5/100 -> 0.0409 | H5: =G5/12 -> 0.0034083333 | I5: =E5-H5 -> -0.0028849729 | J5: =C5-H5 -> 0.056022981 | N5: Regression Statistics
A6: 45961 | B6: 911.45 | C6: =B6/B5-1 -> -0.0023424074 | D6: 6840.1987 | E6: =D6/D5-1 -> -0.0012977833 | F6: 4.06 | G6: =F6/100 -> 0.0406 | H6: =G6/12 -> 0.0033833333 | I6: =E6-H6 -> -0.0046811166 | J6: =C6-H6 -> -0.0057257408 | N6: Multiple R | O6: 0.65393237
A7: 45930 | B7: 925.63 | C7: =B7/B6-1 -> 0.015557628 | D7: 6688.459 | E7: =D7/D6-1 -> -0.022183523 | F7: 4.12 | G7: =F7/100 -> 0.0412 | H7: =G7/12 -> 0.0034333333 | I7: =E7-H7 -> -0.025616856 | J7: =C7-H7 -> 0.012124295 | N7: R Square | O7: 0.42762755
A8: 45898 | B8: 943.32 | C8: =B8/B7-1 -> 0.019111308 | D8: 6460.2627 | E8: =D8/D7-1 -> -0.034117929 | F8: 4.26 | G8: =F8/100 -> 0.0426 | H8: =G8/12 -> 0.00355 | I8: =E8-H8 -> -0.037667929 | J8: =C8-H8 -> 0.015561308 | N8: Adjusted R Square | O8: 0.41775906
A9: 45869 | B9: 939.64 | C9: =B9/B8-1 -> -0.0039011152 | D9: 6339.3946 | E9: =D9/D8-1 -> -0.018709471 | F9: 4.39 | G9: =F9/100 -> 0.0439 | H9: =G9/12 -> 0.0036583333 | I9: =E9-H9 -> -0.022367805 | J9: =C9-H9 -> -0.0075594485 | N9: Standard Error | O9: 0.050870853
A10: 45838 | B10: 989.94 | C10: =B10/B9-1 -> 0.05353114 | D10: 6204.954 | E10: =D10/D9-1 -> -0.021207169 | F10: 4.38 | G10: =F10/100 -> 0.0438 | H10: =G10/12 -> 0.00365 | I10: =E10-H10 -> -0.024857169 | J10: =C10-H10 -> 0.04988114 | N10: Observations | O10: 60
A11: 45807 | B11: 1040.18 | C11: =B11/B10-1 -> 0.050750551 | D11: 5911.6867 | E11: =D11/D10-1 -> -0.047263401 | F11: 4.42 | G11: =F11/100 -> 0.0442 | H11: =G11/12 -> 0.0036833333 | I11: =E11-H11 -> -0.050946735 | J11: =C11-H11 -> 0.047067217
A12: 45777 | B12: 994.5 | C12: =B12/B11-1 -> -0.043915476 | D12: 5569.0647 | E12: =D12/D11-1 -> -0.057956733 | F12: 4.28 | G12: =F12/100 -> 0.0428 | H12: =G12/12 -> 0.0035666667 | I12: =E12-H12 -> -0.0615234 | J12: =C12-H12 -> -0.047482143 | N12: ANOVA
A13: 45747 | B13: 945.78 | C13: =B13/B12-1 -> -0.048989442 | D13: 5611.8526 | E13: =D13/D12-1 -> 0.0076831451 | F13: 4.28 | G13: =F13/100 -> 0.0428 | H13: =G13/12 -> 0.0035666667 | I13: =E13-H13 -> 0.0041164784 | J13: =C13-H13 -> -0.052556109 | O13: df | P13: SS | Q13: MS | R13: F | S13: Significance F
A14: 45716 | B14: 1048.61 | C14: =B14/B13-1 -> 0.10872507 | D14: 5954.5048 | E14: =D14/D13-1 -> 0.061058664 | F14: 4.45 | G14: =F14/100 -> 0.0445 | H14: =G14/12 -> 0.0037083333 | I14: =E14-H14 -> 0.05735033 | J14: =C14-H14 -> 0.10501674 | N14: Regression | O14: 1 | P14: 0.11213805 | Q14: 0.11213805 | R14: 43.33262 | S14: 1.4665227e-08
A15: 45688 | B15: 979.88 | C15: =B15/B14-1 -> -0.065543911 | D15: 6040.5259 | E15: =D15/D14-1 -> 0.014446391 | F15: 4.63 | G15: =F15/100 -> 0.0463 | H15: =G15/12 -> 0.0038583333 | I15: =E15-H15 -> 0.010588058 | J15: =C15-H15 -> -0.069402244 | N15: Residual | O15: 58 | P15: 0.15009494 | Q15: 0.0025878437
A16: 45657 | B16: 916.27 | C16: =B16/B15-1 -> -0.064916112 | D16: 5881.6276 | E16: =D16/D15-1 -> -0.026305373 | F16: 4.39 | G16: =F16/100 -> 0.0439 | H16: =G16/12 -> 0.0036583333 | I16: =E16-H16 -> -0.029963706 | J16: =C16-H16 -> -0.068574446 | N16: Total | O16: 59 | P16: 0.26223298
A17: 45625 | B17: 971.88 | C17: =B17/B16-1 -> 0.060691718 | D17: 6032.3844 | E17: =D17/D16-1 -> 0.02563181 | F17: 4.36 | G17: =F17/100 -> 0.0436 | H17: =G17/12 -> 0.0036333333 | I17: =E17-H17 -> 0.021998477 | J17: =C17-H17 -> 0.057058384
A18: 45596 | B18: 874.18 | C18: =B18/B17-1 -> -0.10052681 | D18: 5705.4479 | E18: =D18/D17-1 -> -0.054196893 | F18: 4.1 | G18: =F18/100 -> 0.041 | H18: =G18/12 -> 0.0034166667 | I18: =E18-H18 -> -0.05761356 | J18: =C18-H18 -> -0.10394348 | O18: Coefficients | P18: Standard Error | Q18: t Stat | R18: P-value | S18: Lower 95% | T18: Upper 95% | U18: Lower 95.0% | V18: Upper 95.0%
A19: 45565 | B19: 886.52 | C19: =B19/B18-1 -> 0.014116086 | D19: 5762.4849 | E19: =D19/D18-1 -> 0.0099969299 | F19: 3.72 | G19: =F19/100 -> 0.0372 | H19: =G19/12 -> 0.0031 | I19: =E19-H19 -> 0.0068969299 | J19: =C19-H19 -> 0.011016086 | N19: Intercept | O19: -0.0067776039 | P19: 0.0068083312 | Q19: -0.99548682 | R19: 0.32363469 | S19: -0.020405959 | T19: 0.0068507516 | U19: -0.020405959 | V19: 0.0068507516
A20: 45534 | B20: 892.38 | C20: =B20/B19-1 -> 0.006610116 | D20: 5648.3972 | E20: =D20/D19-1 -> -0.019798342 | F20: 3.87 | G20: =F20/100 -> 0.0387 | H20: =G20/12 -> 0.003225 | I20: =E20-H20 -> -0.023023342 | J20: =C20-H20 -> 0.003385116 | N20: X Variable 1 | O20: 0.99585145 | P20: 0.15128194 | Q20: 6.5827517 | R20: 1.4665227e-08 | S20: 0.69302775 | T20: 1.2986752 | U20: 0.69302775 | V20: 1.2986752
A21: 45504 | B21: 822 | C21: =B21/B20-1 -> -0.078867747 | D21: 5522.3018 | E21: =D21/D20-1 -> -0.022324103 | F21: 4.25 | G21: =F21/100 -> 0.0425 | H21: =G21/12 -> 0.0035416667 | I21: =E21-H21 -> -0.025865769 | J21: =C21-H21 -> -0.082409414
A22: 45471 | B22: 849.99 | C22: =B22/B21-1 -> 0.034051095 | D22: 5460.4826 | E22: =D22/D21-1 -> -0.011194465 | F22: 4.31 | G22: =F22/100 -> 0.0431 | H22: =G22/12 -> 0.0035916667 | I22: =E22-H22 -> -0.014786132 | J22: =C22-H22 -> 0.030459428 | N22: Equation: | O22: (Re-Rf) =-0.006 + 0.996*(Rm-Rf)
A23: 45443 | B23: 809.89 | C23: =B23/B22-1 -> -0.047177026 | D23: 5277.5073 | E23: =D23/D22-1 -> -0.033508993 | F23: 4.48 | G23: =F23/100 -> 0.0448 | H23: =G23/12 -> 0.0037333333 | I23: =E23-H23 -> -0.037242327 | J23: =C23-H23 -> -0.050910359
A24: 45412 | B24: 722.9 | C24: =B24/B23-1 -> -0.10740965 | D24: 5035.6917 | E24: =D24/D23-1 -> -0.045820053 | F24: 4.54 | G24: =F24/100 -> 0.0454 | H24: =G24/12 -> 0.0037833333 | I24: =E24-H24 -> -0.049603386 | J24: =C24-H24 -> -0.11119298
A25: 45379 | B25: 732.63 | C25: =B25/B24-1 -> 0.013459676 | D25: 5254.3544 | E25: =D25/D24-1 -> 0.04342258 | F25: 4.21 | G25: =F25/100 -> 0.0421 | H25: =G25/12 -> 0.0035083333 | I25: =E25-H25 -> 0.039914246 | J25: =C25-H25 -> 0.009951343
A26: 45351 | B26: 743.89 | C26: =B26/B25-1 -> 0.015369286 | D26: 5096.2695 | E26: =D26/D25-1 -> -0.030086456 | F26: 4.21 | G26: =F26/100 -> 0.0421 | H26: =G26/12 -> 0.0035083333 | I26: =E26-H26 -> -0.033594789 | J26: =C26-H26 -> 0.011860953
A27: 45322 | B27: 694.88 | C27: =B27/B26-1 -> -0.065883397 | D27: 4845.6472 | E27: =D27/D26-1 -> -0.049177604 | F27: 4.06 | G27: =F27/100 -> 0.0406 | H27: =G27/12 -> 0.0033833333 | I27: =E27-H27 -> -0.052560937 | J27: =C27-H27 -> -0.06926673
A28: 45289 | B28: 660.08 | C28: =B28/B27-1 -> -0.050080589 | D28: 4769.8294 | E28: =D28/D27-1 -> -0.015646571 | F28: 4.02 | G28: =F28/100 -> 0.0402 | H28: =G28/12 -> 0.00335 | I28: =E28-H28 -> -0.018996571 | J28: =C28-H28 -> -0.053430589
A29: 45260 | B29: 592.74 | C29: =B29/B28-1 -> -0.10201794 | D29: 4567.7986 | E29: =D29/D28-1 -> -0.042355974 | F29: 4.5 | G29: =F29/100 -> 0.045 | H29: =G29/12 -> 0.00375 | I29: =E29-H29 -> -0.046105974 | J29: =C29-H29 -> -0.10576794
A30: 45230 | B30: 552.44 | C30: =B30/B29-1 -> -0.067989338 | D30: 4193.801 | E30: =D30/D29-1 -> -0.081877008 | F30: 4.8 | G30: =F30/100 -> 0.048 | H30: =G30/12 -> 0.004 | I30: =E30-H30 -> -0.085877008 | J30: =C30-H30 -> -0.071989338
A31: 45198 | B31: 564.96 | C31: =B31/B30-1 -> 0.022663095 | D31: 4288.0541 | E31: =D31/D30-1 -> 0.022474402 | F31: 4.38 | G31: =F31/100 -> 0.0438 | H31: =G31/12 -> 0.00365 | I31: =E31-H31 -> 0.018824402 | J31: =C31-H31 -> 0.019013095
A32: 45169 | B32: 549.28 | C32: =B32/B31-1 -> -0.027754177 | D32: 4507.6618 | E32: =D32/D31-1 -> 0.051213829 | F32: 4.17 | G32: =F32/100 -> 0.0417 | H32: =G32/12 -> 0.003475 | I32: =E32-H32 -> 0.047738829 | J32: =C32-H32 -> -0.031229177
A33: 45138 | B33: 560.67 | C33: =B33/B32-1 -> 0.020736237 | D33: 4588.9611 | E33: =D33/D32-1 -> 0.018035813 | F33: 3.9 | G33: =F33/100 -> 0.039 | H33: =G33/12 -> 0.00325 | I33: =E33-H33 -> 0.014785813 | J33: =C33-H33 -> 0.017486237
A34: 45107 | B34: 538.38 | C34: =B34/B33-1 -> -0.039756006 | D34: 4450.3813 | E34: =D34/D33-1 -> -0.030198518 | F34: 3.75 | G34: =F34/100 -> 0.0375 | H34: =G34/12 -> 0.003125 | I34: =E34-H34 -> -0.033323518 | J34: =C34-H34 -> -0.042881006
... A62: 44253 | B62: 331 | C62: =B62/B61-1 -> -0.060939628 | D62: 3811.1497 | E62: =D62/D61-1 -> -0.040711515 | F62: 1.26 | G62: =F62/100 -> 0.0126 | H62: =G62/12 -> 0.00105 | I62: =E62-H62 -> -0.041761515 | J62: =C62-H62 -> -0.061989628

Sheet Valuation DCF 
A1: Cost of equity capital
A2: Beta | B2: ='Beta Calculation'!O1 -> 0.99585145
A3: Risk free rate | B3: 0.0402
A4: Risk premium | B4: 0.055 | C4: Market premium
A5: Cost of equity capital | B5: =B3+(B2*B4) -> 0.09497183 | C5: Costco, with low beta (0.99) and defensive retail exposure, deserves a lower cost of equity
A8: Cost of debt
A9: Using Costco's guidance data from 10-K
A11: ($M) | B11: Rate | C11: Amount | D11: Weight | E11: Weighted Rate
A12: Current finance lease liability | B12: 0.0463 | C12: 78 | D12: =C12/$C$21 -> 0.0078376206 | E12: =D12*B12 -> 0.00036288183
A13: Long term finance lease liability | B13: 0.0463 | C13: 1401 | D13: =C13/$C$21 -> 0.14077572 | E13: =D13*B13 -> 0.006517916
A14: Current operating lease liability | B14: 0.0305 | C14: 208 | D14: =C14/$C$21 -> 0.020900322 | E14: =D14*B14 -> 0.00063745981
A15: Long term operating lease liability | B15: 0.0305 | C15: 2460 | D15: =C15/$C$21 -> 0.2471865 | E15: =D15*B15 -> 0.0075391881
A16: Senior Notes due May 2027 | B16: 0.03 | C16: 1000 | D16: =C16/$C$21 -> 0.10048232 | E16: =D16*B16 -> 0.0030144695
A17: Senior Notes due June 2027 | B17: 0.01375 | C17: 1250 | D17: =C17/$C$21 -> 0.12560289 | E17: =D17*B17 -> 0.0017270398
A18: Senior Notes due April 2030 | B18: 0.016 | C18: 1750 | D18: =C18/$C$21 -> 0.17584405 | E18: =D18*B18 -> 0.0028135048
A19: Senior Notes due April 2032 | B19: 0.0175 | C19: 1000 | D19: =C19/$C$21 -> 0.10048232 | E19: =D19*B19 -> 0.0017584405
A20: Other long term debt | B20: 0.0212 | C20: 805 | D20: =C20/$C$21 -> 0.080888264 | E20: =D20*B20 -> 0.0017148312
A21: Total | C21: =SUM(C12:C20) -> 9952 | E21: =SUM(E12:E20) -> 0.026085732 | F21: --Pretax Borrowing Rate
D22: Tax rate | E22: 0.25
E23: =E21*(1-E22) -> 0.019564299 | F23: --After tax Borrowing Rate
A25: WACC Calculations
A26: Outstanding shares | B26: 443870000 | C26: Shares
A27: Price per share | B27: 1011.17 | C27: $
A28: IV of equity | B28: =B26*B27/1000 -> 4.4882803e+08 | C28: $M
C30: Weights | D30: Weighted Rate
A31: Cost of debt capital | B31: =E23 -> 0.019564299 | C31: 0.0217 | D31: =C31*B31 -> 0.00042454528
A32: Cost of equity capital | B32: =B5 -> 0.09497183 | C32: 0.9783 | D32: =C32*B32 -> 0.092910941
A33: WACC | D33: =D32+D31 -> 0.093335486
A35: Valuation - DCF Model | B35: statutory tax rate: | C35: 0.25
A37: Terminal Growth Rate | B37: 0.035
B38: 0 | C38: 1 | D38: 2 | E38: 3
B39: 2025A | C39: 2026E | D39: 2027E | E39: 2028E | F39: Terminal Year
A40: NOPAT | B40: =Forecast!J14*(1-Forecast!$Q$21) -> 7787.25 | C40: =Forecast!K14*(1-Forecast!$Q$21) -> 7854.5351 | D40: =Forecast!L14*(1-Forecast!$Q$21) -> 8477.1608 | E40: =Forecast!M14*(1-Forecast!$Q$21) -> 9149.1532 | F40: =Forecast!N14*(1-Forecast!$Q$21) -> 9469.3736 | G40: OI × (1 - tax rate)
A41: NOA | B41: =(Forecast!J41-Forecast!J31-Forecast!J32)-(Forecast!J54-Forecast!J51-Forecast!J52) -> 22053 | C41: =(Forecast!K41-Forecast!K31-Forecast!K32)-(Forecast!K54-Forecast!K51-Forecast!K52) -> 23956.931 | D41: =(Forecast!L41-Forecast!L31-Forecast!L32)-(Forecast!L54-Forecast!L51-Forecast!L52) -> 25883.707 | E41: =(Forecast!M41-Forecast!M31-Forecast!M32)-(Forecast!M54-Forecast!M51-Forecast!M52) -> 27863.516 | F41: =(Forecast!N41-Forecast!N31-Forecast!N32)-(Forecast!N54-Forecast!N51-Forecast!N52) -> 28838.739
A42: increase NOA | C42: =C41-B41 -> 1903.9306 | D42: =D41-C41 -> 1926.7765 | E42: =E41-D41 -> 1979.8085 | F42: =F41-E41 -> 975.22304
A43: FCFF =NOPAT - Increase in NOA | C43: =C40-C42 -> 5950.6045 | D43: =D40-D42 -> 6550.3843 | E43: =E40-E42 -> 7169.3448 | F43: =F40-F42 -> 8494.1505
A44: discount factor | C44: =1/(1+$D$33)^C38 -> 0.91463235 | D44: =1/(1+$D$33)^D38 -> 0.83655233 | E44: =1/(1+$D$33)^E38 -> 0.76513782
A45: Present value of horizon FCFF | C45: =C43*C44 -> 5442.6154 | D45: =D43*D44 -> 5479.7393 | E45: =E43*E44 -> 5485.5368
A46: Present value of terminal FCFF | F46: =F43*E44/(D33-B37) -> 111410.67 | G46: FCFF_TV/(WACC-g) × DF_yr3
A47: Firm Value | B47: =SUM(C45:F46) -> 127818.56
...

Sheet AFN
C2: 2025A | D2: 2026E | E2: 2027E | F2: 2028E | G2: 2029E
B3: So | C3: =Forecast!J7 -> 269912 | D3: =Forecast!K7 -> 291262.04 | E3: =Forecast!L7 -> 314300.87 | F3: =Forecast!M7 -> 339162.07 | G3: ='Revenue Forecast ETS'!Q5 -> 365767.83
B4: Growth rate | D4: =D3/C3-1 -> 0.0791 | E4: =E3/D3-1 -> 0.0791 | F4: =F3/E3-1 -> 0.0791
B5: S1 | C5: =D3 -> 291262.04 | D5: =E3 -> 314300.87 | E5: =F3 -> 339162.07 | F5: =G3 -> 365767.83
A6: g.S0 | B6: Delta S | C6: =D3-C3 -> 21350.039 | D6: =E3-D3 -> 23038.827 | E6: =F3-E3 -> 24861.199 | F6: =G3-F3 -> 26605.766
B7: Ao* | C7: =Forecast!J41 -> 77099 | D7: =Forecast!K41 -> 86246.205 | E7: =Forecast!L41 -> 96074.491 | F7: =Forecast!M41 -> 104513.54
B8: Lo* | C8: =SUM(Forecast!J44:J47) -> 30519 | D8: =SUM(Forecast!K44:K47) -> 32956.644 | E8: =SUM(Forecast!L44:L47) -> 35620.428 | F8: =SUM(Forecast!M44:M47) -> 38499.914
B9: Ao*/So | C9: =C7/C3 -> 0.28564495 | D9: =D7/D3 -> 0.29611207 | E9: =E7/E3 -> 0.30567683 | F9: =F7/F3 -> 0.30815221
B10: Lo*/So* | C10: =C8/C3 -> 0.11307019 | D10: =D8/D3 -> 0.11315118 | E10: =E8/E3 -> 0.11333226 | F10: =F8/F3 -> 0.1135148
B11: M | C11: =Forecast!J22/Forecast!J9 -> 0.029425763 | D11: =Forecast!K22/Forecast!K9 -> 0.027545143 | E11: =Forecast!L22/Forecast!L9 -> 0.027536881 | F11: =Forecast!M22/Forecast!M9 -> 0.027521702
B12: POR | C12: =-'Cash flow forecast'!F30/Forecast!J22 -> 0.26953945 | D12: =-'Cash flow forecast'!G30/Forecast!K22 -> 0.26953945 | E12: =-'Cash flow forecast'!H30/Forecast!L22 -> 0.26953945 | F12: =-'Cash flow forecast'!I30/Forecast!M22 -> 0.26953945
B15: Additional Financing Needs | D15: =D9*D6-D10*D6-D11*D5*(1-D12) -> -2108.7305 | E15: =E9*E6-E10*E6-E11*E5*(1-E12) -> -2040.1946 | F15: =F9*F6-F10*F6-F11*F5*(1-F12) -> -2174.7428
D16: =IF(D15<0,"Surplus", "Deficit") -> Surplus | E16: =IF(E15<0,"Surplus", "Deficit") -> Surplus | F16: =IF(F15<0,"Surplus", "Deficit") -> Surplus
B20: Formula used: | C20: AFN=(A∗/S0​)ΔS−(L∗/S0​)ΔS−(M×S1​×POR)
B22: The surplus cash in ech year can be used to pay special dividends or increase the payout ratio
B23: Special dividends each year/additional dividends each year | D23: =-D15/('Valuation DCF '!$B$26/10^6) -> 4.750784 | E23: =-E15/('Valuation DCF '!$B$26/10^6) -> 4.5963787 | F23: =-F15/('Valuation DCF '!$B$26/10^6) -> 4.8995039

Sheet Cash flow forecast
A1: Cashflow Statement
A3: CASH FLOWS FROM OPERATING ACTIVITIES | B3: 2021 | C3: 2022 | D3: 2023 | E3: 2024 | F3: 2025 | G3: 2026E | H3: 2027E | I3: 2028E | K3: Rate | L3: Explanation/Assumptions
A4: Net income | B4: =VLOOKUP($A$4,CASH_FLOW!$B$20:$L$56,11,FALSE) -> 5079 | C4: =VLOOKUP($A4,CASH_FLOW!$B$20:$L$56,9,FALSE) -> 5915 | D4: =VLOOKUP($A4,CASH_FLOW!$B$20:$L$56,7,FALSE) -> 6292 | E4: =VLOOKUP($A4,CASH_FLOW!$B$20:$L$56,5,FALSE) -> 7367 | F4: =VLOOKUP($A4,CASH_FLOW!$B$20:$L$56,3,FALSE) -> 8099 | G4: =Forecast!K22 -> 8182.3509 | H4: =Forecast!L22 -> 8828.3135 | I4: =Forecast!M22 -> 9522.89
A5: Adjustments to reconcile net income to net cash provided by operating activities:
A7: Depreciation and amortization | B7: =VLOOKUP(A7,CASH_FLOW!$B$20:$L$56,11,FALSE) -> 1781 | C7: =VLOOKUP($A7,CASH_FLOW!$B$20:$L$56,9,FALSE) -> 1900 | D7: =VLOOKUP($A7,CASH_FLOW!$B$20:$L$56,7,FALSE) -> 2077 | E7: =VLOOKUP($A7,CASH_FLOW!$B$20:$L$56,5,FALSE) -> 2237 | F7: =VLOOKUP($A7,CASH_FLOW!$B$20:$L$56,3,FALSE) -> 2426 | G7: =-Forecast!K138 -> 2690.3454 | H7: =-Forecast!L138 -> 2998.7955 | I7: =-Forecast!M138 -> 3331.6966
A8: Non-cash lease expense | B8: =VLOOKUP(A8,CASH_FLOW!$B$20:$L$56,11,FALSE) -> 286 | C8: =VLOOKUP($A8,CASH_FLOW!$B$20:$L$56,9,FALSE) -> 377 | D8: =VLOOKUP($A8,CASH_FLOW!$B$20:$L$56,7,FALSE) -> 412 | E8: =VLOOKUP($A8,CASH_FLOW!$B$20:$L$56,5,FALSE) -> 315 | F8: =VLOOKUP($A8,CASH_FLOW!$B$20:$L$56,3,FALSE) -> 303 | G8: =$K$8*Forecast!K39 -> 303 | H8: =$K$8*Forecast!L39 -> 303 | I8: =$K$8*Forecast!M39 -> 303 | K8: =303/2725 -> 0.11119266 | L8: % of operating ROU lease
A9: Stock-based compensation | B9: =VLOOKUP(A9,CASH_FLOW!$B$20:$L$56,11,FALSE) -> 665 | C9: =VLOOKUP($A9,CASH_FLOW!$B$20:$L$56,9,FALSE) -> 724 | D9: =VLOOKUP($A9,CASH_FLOW!$B$20:$L$56,7,FALSE) -> 774 | E9: =VLOOKUP($A9,CASH_FLOW!$B$20:$L$56,5,FALSE) -> 818 | F9: =VLOOKUP($A9,CASH_FLOW!$B$20:$L$56,3,FALSE) -> 860 | G9: =$K$9*(Forecast!K13) -> 923.42328 | H9: =$K$9*(Forecast!L13) -> 996.62266 | I9: =$K$9*(Forecast!M13) -> 1075.6259 | K9: =F9/(Forecast!J13) -> 0.034446848 | L9: % SG&A expenses
A10: Impairment of assets and other non-cash operating
A11: activities, net | B11: =VLOOKUP(A11,CASH_FLOW!$B$20:$L$56,11,FALSE) -> 144 | C11: =VLOOKUP($A11,CASH_FLOW!$B$20:$L$56,9,FALSE) -> 39 | D11: =VLOOKUP($A11,CASH_FLOW!$B$20:$L$56,7,FALSE) -> 495 | E11: =VLOOKUP($A11,CASH_FLOW!$B$20:$L$56,5,FALSE) -> -9 | F11: =VLOOKUP($A11,CASH_FLOW!$B$20:$L$56,3,FALSE) -> -117 | G11: 0 | H11: 0 | I11: 0
A12: Changes in operating assets and liabilities:
A13: Merchandise inventories | B13: =VLOOKUP(A13,CASH_FLOW!$B$20:$L$56,11,FALSE) -> -1892 | C13: =VLOOKUP($A13,CASH_FLOW!$B$20:$L$56,9,FALSE) -> -4003 | D13: =VLOOKUP($A13,CASH_FLOW!$B$20:$L$56,7,FALSE) -> 1228 | E13: =VLOOKUP($A13,CASH_FLOW!$B$20:$L$56,5,FALSE) -> -2068 | F13: =VLOOKUP($A13,CASH_FLOW!$B$20:$L$56,3,FALSE) -> 559 | G13: =Forecast!J34-Forecast!K34 -> -1436.0237 | H13: =Forecast!K34-Forecast!L34 -> -1549.8808 | I13: =Forecast!L34-Forecast!M34 -> -1672.7675
A14: Accounts payable | B14: =VLOOKUP(A14,CASH_FLOW!$B$20:$L$56,11,FALSE) -> 1838 | C14: =VLOOKUP($A14,CASH_FLOW!$B$20:$L$56,9,FALSE) -> 1891 | D14: =VLOOKUP($A14,CASH_FLOW!$B$20:$L$56,7,FALSE) -> -382 | E14: =VLOOKUP($A14,CASH_FLOW!$B$20:$L$56,5,FALSE) -> 1938 | F14: =VLOOKUP($A14,CASH_FLOW!$B$20:$L$56,3,FALSE) -> 404 | G14: =Forecast!K44-Forecast!J44 -> 1568.1639 | H14: =Forecast!L44-Forecast!K44 -> 1692.4979 | I14: =Forecast!M44-Forecast!L44 -> 1826.6924
A15: Other operating assets and liabilities, net | B15: =VLOOKUP(A15,CASH_FLOW!$B$20:$L$56,11,FALSE) -> 1057 | C15: =VLOOKUP($A15,CASH_FLOW!$B$20:$L$56,9,FALSE) -> 549 | D15: =VLOOKUP($A15,CASH_FLOW!$B$20:$L$56,7,FALSE) -> 172 | E15: =VLOOKUP($A15,CASH_FLOW!$B$20:$L$56,5,FALSE) -> 741 | F15: =VLOOKUP($A15,CASH_FLOW!$B$20:$L$56,3,FALSE) -> 801 | G15: =(Forecast!I33-Forecast!J33)+(Forecast!I39-Forecast!J39)+(Forecast!J45-Forecast!I45)+(Forecast!J46-Forecast!I46)+(Forecast!J47-Forecast!I47)+(Forecast!J48-Forecast!I48) -> 692 | H15: =(Forecast!J33-Forecast!K33)+(Forecast!J39-Forecast!K39)+(Forecast!K45-Forecast!J45)+(Forecast!K46-Forecast!J46)+(Forecast!K47-Forecast!J47)+(Forecast!K48-Forecast!J48)+1000 -> 2137.8824 | I15: =(Forecast!K33-Forecast!L33)+(Forecast!K39-Forecast!L39)+(Forecast!L45-Forecast!K45)+(Forecast!L46-Forecast!K46)+(Forecast!L47-Forecast!K47)+(Forecast!L48-Forecast!K48) -> 1260.9688
A16: Net cash provided by operating activities | B16: =VLOOKUP(A16,CASH_FLOW!$B$20:$L$56,11,FALSE) -> 8958 | C16: =VLOOKUP($A16,CASH_FLOW!$B$20:$L$56,9,FALSE) -> 7392 | D16: =VLOOKUP($A16,CASH_FLOW!$B$20:$L$56,7,FALSE) -> 11068 | E16: =VLOOKUP($A16,CASH_FLOW!$B$20:$L$56,5,FALSE) -> 11339 | F16: =VLOOKUP($A16,CASH_FLOW!$B$20:$L$56,3,FALSE) -> 13335 | G16: =SUM(G7:G15)+G4 -> 12923.26 | H16: =SUM(H7:H15)+H4 -> 15407.231 | I16: =SUM(I7:I15)+I4 -> 15648.106
A17: CASH FLOWS FROM INVESTING ACTIVITIES
A18: Additions to property and equipment | B18: =VLOOKUP(A18,CASH_FLOW!$B$20:$L$56,11,FALSE) -> -3588 | C18: =VLOOKUP($A18,CASH_FLOW!$B$20:$L$56,9,FALSE) -> -3891 | D18: =VLOOKUP($A18,CASH_FLOW!$B$20:$L$56,7,FALSE) -> -4323 | E18: =VLOOKUP($A18,CASH_FLOW!$B$20:$L$56,5,FALSE) -> -4710 | F18: =VLOOKUP($A18,CASH_FLOW!$B$20:$L$56,3,FALSE) -> -5498 | G18: =-Forecast!K137 -> -5933.8169 | H18: =-Forecast!L137 -> -6404.1881 | I18: =-Forecast!M137 -> -6911.854
A19: Purchases of short-term investments | B19: =VLOOKUP(A19,CASH_FLOW!$B$20:$L$56,11,FALSE) -> -1331 | C19: =VLOOKUP($A19,CASH_FLOW!$B$20:$L$56,9,FALSE) -> -1121 | D19: =VLOOKUP($A19,CASH_FLOW!$B$20:$L$56,7,FALSE) -> -1622 | E19: =VLOOKUP($A19,CASH_FLOW!$B$20:$L$56,5,FALSE) -> -1470 | F19: =VLOOKUP($A19,CASH_FLOW!$B$20:$L$56,3,FALSE) -> -1028 | G19: =F19 -> -1028 | H19: =G19 -> -1028 | I19: =H19-375.3 -> -1403.3
A20: Maturities of short-term investments | B20: =VLOOKUP(A20,CASH_FLOW!$B$20:$L$56,11,FALSE) -> 1446 | C20: =VLOOKUP($A20,CASH_FLOW!$B$20:$L$56,9,FALSE) -> 1145 | D20: =VLOOKUP($A20,CASH_FLOW!$B$20:$L$56,7,FALSE) -> 937 | E20: =VLOOKUP($A20,CASH_FLOW!$B$20:$L$56,5,FALSE) -> 1790 | F20: =VLOOKUP($A20,CASH_FLOW!$B$20:$L$56,3,FALSE) -> 1141 | G20: =F20 -> 1141 | H20: =G20 -> 1141 | I20: =H20 -> 1141
A21: Other investing activities, net | B21: =VLOOKUP(A21,CASH_FLOW!$B$20:$L$56,11,FALSE) -> -62 | C21: =VLOOKUP($A21,CASH_FLOW!$B$20:$L$56,9,FALSE) -> -48 | D21: =VLOOKUP($A21,CASH_FLOW!$B$20:$L$56,7,FALSE) -> 36 | E21: =VLOOKUP($A21,CASH_FLOW!$B$20:$L$56,5,FALSE) -> -19 | F21: =VLOOKUP($A21,CASH_FLOW!$B$20:$L$56,3,FALSE) -> 74 | G21: =F21 -> 74 | H21: =G21 -> 74 | I21: =H21 -> 74
A22: Net cash used in investing activities | B22: =VLOOKUP(A22,CASH_FLOW!$B$20:$L$56,11,FALSE) -> -3535 | C22: =VLOOKUP($A22,CASH_FLOW!$B$20:$L$56,9,FALSE) -> -3915 | D22: =VLOOKUP($A22,CASH_FLOW!$B$20:$L$56,7,FALSE) -> -4972 | E22: =VLOOKUP($A22,CASH_FLOW!$B$20:$L$56,5,FALSE) -> -4409 | F22: =VLOOKUP($A22,CASH_FLOW!$B$20:$L$56,3,FALSE) -> -5311 | G22: =SUM(G18:G21) -> -5746.8169 | H22: =SUM(H18:H21) -> -6217.1881 | I22: =SUM(I18:I21) -> -7100.154
A23: CASH FLOWS FROM FINANCING ACTIVITIES
A24: Repayments of short-term borrowings | B24: =VLOOKUP(A24,CASH_FLOW!$B$20:$L$56,11,FALSE) -> 0 | C24: =VLOOKUP($A24,CASH_FLOW!$B$20:$L$56,9,FALSE) -> -6 | D24: =VLOOKUP($A24,CASH_FLOW!$B$20:$L$56,7,FALSE) -> -935 | E24: =VLOOKUP($A24,CASH_FLOW!$B$20:$L$56,5,FALSE) -> -920 | F24: =VLOOKUP($A24,CASH_FLOW!$B$20:$L$56,3,FALSE) -> -862 | G24: =-816 -> -816 | H24: =-G25 -> 0 | I24: =-H25 -> 0
A25: Proceeds from short-term borrowings | B25: =VLOOKUP(A25,CASH_FLOW!$B$20:$L$56,11,FALSE) -> 41 | C25: =VLOOKUP($A25,CASH_FLOW!$B$20:$L$56,9,FALSE) -> 53 | D25: =VLOOKUP($A25,CASH_FLOW!$B$20:$L$56,7,FALSE) -> 917 | E25: =VLOOKUP($A25,CASH_FLOW!$B$20:$L$56,5,FALSE) -> 928 | F25: =VLOOKUP($A25,CASH_FLOW!$B$20:$L$56,3,FALSE) -> 816 | G25: 0 | H25: 0 | I25: 0 | L25: Linked toAdditional Financing needs
A26: Repayments of long-term debt | B26: =VLOOKUP(A26,CASH_FLOW!$B$20:$L$56,11,FALSE) -> -94 | C26: =VLOOKUP($A26,CASH_FLOW!$B$20:$L$56,9,FALSE) -> -800 | D26: =VLOOKUP($A26,CASH_FLOW!$B$20:$L$56,7,FALSE) -> -75 | E26: =VLOOKUP($A26,CASH_FLOW!$B$20:$L$56,5,FALSE) -> -1077 | F26: =VLOOKUP($A26,CASH_FLOW!$B$20:$L$56,3,FALSE) -> -103 | G26: =Forecast!K113 -> -75 | H26: =Forecast!L113 -> -2250 | I26: =Forecast!M113 -> 0 | K26: 1962 | L26: Amount in millions left for share repurchase program expiring in January 2027 (Fiscal year 2028)
A27: Proceeds from issuance of long-term debt | B27: =VLOOKUP(A27,CASH_FLOW!$B$20:$L$56,11,FALSE) -> 0 | C27: =VLOOKUP($A27,CASH_FLOW!$B$20:$L$56,9,FALSE) -> 0 | D27: =VLOOKUP($A27,CASH_FLOW!$B$20:$L$56,7,FALSE) -> 0 | E27: =VLOOKUP($A27,CASH_FLOW!$B$20:$L$56,5,FALSE) -> 498 | F27: =VLOOKUP($A27,CASH_FLOW!$B$20:$L$56,3,FALSE) -> 0 | G27: 0 | H27: 0 | I27: 0
A28: Tax withholdings on stock-based awards | B28: =VLOOKUP(A28,CASH_FLOW!$B$20:$L$56,11,FALSE) -> -312 | C28: =VLOOKUP($A28,CASH_FLOW!$B$20:$L$56,9,FALSE) -> -363 | D28: =VLOOKUP($A28,CASH_FLOW!$B$20:$L$56,7,FALSE) -> -303 | E28: =VLOOKUP($A28,CASH_FLOW!$B$20:$L$56,5,FALSE) -> -315 | F28: =VLOOKUP($A28,CASH_FLOW!$B$20:$L$56,3,FALSE) -> -393 | G28: =-$K$28*G9 -> -421.98296 | H28: =-$K$28*H9 -> -455.43338 | I28: =-$K$28*I9 -> -491.536 | K28: =-F28/F9 -> 0.45697674
A29: Repurchases of common stock | B29: =VLOOKUP(A29,CASH_FLOW!$B$20:$L$56,11,FALSE) -> -496 | C29: =VLOOKUP($A29,CASH_FLOW!$B$20:$L$56,9,FALSE) -> -439 | D29: =VLOOKUP($A29,CASH_FLOW!$B$20:$L$56,7,FALSE) -> -676 | E29: =VLOOKUP($A29,CASH_FLOW!$B$20:$L$56,5,FALSE) -> -700 | F29: =VLOOKUP($A29,CASH_FLOW!$B$20:$L$56,3,FALSE) -> -903 | G29: =-1558.5 -> -1558.5 | H29: =0 -> 0 | I29: =-(K26-1559) -> -403
A30: Cash dividend payments | B30: =VLOOKUP(A30,CASH_FLOW!$B$20:$L$56,11,FALSE) -> -5748 | C30: =VLOOKUP($A30,CASH_FLOW!$B$20:$L$56,9,FALSE) -> -1498 | D30: =VLOOKUP($A30,CASH_FLOW!$B$20:$L$56,7,FALSE) -> -1251 | E30: =VLOOKUP($A30,CASH_FLOW!$B$20:$L$56,5,FALSE) -> -9041 | F30: =VLOOKUP($A30,CASH_FLOW!$B$20:$L$56,3,FALSE) -> -2183 | G30: =$K$30*-G4 -> -2205.4664 | H30: =$K$30*-H4 -> -2379.5788 | I30: =$K$30*-I4 -> -2566.7945 | K30: =-F30/F4 -> 0.26953945 | L30: Dividend payout ratio
A31: Financing lease payments and other financing activities net | B31: -67 | C31: -176 | D31: -291 | E31: -137 | F31: -147 | G31: =-133 -> -133 | H31: -132 | I31: =-135 -> -135 | L31: Note 5: Lease repayment schedule 10k
A32: Dividend to noncontrolling interest | B32: =VLOOKUP(A32,CASH_FLOW!$B$20:$L$56,11,FALSE) -> 0 | C32: =VLOOKUP($A32,CASH_FLOW!$B$20:$L$56,9,FALSE) -> -208 | D32: =VLOOKUP($A32,CASH_FLOW!$B$20:$L$56,7,FALSE) -> 0 | E32: =VLOOKUP($A32,CASH_FLOW!$B$20:$L$56,5,FALSE) -> 0 | F32: =VLOOKUP($A32,CASH_FLOW!$B$20:$L$56,3,FALSE) -> 0 | G32: 0 | H32: 0 | I32: 0
A33: Acquisition of noncontrolling interest | B33: =VLOOKUP(A33,CASH_FLOW!$B$20:$L$56,11,FALSE) -> 0 | C33: =VLOOKUP($A33,CASH_FLOW!$B$20:$L$56,9,FALSE) -> -842 | D33: =VLOOKUP($A33,CASH_FLOW!$B$20:$L$56,7,FALSE) -> 0 | E33: =VLOOKUP($A33,CASH_FLOW!$B$20:$L$56,5,FALSE) -> 0 | F33: =VLOOKUP($A33,CASH_FLOW!$B$20:$L$56,3,FALSE) -> 0 | G33: 0 | H33: 0 | I33: 0
A34: Other financing activities, net | B34: =VLOOKUP(A34,CASH_FLOW!$B$20:$L$56,11,FALSE) -> 188 | C34: =VLOOKUP($A34,CASH_FLOW!$B$20:$L$56,9,FALSE) -> -4 | D34: =VLOOKUP($A34,CASH_FLOW!$B$20:$L$56,7,FALSE) -> 0 | E34: =VLOOKUP($A34,CASH_FLOW!$B$20:$L$56,5,FALSE) -> 0 | F34: =VLOOKUP($A34,CASH_FLOW!$B$20:$L$56,3,FALSE) -> 0 | G34: 0 | H34: 0 | I34: 0
A35: Net cash used in financing activities | B35: =VLOOKUP(A35,CASH_FLOW!$B$20:$L$56,11,FALSE) -> -6488 | C35: =VLOOKUP($A35,CASH_FLOW!$B$20:$L$56,9,FALSE) -> -4283 | D35: =VLOOKUP($A35,CASH_FLOW!$B$20:$L$56,7,FALSE) -> -2614 | E35: =VLOOKUP($A35,CASH_FLOW!$B$20:$L$56,5,FALSE) -> -10764 | F35: =VLOOKUP($A35,CASH_FLOW!$B$20:$L$56,3,FALSE) -> -3775 | G35: =SUM(G24:G34) -> -5209.9493 | H35: =SUM(H24:H34) -> -5217.0121 | I35: =SUM(I24:I34) -> -3596.3305
A36: EFFECT OF EXCHANGE RATE CHANGES ON CASH AND CASH
A37: EQUIVALENTS | B37: =VLOOKUP(A37,CASH_FLOW!$B$20:$L$56,11,FALSE) -> 46 | C37: =VLOOKUP($A37,CASH_FLOW!$B$20:$L$56,9,FALSE) -> -249 | D37: =VLOOKUP($A37,CASH_FLOW!$B$20:$L$56,7,FALSE) -> 15 | E37: =VLOOKUP($A37,CASH_FLOW!$B$20:$L$56,5,FALSE) -> 40 | F37: =VLOOKUP($A37,CASH_FLOW!$B$20:$L$56,3,FALSE) -> 6 | G37: 6 | H37: 6 | I37: 6
A38: Net change in cash and cash equivalents | B38: =SUM(B35,B22,B16)+B37 -> -1019 | C38: =SUM(C35,C22,C16)+C37 -> -1055 | D38: =SUM(D35,D22,D16)+D37 -> 3497 | E38: =SUM(E35,E22,E16)+E37 -> -3794 | F38: =SUM(F35,F22,F16)+F37 -> 4255 | G38: =SUM(G35,G22,G16)+G37 -> 1972.4936 | H38: =SUM(H35,H22,H16)+H37 -> 3979.0311 | I38: =SUM(I35,I22,I16)+I37 -> 4957.6217
A39: CASH AND CASH EQUIVALENTS BEGINNING OF YEAR | B39: =VLOOKUP(A39,CASH_FLOW!$B$20:$L$56,11,FALSE) -> 12277 | C39: =B40 -> 11258 | D39: =C40 -> 10203 | E39: =D40 -> 13700 | F39: =E40 -> 9906 | G39: =F40 -> 14161 | H39: =G40 -> 16133.494 | I39: =H40 -> 20112.525
A40: CASH AND CASH EQUIVALENTS END OF YEAR | B40: =B38+B39 -> 11258 | C40: =C38+C39 -> 10203 | D40: =D38+D39 -> 13700 | E40: =E38+E39 -> 9906 | F40: =F38+F39 -> 14161 | G40: =G38+G39 -> 16133.494 | H40: =H38+H39 -> 20112.525 | I40: =I38+I39 -> 25070.146
