Workbook

Sheet Simulator
A1: Simulator for Openera
A4: Variables | B4: Values | D4: Add charts | I4: Yes | J4: 250
A5: Home Price | C5: Enter value | D5: Add charts for quick insight: | I5: No | J5: 0
A6: Down Payment % | C6: Select from list
A7: Down payment amount | B7: =B6*B5 -> 0 | D7: Line chart: Monthly payment vs. Interest rate
A8: Loan Amount | B8: =B5*(1-B6) -> 0
A9: Credit score | B9: 720–739 | C9: Select from list | D9: Column chart: Compare total cost across scenarios
A10: Annual interest rate | B10: =VLOOKUP(B9,'Credit scores & Interest rates'!G3:H10,2,) -> 0.0675
A11: Loan tenure | C11: Select from list
A12: Monthly mortgage | B12: =PMT(B10/12,B11*12,-B8) -> #NUM! | D12: Gauge chart (optional): “Affordability Index” as a % of monthly income
A13: State | C13: Select from list
A14: Annual property tax rate | B14: =VLOOKUP(B13,'Tax rates'!A2:B52,2,FALSE) -> #N/A
A15: Monthly Property tax | B15: =(B14/12)*B5 -> #N/A | D15: Use conditional formatting (e.g. green/yellow/red) to show affordability ranges.
A16: Annual Home Insurance | B16: =VLOOKUP($B$13,'Statewise Insurance'!$A$5:$C$106,2,FALSE) -> #N/A
A17: Monthly Home Insurance | B17: =VLOOKUP($B$13,'Statewise Insurance'!$A$5:$C$106,3,FALSE) -> #N/A
A18: Is the home part of HOA? | C18: Select from list
A19: HOA Fees (Monthly) | B19: =IF(B18="Yes", J4,J5) -> 0 | D19: Affordability Index
A20: Total Monthly Mortage | B20: =B19+B17+B15+B12 -> #N/A | D20: < 0.5 | E20: Affordable
D21: >0.5, < 0.75 | E21: Slightly affordable
A22: Monthly Income | C22: Enter value | D22: > 0.75 | E22: Not affordable
A23: Affordability | B23: =B20/B22 -> #N/A

Sheet Revenue model
B1: First month free for buyers and sellers | C1: Basic free property search
B3: Revenue Sources | D3: Amount | E3: Features
A4: 1 | B4: Subscriptions
B5: Basic | D5: $10/month | E5: Access to financial calculator on a single page to calculate the mortgage amount per month
B6: Premium | D6: $15/month | E6: Transparency score, Affordability and Neighbourhood history
B7: Pro | D7: $25/month | E7: Personalized financial roadmap, access to verified advisors, market risk alerts, refinance recommendations
A8: 2 | B8: Referral fee | D8: $30/lead | E8: Home Insurance & Mortgage lenders
A9: 3 | B9: Agent subsriptions | D9: $150/year | E9: Agents receive a trust badge
A10: 4 | B10: Home-owner companionship feature | D10: $4/month | E10: To help homeowners with easy maintenance through a network of trusted partners and affiliates.
G14: Assumptions:
B15: Revenue | C15: $ | G15: Initial launch in 1-2 states
B16: Subscriptions | C16: =M31 -> 18300 | K16: Subscirption curve for year 1
B17: Referral fee | C17: =H25*H26 -> 22500 | G17: Users | H17: 15000 | I17: yearly
B18: Agent fee | C18: =H34*H35 -> 11250 | G18: Conversion rate | H18: 0.02 | K18: Month | L18: # of Subscribers | M18: Revenue
B19: Home owner comp fee | C19: =H40*H39*12 -> 5760 | G19: Total subscriptions | H19: =H17*H18 -> 300 | K19: 1 | L19: 5 | M19: =L19*$H$20 -> 75
B20: Total revenue | C20: =SUM(C16:C19) -> 57810 | G20: Monthly revenue subscription | H20: 15 | K20: 2 | L20: 10 | M20: =L20*$H$20 -> 150
K21: 3 | L21: 25 | M21: =L21*$H$20 -> 375
B22: Fixed Costs/Investments | G22: Monthly revenue | H22: =H20*H19 -> 4500 | K22: 4 | L22: 40 | M22: =L22*$H$20 -> 600
B23: Data APIs | C23: =500*12 -> 6000 | K23: 5 | L23: 60 | M23: =L23*$H$20 -> 900
B24: Hosting, AWS cost | C24: =200*12 -> 2400 | G24: % of users that connect to affiliates/referral | H24: =5% -> 0.05 | K24: 6 | L24: 80 | M24: =L24*$H$20 -> 1200
B25: Tools (Notion, Figma, domain, email) | C25: =100*12 -> 1200 | G25: Total leads | H25: =H24*H17 -> 750 | K25: 7 | L25: 100 | M25: =L25*$H$20 -> 1500
B26: Marketing budget | C26: =800*12 -> 9600 | G26: Revenue per lead | H26: 30 | K26: 8 | L26: 100 | M26: =L26*$H$20 -> 1500
B27: Contractors/Design/Development budget if needed | C27: =2500*12 -> 30000 | K27: 9 | L27: 200 | M27: =L27*$H$20 -> 3000
B28: MLS costs | C28: 20000 | K28: 10 | L28: 200 | M28: =L28*$H$20 -> 3000
G29: Number of agents signed up | K29: 11 | L29: 200 | M29: =L29*$H$20 -> 3000
B30: Total Costs per year | C30: =SUM(C23:C28) -> 69200 | G30: Based on initial launch | K30: 12 | L30: 200 | M30: =L30*$H$20 -> 3000
C31: =SUM(C23:C27) -> 49200 | G31: Reach | H31: 5000 | M31: =SUM(M19:M30) -> 18300
B32: Profit per year | C32: =C20-C30 -> -11390 | G32: Interested agents | H32: 0.15
C33: =C20-C31 -> 8610 | G33: Willingness to pay | H33: 0.1
B34: Bootstrapped project | C34: 35000 | G34: Total Onboarded agents | H34: =H31*H32*H33 -> 75
B35: Return on Equity | C35: =C32/C34 -> -0.32542857 | G35: Per agent fee | H35: 150 | I35: /year | L35: Sensitivity Analysis
L36: 10000
B37: CAC | C37: =C26/H19 -> 32 | G37: Home owner comp fee | L37: 0.01
G38: Closed deals out of active users | H38: 0.4 | L38: =L37*L36 -> 100
B39: Breakeven subscriber months | C39: =-C32/H20 -> 759.33333 | G39: Total closings | H39: =H38*H19 -> 120 | L39: =H20*L38 -> 1500 | M39: 6
B40: Additional subscribers required for breakeven for 12 months | C40: =C39/12 -> 63.277778 | G40: Per month fee | H40: 4 | L40: 3300
L41: =L39*M39+L40 -> 12300
B43: Target Market
B44: TAM | C44: 50000000 | D44: =C44*30% -> 15000000 | E44: =D44*30% -> 4500000 | L44: 0.05
B45: SAM | C45: 600000 | D45: =E44*12% -> 540000 | E45: =16%*E44 -> 720000 | F45: For 2 states initial launch | L45: =L44*L36 -> 500
...

Sheet Credit scores & Interest rates
G2: Minimum credit score | H2: Interest rate | J2: Years | L2: Downpayment %
B3: Credit Score | C3: Rate adjustment | D3: Base rate = 6.5% | G3: 760–850 | H3: 0.065 | J3: 0 | L3: 0.05
B4: 760–850 | C4: 0 | D4: 0.065 | G4: 740–759 | H4: 0.06625 | J4: 5 | L4: 0.1
B5: 740–759 | C5: 0.00125 | D5: 0.06625 | G5: 720–739 | H5: 0.0675 | J5: 10 | L5: 0.15
B6: 720–739 | C6: 0.0025 | D6: 0.0675 | G6: 700–719 | H6: 0.06875 | J6: 15 | L6: 0.2
B7: 700–719 | C7: 0.00375 | D7: 0.06875 | G7: 680–699 | H7: 0.07125 | J7: 20 | L7: 0.25
B8: 680–699 | C8: 0.00625 | D8: 0.07125 | G8: 660–679 | H8: 0.07375 | J8: 25 | L8: 0.3
B9: 660–679 | C9: 0.00875 | D9: 0.07375 | G9: 640–659 | H9: 0.07625 | J9: 30 | L9: 0.35
B10: 640–659 | C10: 0.01125 | D10: 0.07625 | G10: 620–639 | H10: 0.07875 | J10: 35 | L10: 0.4
B11: 620–639 | C11: 0.01375 | D11: 0.07875 | J11: 40 | L11: 0.45
B13: Base rate | C13: 0.065
B14: Penalty factor | C14: 0.0025

Sheet Statewise Insurance
A1: State | B1: Average annual cost | C1: Average monthly cost
A3: National average | B3: 2110 | C3: 176
A5: Alabama | B5: 3420 | C5: 285
A7: Alaska | B7: 1035 | C7: 86
A9: Arizona | B9: 2565 | C9: 214
A11: Arkansas | B11: 3215 | C11: 268
A13: California | B13: 1335 | C13: 111
A15: Colorado | B15: 4175 | C15: 348
A17: Connecticut | B17: 1870 | C17: 156
A19: Delaware | B19: 1025 | C19: 85
A21: Florida | B21: 2625 | C21: 219
A23: Georgia | B23: 2435 | C23: 203
A25: Hawaii | B25: 610 | C25: 51
... A105: Wyoming | B105: 1555 | C105: 130

Sheet Insurance
C2: Policy Type | D2: Typical Annual Premium | E2: Why It Costs This Much
C3: Homeowners Insurance | D3: $1,200–$1,800/year | E3: Covers the entire home structure and rebuilding costs
C4: Renter’s Insurance | D4: $150–$300/year | E4: Only covers personal property and liability, not the structure

Sheet Tax rates
A1: State | B1: Effective Property Tax Rate (Owner-Occupied, 2023)
A2: Alabama | B2: 0.0036
A3: Alaska | B3: 0.0091
A4: Arizona | B4: 0.0044
A5: Arkansas | B5: 0.0053
A6: California | B6: 0.007
A7: Colorado | B7: 0.005
A8: Connecticut | B8: 0.0148
A9: Delaware | B9: 0.005
A10: Florida | B10: 0.0074
A11: Georgia | B11: 0.0077
A12: Hawaii | B12: 0.0032
A13: Idaho | B13: 0.0048
... A52: District of Columbia | B52: 0.0061

Sheet Loan Amortization table
C1: Total Loan Amount | D1: =Simulator!B8 -> 0
C2: Interest rate | D2: =Simulator!B10 -> 0.0675
C3: Tenure | D3: =Simulator!B11 -> 0 | E3: years
C4: Months | D4: =12*D3 -> 0 | E4: months
A6: Year | B6: Loan amount | C6: Interest | D6: Principal | E6: Instalment amount | F6: Remaining Loan Amount
A7: =1 -> 1 | B7: =D1 -> 0 | C7: =($D$2/12)*B7 -> 0 | D7: =E7-C7 -> #NUM! | E7: =PMT($D$2/12,$D$4,-$D$1,,) -> #NUM! | F7: =B7-D7 -> #NUM!
A8: 2 | B8: =F7 -> #NUM! | C8: =($D$2/12)*B8 -> #NUM! | D8: =E8-C8 -> #NUM! | E8: =PMT($D$2/12,$D$4,-$D$1,,) -> #NUM! | F8: =B8-D8 -> #NUM!
A9: 3 | B9: =F8 -> #NUM! | C9: =($D$2/12)*B9 -> #NUM! | D9: =E9-C9 -> #NUM! | E9: =PMT($D$2/12,$D$4,-$D$1,,) -> #NUM! | F9: =B9-D9 -> #NUM!
A10: 4 | B10: =F9 -> #NUM! | C10: =($D$2/12)*B10 -> #NUM! | D10: =E10-C10 -> #NUM! | E10: =PMT($D$2/12,$D$4,-$D$1,,) -> #NUM! | F10: =B10-D10 -> #NUM!
A11: 5 | B11: =F10 -> #NUM! | C11: =($D$2/12)*B11 -> #NUM! | D11: =E11-C11 -> #NUM! | E11: =PMT($D$2/12,$D$4,-$D$1,,) -> #NUM! | F11: =B11-D11 -> #NUM!
A12: 6 | B12: =F11 -> #NUM! | C12: =($D$2/12)*B12 -> #NUM! | D12: =E12-C12 -> #NUM! | E12: =PMT($D$2/12,$D$4,-$D$1,,) -> #NUM! | F12: =B12-D12 -> #NUM!
A13: 7 | B13: =F12 -> #NUM! | C13: =($D$2/12)*B13 -> #NUM! | D13: =E13-C13 -> #NUM! | E13: =PMT($D$2/12,$D$4,-$D$1,,) -> #NUM! | F13: =B13-D13 -> #NUM!
A14: 8 | B14: =F13 -> #NUM! | C14: =($D$2/12)*B14 -> #NUM! | D14: =E14-C14 -> #NUM! | E14: =PMT($D$2/12,$D$4,-$D$1,,) -> #NUM! | F14: =B14-D14 -> #NUM!
A15: 9 | B15: =F14 -> #NUM! | C15: =($D$2/12)*B15 -> #NUM! | D15: =E15-C15 -> #NUM! | E15: =PMT($D$2/12,$D$4,-$D$1,,) -> #NUM! | F15: =B15-D15 -> #NUM!
A16: 10 | B16: =F15 -> #NUM! | C16: =($D$2/12)*B16 -> #NUM! | D16: =E16-C16 -> #NUM! | E16: =PMT($D$2/12,$D$4,-$D$1,,) -> #NUM! | F16: =B16-D16 -> #NUM!
A17: 11 | B17: =F16 -> #NUM! | C17: =($D$2/12)*B17 -> #NUM! | D17: =E17-C17 -> #NUM! | E17: =PMT($D$2/12,$D$4,-$D$1,,) -> #NUM! | F17: =B17-D17 -> #NUM!
A18: 12 | B18: =F17 -> #NUM! | C18: =($D$2/12)*B18 -> #NUM! | D18: =E18-C18 -> #NUM! | E18: =PMT($D$2/12,$D$4,-$D$1,,) -> #NUM! | F18: =B18-D18 -> #NUM!
A19: 13 | B19: =F18 -> #NUM! | C19: =($D$2/12)*B19 -> #NUM! | D19: =E19-C19 -> #NUM! | E19: =PMT($D$2/12,$D$4,-$D$1,,) -> #NUM! | F19: =B19-D19 -> #NUM!
... A606: 600 | B606: =F605 -> #NUM! | C606: =($D$2/12)*B606 -> #NUM! | D606: =E606-C606 -> #NUM! | E606: =PMT($D$2/12,$D$4,-$D$1,,) -> #NUM! | F606: =B606-D606 -> #NUM!
